Workbook

Sheet README
A1: Pokemon Yellow — Type Coverage Model
A2: Generation 1 rules. Every number in this workbook is a live formula; edit the Type Chart and everything downstream recalculates.
A4: HOW TO USE
A5: Type Chart | B5: The Gen 1 matrix. BLUE cells are the only hardcoded inputs in the workbook. Change one and every other sheet updates.
A6: Gen1 Quirks | B6: Read this FIRST. Gen 1 is not modern Pokemon. Five differences will actively mislead you if you play on instinct.
A7: Pokedex | B7: All 151 with types.
A8: Effectiveness | B8: 151 x 15 grid: what each attacking type does to each species. The engine room.
A9: Type Scorecard | B9: Per attacking type: raw coverage vs. the full dex AND vs. Yellow's 49 boss Pokemon, then discounted by whether Gen 1 gives you a move worth using.
A10: Yellow Bosses | B10: All 49 Pokemon across 8 gyms + Elite Four + Champion, with every type's multiplier against them. Yellow-specific rosters (they differ from Red/Blue).
A11: Move Reality | B11: The layer that matters. A type's coverage is worthless if its best move is 20 base power.
A12: Combo Search | B12: Brute force: all 1,365 four-type combinations, scored against the actual boss gauntlet.
A13: Recommended Team | B13: The conclusion.
A15: SCORING
A16: Boss SE | B16: Count of the 49 boss Pokemon hit for 2x or better by at least one type in the set.
A17: Walled | B17: Count of bosses where EVERY type in the set is resisted or immune. Zero is the goal.
A18: Move Viability | B18: 0-10, hand-scored. Reflects base power, accuracy, whether a TM/HM exists in Yellow, and Gen 1's physical/special split by type. Documented per-move on 'Move Reality'.
A19: Practical Score | B19: Boss SE % x Move Viability / 10. Punishes types that look great on the chart but have no move to exploit it (looking at you, Bug).
A21: SOURCES
A22: Boss rosters | B22: dittobase.com/yellow/gym-leaders-elite-four — Yellow-specific teams. Notable Yellow deviations: Lt. Surge is a lone Lv28 Raichu; Koga runs three Venonat + Venomoth (not Koffing/Muk); Sabrina is the pure Abra line at Lv50.
A23: Type chart / mechanics | B23: Generation 1 rules as shipped, bugs included.
A24: Champion caveat | B24: Blue's team has 3 variants keyed to his Eevee's evolution. The Vaporeon branch is modeled here. The other two swap that one slot for Jolteon or Flareon; it does not change any conclusion.

Sheet Type Chart
A1: Generation 1 Type Chart
A2: Rows = ATTACKING type. Columns = DEFENDING type. Blue = hardcoded input (the only ones in this file). Red fill = Gen 1 deviates from modern here.
A4: ATK \ DEF | B4: Normal | C4: Fire | D4: Water | E4: Electric | F4: Grass | G4: Ice | H4: Fighting | I4: Poison | J4: Ground | K4: Flying | L4: Psychic | M4: Bug | N4: Rock | O4: Ghost | P4: Dragon
A5: Normal | B5: 1 | C5: 1 | D5: 1 | E5: 1 | F5: 1 | G5: 1 | H5: 1 | I5: 1 | J5: 1 | K5: 1 | L5: 1 | M5: 1 | N5: 0.5 | O5: 0 | P5: 1
A6: Fire | B6: 1 | C6: 0.5 | D6: 0.5 | E6: 1 | F6: 2 | G6: 2 | H6: 1 | I6: 1 | J6: 1 | K6: 1 | L6: 1 | M6: 2 | N6: 0.5 | O6: 1 | P6: 0.5
A7: Water | B7: 1 | C7: 2 | D7: 0.5 | E7: 1 | F7: 0.5 | G7: 1 | H7: 1 | I7: 1 | J7: 2 | K7: 1 | L7: 1 | M7: 1 | N7: 2 | O7: 1 | P7: 0.5
A8: Electric | B8: 1 | C8: 1 | D8: 2 | E8: 0.5 | F8: 0.5 | G8: 1 | H8: 1 | I8: 1 | J8: 0 | K8: 2 | L8: 1 | M8: 1 | N8: 1 | O8: 1 | P8: 0.5
A9: Grass | B9: 1 | C9: 0.5 | D9: 2 | E9: 1 | F9: 0.5 | G9: 1 | H9: 1 | I9: 0.5 | J9: 2 | K9: 0.5 | L9: 1 | M9: 0.5 | N9: 2 | O9: 1 | P9: 0.5
A10: Ice | B10: 1 | C10: 1 | D10: 0.5 | E10: 1 | F10: 2 | G10: 0.5 | H10: 1 | I10: 1 | J10: 2 | K10: 2 | L10: 1 | M10: 1 | N10: 1 | O10: 1 | P10: 2
A11: Fighting | B11: 2 | C11: 1 | D11: 1 | E11: 1 | F11: 1 | G11: 2 | H11: 1 | I11: 0.5 | J11: 1 | K11: 0.5 | L11: 0.5 | M11: 0.5 | N11: 2 | O11: 0 | P11: 1
A12: Poison | B12: 1 | C12: 1 | D12: 1 | E12: 1 | F12: 2 | G12: 1 | H12: 1 | I12: 0.5 | J12: 0.5 | K12: 1 | L12: 1 | M12: 2 | N12: 0.5 | O12: 0.5 | P12: 1
A13: Ground | B13: 1 | C13: 2 | D13: 1 | E13: 2 | F13: 0.5 | G13: 1 | H13: 1 | I13: 2 | J13: 1 | K13: 0 | L13: 1 | M13: 0.5 | N13: 2 | O13: 1 | P13: 1
A14: Flying | B14: 1 | C14: 1 | D14: 1 | E14: 0.5 | F14: 2 | G14: 1 | H14: 2 | I14: 1 | J14: 1 | K14: 1 | L14: 1 | M14: 2 | N14: 0.5 | O14: 1 | P14: 1
A15: Psychic | B15: 1 | C15: 1 | D15: 1 | E15: 1 | F15: 1 | G15: 1 | H15: 2 | I15: 2 | J15: 1 | K15: 1 | L15: 0.5 | M15: 1 | N15: 1 | O15: 1 | P15: 1
A16: Bug | B16: 1 | C16: 0.5 | D16: 1 | E16: 1 | F16: 2 | G16: 1 | H16: 0.5 | I16: 2 | J16: 1 | K16: 0.5 | L16: 2 | M16: 1 | N16: 1 | O16: 0.5 | P16: 1
... A19: Dragon | B19: 1 | C19: 1 | D19: 1 | E19: 1 | F19: 1 | G19: 1 | H19: 1 | I19: 1 | J19: 1 | K19: 1 | L19: 1 | M19: 1 | N19: 1 | O19: 1 | P19: 2
A21: Green = super effective (2x) | Yellow = resisted (0.5x) | Black = immune (0x) | RED = differs from modern Pokemon

Sheet Gen1 Quirks
A1: Gen 1 vs. Modern — What Will Trip You Up
A2: If you learned Pokemon after 1999, these five rules are counterintuitive and they matter.
A4: Interaction | B4: Gen 1 (Yellow) | C4: Modern | D4: Why you care
A5: Ghost -> Psychic | B5: 0x (was meant to be 2x) | C5: 2x | D5: The single most famous Gen 1 bug. Ghost moves literally cannot touch Psychic. Sabrina/Alakazam have NO exploitable weakness.
A6: Bug -> Psychic | B6: 2x | C6: 2x | D6: Bug is Psychic's only working weakness in Gen 1 -- but every Bug move is garbage (Twineedle 25, Pin Missile 14, Leech Life 20). Coverage that exists on paper only.
A7: Poison -> Bug | B7: 2x | C7: 1x | D7: Gen 1 only. Poison beats Bug.
A8: Bug -> Poison | B8: 2x | C8: 1x | D8: Gen 1 only, and it goes BOTH ways. Bug beats Poison too.
A9: Ice -> Fire | B9: 1x | C9: 0.5x | D9: Fire does NOT resist Ice in Gen 1. Blizzard hits Blaine's whole gym for neutral.
A10: Dragon -> Dragon | B10: 2x | C10: 2x | D10: Moot: the only Dragon move in Gen 1 is Dragon Rage, fixed 40 damage.
A11: No Dark / Steel / Fairy | B11: n/a | C11: exists | D11: Only 15 types. Psychic has no counterplay because the types that would check it don't exist yet.
A12: Physical/Special split | B12: Does not exist | C12: Per-move | D12: Type determines category. Normal/Fighting/Flying/Ground/Rock/Bug/Ghost/Poison = Physical (uses Attack). Water/Grass/Fire/Ice/Electric/Psychic/Dragon = Special. A Pokemon's ONE Special stat is both its special attack AND special defense.

Sheet Pokedex
A1: Kanto Pokedex — Types
A2: Reference table. Type 2 blank = single-typed.
A4: # | B4: Name | C4: Type 1 | D4: Type 2
A5: 1 | B5: Bulbasaur | C5: Grass | D5: Poison
A6: 2 | B6: Ivysaur | C6: Grass | D6: Poison
A7: 3 | B7: Venusaur | C7: Grass | D7: Poison
A8: 4 | B8: Charmander | C8: Fire
A9: 5 | B9: Charmeleon | C9: Fire
A10: 6 | B10: Charizard | C10: Fire | D10: Flying
A11: 7 | B11: Squirtle | C11: Water
A12: 8 | B12: Wartortle | C12: Water
A13: 9 | B13: Blastoise | C13: Water
A14: 10 | B14: Caterpie | C14: Bug
A15: 11 | B15: Metapod | C15: Bug
A16: 12 | B16: Butterfree | C16: Bug | D16: Flying
A17: 13 | B17: Weedle | C17: Bug | D17: Poison
A18: 14 | B18: Kakuna | C18: Bug | D18: Poison
A19: 15 | B19: Beedrill | C19: Bug | D19: Poison
A20: 16 | B20: Pidgey | C20: Normal | D20: Flying
A21: 17 | B21: Pidgeotto | C21: Normal | D21: Flying
A22: 18 | B22: Pidgeot | C22: Normal | D22: Flying
A23: 19 | B23: Rattata | C23: Normal
A24: 20 | B24: Raticate | C24: Normal
A25: 21 | B25: Spearow | C25: Normal | D25: Flying
A26: 22 | B26: Fearow | C26: Normal | D26: Flying
A27: 23 | B27: Ekans | C27: Poison
A28: 24 | B28: Arbok | C28: Poison
A29: 25 | B29: Pikachu | C29: Electric
A30: 26 | B30: Raichu | C30: Electric
A31: 27 | B31: Sandshrew | C31: Ground
A32: 28 | B32: Sandslash | C32: Ground
A33: 29 | B33: Nidoran-F | C33: Poison
A34: 30 | B34: Nidorina | C34: Poison
A35: 31 | B35: Nidoqueen | C35: Poison | D35: Ground
A36: 32 | B36: Nidoran-M | C36: Poison
A37: 33 | B37: Nidorino | C37: Poison
A38: 34 | B38: Nidoking | C38: Poison | D38: Ground
A39: 35 | B39: Clefairy | C39: Normal
A40: 36 | B40: Clefable | C40: Normal
A41: 37 | B41: Vulpix | C41: Fire
...

Sheet Effectiveness
A1: Damage Multiplier — Every Attacking Type vs. All 151
A2: Live INDEX/MATCH against 'Type Chart'. Column letters E:S map to the 15 attacking types.
A4: # | B4: Name | C4: Type 1 | D4: Type 2 | E4: Normal | F4: Fire | G4: Water | H4: Electric | I4: Grass | J4: Ice | K4: Fighting | L4: Poison | M4: Ground | N4: Flying | O4: Psychic | P4: Bug | Q4: Rock | R4: Ghost | S4: Dragon
A5: 1 | B5: Bulbasaur | C5: =Pokedex!C5 -> Grass | D5: =Pokedex!D5 -> Poison | E5: =INDEX('Type Chart'!$B$5:$P$19,MATCH(E$4,'Type Chart'!$A$5:$A$19,0),MATCH($C5,'Type Chart'!$B$4:$P$4,0))*IF($D5="",1,INDEX('Type Chart'!$B$5:$P$19,MATCH(E$4,'Type Chart'!$A$5:$A$19,0),MATCH($D5,'Type Chart'!$B$4:$P$4,0))) -> 1 | F5: =INDEX('Type Chart'!$B$5:$P$19,MATCH(F$4,'Type Chart'!$A$5:$A$19,0),MATCH($C5,'Type Chart'!$B$4:$P$4,0))*IF($D5="",1,INDEX('Type Chart'!$B$5:$P$19,MATCH(F$4,'Type Chart'!$A$5:$A$19,0),MATCH($D5,'Type Chart'!$B$4:$P$4,0))) -> 2 | G5: =INDEX('Type Chart'!$B$5:$P$19,MATCH(G$4,'Type Chart'!$A$5:$A$19,0),MATCH($C5,'Type Chart'!$B$4:$P$4,0))*IF($D5="",1,INDEX('Type Chart'!$B$5:$P$19,MATCH(G$4,'Type Chart'!$A$5:$A$19,0),MATCH($D5,'Type Chart'!$B$4:$P$4,0))) -> 0.5 | H5: =INDEX('Type Chart'!$B$5:$P$19,MATCH(H$4,'Type Chart'!$A$5:$A$19,0),MATCH($C5,'Type Chart'!$B$4:$P$4,0))*IF($D5="",1,INDEX('Type Chart'!$B$5:$P$19,MATCH(H$4,'Type Chart'!$A$5:$A$19,0),MATCH($D5,'Type Chart'!$B$4:$P$4,0))) -> 0.5 | I5: =INDEX('Type Chart'!$B$5:$P$19,MATCH(I$4,'Type Chart'!$A$5:$A$19,0),MATCH($C5,'Type Chart'!$B$4:$P$4,0))*IF($D5="",1,INDEX('Type Chart'!$B$5:$P$19,MATCH(I$4,'Type Chart'!$A$5:$A$19,0),MATCH($D5,'Type Chart'!$B$4:$P$4,0))) -> 0.25 | J5: =INDEX('Type Chart'!$B$5:$P$19,MATCH(J$4,'Type Chart'!$A$5:$A$19,0),MATCH($C5,'Type Chart'!$B$4:$P$4,0))*IF($D5="",1,INDEX('Type Chart'!$B$5:$P$19,MATCH(J$4,'Type Chart'!$A$5:$A$19,0),MATCH($D5,'Type Chart'!$B$4:$P$4,0))) -> 2 | K5: =INDEX('Type Chart'!$B$5:$P$19,MATCH(K$4,'Type Chart'!$A$5:$A$19,0),MATCH($C5,'Type Chart'!$B$4:$P$4,0))*IF($D5="",1,INDEX('Type Chart'!$B$5:$P$19,MATCH(K$4,'Type Chart'!$A$5:$A$19,0),MATCH($D5,'Type Chart'!$B$4:$P$4,0))) -> 0.5 | L5: =INDEX('Type Chart'!$B$5:$P$19,MATCH(L$4,'Type Chart'!$A$5:$A$19,0),MATCH($C5,'Type Chart'!$B$4:$P$4,0))*IF($D5="",1,INDEX('Type Chart'!$B$5:$P$19,MATCH(L$4,'Type Chart'!$A$5:$A$19,0),MATCH($D5,'Type Chart'!$B$4:$P$4,0))) -> 1 | ... S5: =INDEX('Type Chart'!$B$5:$P$19,MATCH(S$4,'Type Chart'!$A$5:$A$19,0),MATCH($C5,'Type Chart'!$B$4:$P$4,0))*IF($D5="",1,INDEX('Type Chart'!$B$5:$P$19,MATCH(S$4,'Type Chart'!$A$5:$A$19,0),MATCH($D5,'Type Chart'!$B$4:$P$4,0))) -> 1
A6: 2 | B6: Ivysaur | C6: =Pokedex!C6 -> Grass | D6: =Pokedex!D6 -> Poison | E6: =INDEX('Type Chart'!$B$5:$P$19,MATCH(E$4,'Type Chart'!$A$5:$A$19,0),MATCH($C6,'Type Chart'!$B$4:$P$4,0))*IF($D6="",1,INDEX('Type Chart'!$B$5:$P$19,MATCH(E$4,'Type Chart'!$A$5:$A$19,0),MATCH($D6,'Type Chart'!$B$4:$P$4,0))) -> 1 | F6: =INDEX('Type Chart'!$B$5:$P$19,MATCH(F$4,'Type Chart'!$A$5:$A$19,0),MATCH($C6,'Type Chart'!$B$4:$P$4,0))*IF($D6="",1,INDEX('Type Chart'!$B$5:$P$19,MATCH(F$4,'Type Chart'!$A$5:$A$19,0),MATCH($D6,'Type Chart'!$B$4:$P$4,0))) -> 2 | G6: =INDEX('Type Chart'!$B$5:$P$19,MATCH(G$4,'Type Chart'!$A$5:$A$19,0),MATCH($C6,'Type Chart'!$B$4:$P$4,0))*IF($D6="",1,INDEX('Type Chart'!$B$5:$P$19,MATCH(G$4,'Type Chart'!$A$5:$A$19,0),MATCH($D6,'Type Chart'!$B$4:$P$4,0))) -> 0.5 | H6: =INDEX('Type Chart'!$B$5:$P$19,MATCH(H$4,'Type Chart'!$A$5:$A$19,0),MATCH($C6,'Type Chart'!$B$4:$P$4,0))*IF($D6="",1,INDEX('Type Chart'!$B$5:$P$19,MATCH(H$4,'Type Chart'!$A$5:$A$19,0),MATCH($D6,'Type Chart'!$B$4:$P$4,0))) -> 0.5 | I6: =INDEX('Type Chart'!$B$5:$P$19,MATCH(I$4,'Type Chart'!$A$5:$A$19,0),MATCH($C6,'Type Chart'!$B$4:$P$4,0))*IF($D6="",1,INDEX('Type Chart'!$B$5:$P$19,MATCH(I$4,'Type Chart'!$A$5:$A$19,0),MATCH($D6,'Type Chart'!$B$4:$P$4,0))) -> 0.25 | J6: =INDEX('Type Chart'!$B$5:$P$19,MATCH(J$4,'Type Chart'!$A$5:$A$19,0),MATCH($C6,'Type Chart'!$B$4:$P$4,0))*IF($D6="",1,INDEX('Type Chart'!$B$5:$P$19,MATCH(J$4,'Type Chart'!$A$5:$A$19,0),MATCH($D6,'Type Chart'!$B$4:$P$4,0))) -> 2 | K6: =INDEX('Type Chart'!$B$5:$P$19,MATCH(K$4,'Type Chart'!$A$5:$A$19,0),MATCH($C6,'Type Chart'!$B$4:$P$4,0))*IF($D6="",1,INDEX('Type Chart'!$B$5:$P$19,MATCH(K$4,'Type Chart'!$A$5:$A$19,0),MATCH($D6,'Type Chart'!$B$4:$P$4,0))) -> 0.5 | L6: =INDEX('Type Chart'!$B$5:$P$19,MATCH(L$4,'Type Chart'!$A$5:$A$19,0),MATCH($C6,'Type Chart'!$B$4:$P$4,0))*IF($D6="",1,INDEX('Type Chart'!$B$5:$P$19,MATCH(L$4,'Type Chart'!$A$5:$A$19,0),MATCH($D6,'Type Chart'!$B$4:$P$4,0))) -> 1 | ... S6: =INDEX('Type Chart'!$B$5:$P$19,MATCH(S$4,'Type Chart'!$A$5:$A$19,0),MATCH($C6,'Type Chart'!$B$4:$P$4,0))*IF($D6="",1,INDEX('Type Chart'!$B$5:$P$19,MATCH(S$4,'Type Chart'!$A$5:$A$19,0),MATCH($D6,'Type Chart'!$B$4:$P$4,0))) -> 1
A7: 3 | B7: Venusaur | C7: =Pokedex!C7 -> Grass | D7: =Pokedex!D7 -> Poison | E7: =INDEX('Type Chart'!$B$5:$P$19,MATCH(E$4,'Type Chart'!$A$5:$A$19,0),MATCH($C7,'Type Chart'!$B$4:$P$4,0))*IF($D7="",1,INDEX('Type Chart'!$B$5:$P$19,MATCH(E$4,'Type Chart'!$A$5:$A$19,0),MATCH($D7,'Type Chart'!$B$4:$P$4,0))) -> 1 | F7: =INDEX('Type Chart'!$B$5:$P$19,MATCH(F$4,'Type Chart'!$A$5:$A$19,0),MATCH($C7,'Type Chart'!$B$4:$P$4,0))*IF($D7="",1,INDEX('Type Chart'!$B$5:$P$19,MATCH(F$4,'Type Chart'!$A$5:$A$19,0),MATCH($D7,'Type Chart'!$B$4:$P$4,0))) -> 2 | G7: =INDEX('Type Chart'!$B$5:$P$19,MATCH(G$4,'Type Chart'!$A$5:$A$19,0),MATCH($C7,'Type Chart'!$B$4:$P$4,0))*IF($D7="",1,INDEX('Type Chart'!$B$5:$P$19,MATCH(G$4,'Type Chart'!$A$5:$A$19,0),MATCH($D7,'Type Chart'!$B$4:$P$4,0))) -> 0.5 | H7: =INDEX('Type Chart'!$B$5:$P$19,MATCH(H$4,'Type Chart'!$A$5:$A$19,0),MATCH($C7,'Type Chart'!$B$4:$P$4,0))*IF($D7="",1,INDEX('Type Chart'!$B$5:$P$19,MATCH(H$4,'Type Chart'!$A$5:$A$19,0),MATCH($D7,'Type Chart'!$B$4:$P$4,0))) -> 0.5 | I7: =INDEX('Type Chart'!$B$5:$P$19,MATCH(I$4,'Type Chart'!$A$5:$A$19,0),MATCH($C7,'Type Chart'!$B$4:$P$4,0))*IF($D7="",1,INDEX('Type Chart'!$B$5:$P$19,MATCH(I$4,'Type Chart'!$A$5:$A$19,0),MATCH($D7,'Type Chart'!$B$4:$P$4,0))) -> 0.25 | J7: =INDEX('Type Chart'!$B$5:$P$19,MATCH(J$4,'Type Chart'!$A$5:$A$19,0),MATCH($C7,'Type Chart'!$B$4:$P$4,0))*IF($D7="",1,INDEX('Type Chart'!$B$5:$P$19,MATCH(J$4,'Type Chart'!$A$5:$A$19,0),MATCH($D7,'Type Chart'!$B$4:$P$4,0))) -> 2 | K7: =INDEX('Type Chart'!$B$5:$P$19,MATCH(K$4,'Type Chart'!$A$5:$A$19,0),MATCH($C7,'Type Chart'!$B$4:$P$4,0))*IF($D7="",1,INDEX('Type Chart'!$B$5:$P$19,MATCH(K$4,'Type Chart'!$A$5:$A$19,0),MATCH($D7,'Type Chart'!$B$4:$P$4,0))) -> 0.5 | L7: =INDEX('Type Chart'!$B$5:$P$19,MATCH(L$4,'Type Chart'!$A$5:$A$19,0),MATCH($C7,'Type Chart'!$B$4:$P$4,0))*IF($D7="",1,INDEX('Type Chart'!$B$5:$P$19,MATCH(L$4,'Type Chart'!$A$5:$A$19,0),MATCH($D7,'Type Chart'!$B$4:$P$4,0))) -> 1 | ... S7: =INDEX('Type Chart'!$B$5:$P$19,MATCH(S$4,'Type Chart'!$A$5:$A$19,0),MATCH($C7,'Type Chart'!$B$4:$P$4,0))*IF($D7="",1,INDEX('Type Chart'!$B$5:$P$19,MATCH(S$4,'Type Chart'!$A$5:$A$19,0),MATCH($D7,'Type Chart'!$B$4:$P$4,0))) -> 1
A8: 4 | B8: Charmander | C8: =Pokedex!C8 -> Fire | D8: =Pokedex!D8 -> 0 | E8: =INDEX('Type Chart'!$B$5:$P$19,MATCH(E$4,'Type Chart'!$A$5:$A$19,0),MATCH($C8,'Type Chart'!$B$4:$P$4,0))*IF($D8="",1,INDEX('Type Chart'!$B$5:$P$19,MATCH(E$4,'Type Chart'!$A$5:$A$19,0),MATCH($D8,'Type Chart'!$B$4:$P$4,0))) -> 1 | F8: =INDEX('Type Chart'!$B$5:$P$19,MATCH(F$4,'Type Chart'!$A$5:$A$19,0),MATCH($C8,'Type Chart'!$B$4:$P$4,0))*IF($D8="",1,INDEX('Type Chart'!$B$5:$P$19,MATCH(F$4,'Type Chart'!$A$5:$A$19,0),MATCH($D8,'Type Chart'!$B$4:$P$4,0))) -> 0.5 | G8: =INDEX('Type Chart'!$B$5:$P$19,MATCH(G$4,'Type Chart'!$A$5:$A$19,0),MATCH($C8,'Type Chart'!$B$4:$P$4,0))*IF($D8="",1,INDEX('Type Chart'!$B$5:$P$19,MATCH(G$4,'Type Chart'!$A$5:$A$19,0),MATCH($D8,'Type Chart'!$B$4:$P$4,0))) -> 2 | H8: =INDEX('Type Chart'!$B$5:$P$19,MATCH(H$4,'Type Chart'!$A$5:$A$19,0),MATCH($C8,'Type Chart'!$B$4:$P$4,0))*IF($D8="",1,INDEX('Type Chart'!$B$5:$P$19,MATCH(H$4,'Type Chart'!$A$5:$A$19,0),MATCH($D8,'Type Chart'!$B$4:$P$4,0))) -> 1 | I8: =INDEX('Type Chart'!$B$5:$P$19,MATCH(I$4,'Type Chart'!$A$5:$A$19,0),MATCH($C8,'Type Chart'!$B$4:$P$4,0))*IF($D8="",1,INDEX('Type Chart'!$B$5:$P$19,MATCH(I$4,'Type Chart'!$A$5:$A$19,0),MATCH($D8,'Type Chart'!$B$4:$P$4,0))) -> 0.5 | J8: =INDEX('Type Chart'!$B$5:$P$19,MATCH(J$4,'Type Chart'!$A$5:$A$19,0),MATCH($C8,'Type Chart'!$B$4:$P$4,0))*IF($D8="",1,INDEX('Type Chart'!$B$5:$P$19,MATCH(J$4,'Type Chart'!$A$5:$A$19,0),MATCH($D8,'Type Chart'!$B$4:$P$4,0))) -> 1 | K8: =INDEX('Type Chart'!$B$5:$P$19,MATCH(K$4,'Type Chart'!$A$5:$A$19,0),MATCH($C8,'Type Chart'!$B$4:$P$4,0))*IF($D8="",1,INDEX('Type Chart'!$B$5:$P$19,MATCH(K$4,'Type Chart'!$A$5:$A$19,0),MATCH($D8,'Type Chart'!$B$4:$P$4,0))) -> 1 | L8: =INDEX('Type Chart'!$B$5:$P$19,MATCH(L$4,'Type Chart'!$A$5:$A$19,0),MATCH($C8,'Type Chart'!$B$4:$P$4,0))*IF($D8="",1,INDEX('Type Chart'!$B$5:$P$19,MATCH(L$4,'Type Chart'!$A$5:$A$19,0),MATCH($D8,'Type Chart'!$B$4:$P$4,0))) -> 1 | ... S8: =INDEX('Type Chart'!$B$5:$P$19,MATCH(S$4,'Type Chart'!$A$5:$A$19,0),MATCH($C8,'Type Chart'!$B$4:$P$4,0))*IF($D8="",1,INDEX('Type Chart'!$B$5:$P$19,MATCH(S$4,'Type Chart'!$A$5:$A$19,0),MATCH($D8,'Type Chart'!$B$4:$P$4,0))) -> 1
A9: 5 | B9: Charmeleon | C9: =Pokedex!C9 -> Fire | D9: =Pokedex!D9 -> 0 | E9: =INDEX('Type Chart'!$B$5:$P$19,MATCH(E$4,'Type Chart'!$A$5:$A$19,0),MATCH($C9,'Type Chart'!$B$4:$P$4,0))*IF($D9="",1,INDEX('Type Chart'!$B$5:$P$19,MATCH(E$4,'Type Chart'!$A$5:$A$19,0),MATCH($D9,'Type Chart'!$B$4:$P$4,0))) -> 1 | F9: =INDEX('Type Chart'!$B$5:$P$19,MATCH(F$4,'Type Chart'!$A$5:$A$19,0),MATCH($C9,'Type Chart'!$B$4:$P$4,0))*IF($D9="",1,INDEX('Type Chart'!$B$5:$P$19,MATCH(F$4,'Type Chart'!$A$5:$A$19,0),MATCH($D9,'Type Chart'!$B$4:$P$4,0))) -> 0.5 | G9: =INDEX('Type Chart'!$B$5:$P$19,MATCH(G$4,'Type Chart'!$A$5:$A$19,0),MATCH($C9,'Type Chart'!$B$4:$P$4,0))*IF($D9="",1,INDEX('Type Chart'!$B$5:$P$19,MATCH(G$4,'Type Chart'!$A$5:$A$19,0),MATCH($D9,'Type Chart'!$B$4:$P$4,0))) -> 2 | H9: =INDEX('Type Chart'!$B$5:$P$19,MATCH(H$4,'Type Chart'!$A$5:$A$19,0),MATCH($C9,'Type Chart'!$B$4:$P$4,0))*IF($D9="",1,INDEX('Type Chart'!$B$5:$P$19,MATCH(H$4,'Type Chart'!$A$5:$A$19,0),MATCH($D9,'Type Chart'!$B$4:$P$4,0))) -> 1 | I9: =INDEX('Type Chart'!$B$5:$P$19,MATCH(I$4,'Type Chart'!$A$5:$A$19,0),MATCH($C9,'Type Chart'!$B$4:$P$4,0))*IF($D9="",1,INDEX('Type Chart'!$B$5:$P$19,MATCH(I$4,'Type Chart'!$A$5:$A$19,0),MATCH($D9,'Type Chart'!$B$4:$P$4,0))) -> 0.5 | J9: =INDEX('Type Chart'!$B$5:$P$19,MATCH(J$4,'Type Chart'!$A$5:$A$19,0),MATCH($C9,'Type Chart'!$B$4:$P$4,0))*IF($D9="",1,INDEX('Type Chart'!$B$5:$P$19,MATCH(J$4,'Type Chart'!$A$5:$A$19,0),MATCH($D9,'Type Chart'!$B$4:$P$4,0))) -> 1 | K9: =INDEX('Type Chart'!$B$5:$P$19,MATCH(K$4,'Type Chart'!$A$5:$A$19,0),MATCH($C9,'Type Chart'!$B$4:$P$4,0))*IF($D9="",1,INDEX('Type Chart'!$B$5:$P$19,MATCH(K$4,'Type Chart'!$A$5:$A$19,0),MATCH($D9,'Type Chart'!$B$4:$P$4,0))) -> 1 | L9: =INDEX('Type Chart'!$B$5:$P$19,MATCH(L$4,'Type Chart'!$A$5:$A$19,0),MATCH($C9,'Type Chart'!$B$4:$P$4,0))*IF($D9="",1,INDEX('Type Chart'!$B$5:$P$19,MATCH(L$4,'Type Chart'!$A$5:$A$19,0),MATCH($D9,'Type Chart'!$B$4:$P$4,0))) -> 1 | ... S9: =INDEX('Type Chart'!$B$5:$P$19,MATCH(S$4,'Type Chart'!$A$5:$A$19,0),MATCH($C9,'Type Chart'!$B$4:$P$4,0))*IF($D9="",1,INDEX('Type Chart'!$B$5:$P$19,MATCH(S$4,'Type Chart'!$A$5:$A$19,0),MATCH($D9,'Type Chart'!$B$4:$P$4,0))) -> 1
A10: 6 | B10: Charizard | C10: =Pokedex!C10 -> Fire | D10: =Pokedex!D10 -> Flying | E10: =INDEX('Type Chart'!$B$5:$P$19,MATCH(E$4,'Type Chart'!$A$5:$A$19,0),MATCH($C10,'Type Chart'!$B$4:$P$4,0))*IF($D10="",1,INDEX('Type Chart'!$B$5:$P$19,MATCH(E$4,'Type Chart'!$A$5:$A$19,0),MATCH($D10,'Type Chart'!$B$4:$P$4,0))) -> 1 | F10: =INDEX('Type Chart'!$B$5:$P$19,MATCH(F$4,'Type Chart'!$A$5:$A$19,0),MATCH($C10,'Type Chart'!$B$4:$P$4,0))*IF($D10="",1,INDEX('Type Chart'!$B$5:$P$19,MATCH(F$4,'Type Chart'!$A$5:$A$19,0),MATCH($D10,'Type Chart'!$B$4:$P$4,0))) -> 0.5 | G10: =INDEX('Type Chart'!$B$5:$P$19,MATCH(G$4,'Type Chart'!$A$5:$A$19,0),MATCH($C10,'Type Chart'!$B$4:$P$4,0))*IF($D10="",1,INDEX('Type Chart'!$B$5:$P$19,MATCH(G$4,'Type Chart'!$A$5:$A$19,0),MATCH($D10,'Type Chart'!$B$4:$P$4,0))) -> 2 | H10: =INDEX('Type Chart'!$B$5:$P$19,MATCH(H$4,'Type Chart'!$A$5:$A$19,0),MATCH($C10,'Type Chart'!$B$4:$P$4,0))*IF($D10="",1,INDEX('Type Chart'!$B$5:$P$19,MATCH(H$4,'Type Chart'!$A$5:$A$19,0),MATCH($D10,'Type Chart'!$B$4:$P$4,0))) -> 2 | I10: =INDEX('Type Chart'!$B$5:$P$19,MATCH(I$4,'Type Chart'!$A$5:$A$19,0),MATCH($C10,'Type Chart'!$B$4:$P$4,0))*IF($D10="",1,INDEX('Type Chart'!$B$5:$P$19,MATCH(I$4,'Type Chart'!$A$5:$A$19,0),MATCH($D10,'Type Chart'!$B$4:$P$4,0))) -> 0.25 | J10: =INDEX('Type Chart'!$B$5:$P$19,MATCH(J$4,'Type Chart'!$A$5:$A$19,0),MATCH($C10,'Type Chart'!$B$4:$P$4,0))*IF($D10="",1,INDEX('Type Chart'!$B$5:$P$19,MATCH(J$4,'Type Chart'!$A$5:$A$19,0),MATCH($D10,'Type Chart'!$B$4:$P$4,0))) -> 2 | K10: =INDEX('Type Chart'!$B$5:$P$19,MATCH(K$4,'Type Chart'!$A$5:$A$19,0),MATCH($C10,'Type Chart'!$B$4:$P$4,0))*IF($D10="",1,INDEX('Type Chart'!$B$5:$P$19,MATCH(K$4,'Type Chart'!$A$5:$A$19,0),MATCH($D10,'Type Chart'!$B$4:$P$4,0))) -> 0.5 | L10: =INDEX('Type Chart'!$B$5:$P$19,MATCH(L$4,'Type Chart'!$A$5:$A$19,0),MATCH($C10,'Type Chart'!$B$4:$P$4,0))*IF($D10="",1,INDEX('Type Chart'!$B$5:$P$19,MATCH(L$4,'Type Chart'!$A$5:$A$19,0),MATCH($D10,'Type Chart'!$B$4:$P$4,0))) -> 1 | ... S10: =INDEX('Type Chart'!$B$5:$P$19,MATCH(S$4,'Type Chart'!$A$5:$A$19,0),MATCH($C10,'Type Chart'!$B$4:$P$4,0))*IF($D10="",1,INDEX('Type Chart'!$B$5:$P$19,MATCH(S$4,'Type Chart'!$A$5:$A$19,0),MATCH($D10,'Type Chart'!$B$4:$P$4,0))) -> 1
A11: 7 | B11: Squirtle | C11: =Pokedex!C11 -> Water | D11: =Pokedex!D11 -> 0 | E11: =INDEX('Type Chart'!$B$5:$P$19,MATCH(E$4,'Type Chart'!$A$5:$A$19,0),MATCH($C11,'Type Chart'!$B$4:$P$4,0))*IF($D11="",1,INDEX('Type Chart'!$B$5:$P$19,MATCH(E$4,'Type Chart'!$A$5:$A$19,0),MATCH($D11,'Type Chart'!$B$4:$P$4,0))) -> 1 | F11: =INDEX('Type Chart'!$B$5:$P$19,MATCH(F$4,'Type Chart'!$A$5:$A$19,0),MATCH($C11,'Type Chart'!$B$4:$P$4,0))*IF($D11="",1,INDEX('Type Chart'!$B$5:$P$19,MATCH(F$4,'Type Chart'!$A$5:$A$19,0),MATCH($D11,'Type Chart'!$B$4:$P$4,0))) -> 0.5 | G11: =INDEX('Type Chart'!$B$5:$P$19,MATCH(G$4,'Type Chart'!$A$5:$A$19,0),MATCH($C11,'Type Chart'!$B$4:$P$4,0))*IF($D11="",1,INDEX('Type Chart'!$B$5:$P$19,MATCH(G$4,'Type Chart'!$A$5:$A$19,0),MATCH($D11,'Type Chart'!$B$4:$P$4,0))) -> 0.5 | H11: =INDEX('Type Chart'!$B$5:$P$19,MATCH(H$4,'Type Chart'!$A$5:$A$19,0),MATCH($C11,'Type Chart'!$B$4:$P$4,0))*IF($D11="",1,INDEX('Type Chart'!$B$5:$P$19,MATCH(H$4,'Type Chart'!$A$5:$A$19,0),MATCH($D11,'Type Chart'!$B$4:$P$4,0))) -> 2 | I11: =INDEX('Type Chart'!$B$5:$P$19,MATCH(I$4,'Type Chart'!$A$5:$A$19,0),MATCH($C11,'Type Chart'!$B$4:$P$4,0))*IF($D11="",1,INDEX('Type Chart'!$B$5:$P$19,MATCH(I$4,'Type Chart'!$A$5:$A$19,0),MATCH($D11,'Type Chart'!$B$4:$P$4,0))) -> 2 | J11: =INDEX('Type Chart'!$B$5:$P$19,MATCH(J$4,'Type Chart'!$A$5:$A$19,0),MATCH($C11,'Type Chart'!$B$4:$P$4,0))*IF($D11="",1,INDEX('Type Chart'!$B$5:$P$19,MATCH(J$4,'Type Chart'!$A$5:$A$19,0),MATCH($D11,'Type Chart'!$B$4:$P$4,0))) -> 0.5 | K11: =INDEX('Type Chart'!$B$5:$P$19,MATCH(K$4,'Type Chart'!$A$5:$A$19,0),MATCH($C11,'Type Chart'!$B$4:$P$4,0))*IF($D11="",1,INDEX('Type Chart'!$B$5:$P$19,MATCH(K$4,'Type Chart'!$A$5:$A$19,0),MATCH($D11,'Type Chart'!$B$4:$P$4,0))) -> 1 | L11: =INDEX('Type Chart'!$B$5:$P$19,MATCH(L$4,'Type Chart'!$A$5:$A$19,0),MATCH($C11,'Type Chart'!$B$4:$P$4,0))*IF($D11="",1,INDEX('Type Chart'!$B$5:$P$19,MATCH(L$4,'Type Chart'!$A$5:$A$19,0),MATCH($D11,'Type Chart'!$B$4:$P$4,0))) -> 1 | ... S11: =INDEX('Type Chart'!$B$5:$P$19,MATCH(S$4,'Type Chart'!$A$5:$A$19,0),MATCH($C11,'Type Chart'!$B$4:$P$4,0))*IF($D11="",1,INDEX('Type Chart'!$B$5:$P$19,MATCH(S$4,'Type Chart'!$A$5:$A$19,0),MATCH($D11,'Type Chart'!$B$4:$P$4,0))) -> 1
A12: 8 | B12: Wartortle | C12: =Pokedex!C12 -> Water | D12: =Pokedex!D12 -> 0 | E12: =INDEX('Type Chart'!$B$5:$P$19,MATCH(E$4,'Type Chart'!$A$5:$A$19,0),MATCH($C12,'Type Chart'!$B$4:$P$4,0))*IF($D12="",1,INDEX('Type Chart'!$B$5:$P$19,MATCH(E$4,'Type Chart'!$A$5:$A$19,0),MATCH($D12,'Type Chart'!$B$4:$P$4,0))) -> 1 | F12: =INDEX('Type Chart'!$B$5:$P$19,MATCH(F$4,'Type Chart'!$A$5:$A$19,0),MATCH($C12,'Type Chart'!$B$4:$P$4,0))*IF($D12="",1,INDEX('Type Chart'!$B$5:$P$19,MATCH(F$4,'Type Chart'!$A$5:$A$19,0),MATCH($D12,'Type Chart'!$B$4:$P$4,0))) -> 0.5 | G12: =INDEX('Type Chart'!$B$5:$P$19,MATCH(G$4,'Type Chart'!$A$5:$A$19,0),MATCH($C12,'Type Chart'!$B$4:$P$4,0))*IF($D12="",1,INDEX('Type Chart'!$B$5:$P$19,MATCH(G$4,'Type Chart'!$A$5:$A$19,0),MATCH($D12,'Type Chart'!$B$4:$P$4,0))) -> 0.5 | H12: =INDEX('Type Chart'!$B$5:$P$19,MATCH(H$4,'Type Chart'!$A$5:$A$19,0),MATCH($C12,'Type Chart'!$B$4:$P$4,0))*IF($D12="",1,INDEX('Type Chart'!$B$5:$P$19,MATCH(H$4,'Type Chart'!$A$5:$A$19,0),MATCH($D12,'Type Chart'!$B$4:$P$4,0))) -> 2 | I12: =INDEX('Type Chart'!$B$5:$P$19,MATCH(I$4,'Type Chart'!$A$5:$A$19,0),MATCH($C12,'Type Chart'!$B$4:$P$4,0))*IF($D12="",1,INDEX('Type Chart'!$B$5:$P$19,MATCH(I$4,'Type Chart'!$A$5:$A$19,0),MATCH($D12,'Type Chart'!$B$4:$P$4,0))) -> 2 | J12: =INDEX('Type Chart'!$B$5:$P$19,MATCH(J$4,'Type Chart'!$A$5:$A$19,0),MATCH($C12,'Type Chart'!$B$4:$P$4,0))*IF($D12="",1,INDEX('Type Chart'!$B$5:$P$19,MATCH(J$4,'Type Chart'!$A$5:$A$19,0),MATCH($D12,'Type Chart'!$B$4:$P$4,0))) -> 0.5 | K12: =INDEX('Type Chart'!$B$5:$P$19,MATCH(K$4,'Type Chart'!$A$5:$A$19,0),MATCH($C12,'Type Chart'!$B$4:$P$4,0))*IF($D12="",1,INDEX('Type Chart'!$B$5:$P$19,MATCH(K$4,'Type Chart'!$A$5:$A$19,0),MATCH($D12,'Type Chart'!$B$4:$P$4,0))) -> 1 | L12: =INDEX('Type Chart'!$B$5:$P$19,MATCH(L$4,'Type Chart'!$A$5:$A$19,0),MATCH($C12,'Type Chart'!$B$4:$P$4,0))*IF($D12="",1,INDEX('Type Chart'!$B$5:$P$19,MATCH(L$4,'Type Chart'!$A$5:$A$19,0),MATCH($D12,'Type Chart'!$B$4:$P$4,0))) -> 1 | ... S12: =INDEX('Type Chart'!$B$5:$P$19,MATCH(S$4,'Type Chart'!$A$5:$A$19,0),MATCH($C12,'Type Chart'!$B$4:$P$4,0))*IF($D12="",1,INDEX('Type Chart'!$B$5:$P$19,MATCH(S$4,'Type Chart'!$A$5:$A$19,0),MATCH($D12,'Type Chart'!$B$4:$P$4,0))) -> 1
A13: 9 | B13: Blastoise | C13: =Pokedex!C13 -> Water | D13: =Pokedex!D13 -> 0 | E13: =INDEX('Type Chart'!$B$5:$P$19,MATCH(E$4,'Type Chart'!$A$5:$A$19,0),MATCH($C13,'Type Chart'!$B$4:$P$4,0))*IF($D13="",1,INDEX('Type Chart'!$B$5:$P$19,MATCH(E$4,'Type Chart'!$A$5:$A$19,0),MATCH($D13,'Type Chart'!$B$4:$P$4,0))) -> 1 | F13: =INDEX('Type Chart'!$B$5:$P$19,MATCH(F$4,'Type Chart'!$A$5:$A$19,0),MATCH($C13,'Type Chart'!$B$4:$P$4,0))*IF($D13="",1,INDEX('Type Chart'!$B$5:$P$19,MATCH(F$4,'Type Chart'!$A$5:$A$19,0),MATCH($D13,'Type Chart'!$B$4:$P$4,0))) -> 0.5 | G13: =INDEX('Type Chart'!$B$5:$P$19,MATCH(G$4,'Type Chart'!$A$5:$A$19,0),MATCH($C13,'Type Chart'!$B$4:$P$4,0))*IF($D13="",1,INDEX('Type Chart'!$B$5:$P$19,MATCH(G$4,'Type Chart'!$A$5:$A$19,0),MATCH($D13,'Type Chart'!$B$4:$P$4,0))) -> 0.5 | H13: =INDEX('Type Chart'!$B$5:$P$19,MATCH(H$4,'Type Chart'!$A$5:$A$19,0),MATCH($C13,'Type Chart'!$B$4:$P$4,0))*IF($D13="",1,INDEX('Type Chart'!$B$5:$P$19,MATCH(H$4,'Type Chart'!$A$5:$A$19,0),MATCH($D13,'Type Chart'!$B$4:$P$4,0))) -> 2 | I13: =INDEX('Type Chart'!$B$5:$P$19,MATCH(I$4,'Type Chart'!$A$5:$A$19,0),MATCH($C13,'Type Chart'!$B$4:$P$4,0))*IF($D13="",1,INDEX('Type Chart'!$B$5:$P$19,MATCH(I$4,'Type Chart'!$A$5:$A$19,0),MATCH($D13,'Type Chart'!$B$4:$P$4,0))) -> 2 | J13: =INDEX('Type Chart'!$B$5:$P$19,MATCH(J$4,'Type Chart'!$A$5:$A$19,0),MATCH($C13,'Type Chart'!$B$4:$P$4,0))*IF($D13="",1,INDEX('Type Chart'!$B$5:$P$19,MATCH(J$4,'Type Chart'!$A$5:$A$19,0),MATCH($D13,'Type Chart'!$B$4:$P$4,0))) -> 0.5 | K13: =INDEX('Type Chart'!$B$5:$P$19,MATCH(K$4,'Type Chart'!$A$5:$A$19,0),MATCH($C13,'Type Chart'!$B$4:$P$4,0))*IF($D13="",1,INDEX('Type Chart'!$B$5:$P$19,MATCH(K$4,'Type Chart'!$A$5:$A$19,0),MATCH($D13,'Type Chart'!$B$4:$P$4,0))) -> 1 | L13: =INDEX('Type Chart'!$B$5:$P$19,MATCH(L$4,'Type Chart'!$A$5:$A$19,0),MATCH($C13,'Type Chart'!$B$4:$P$4,0))*IF($D13="",1,INDEX('Type Chart'!$B$5:$P$19,MATCH(L$4,'Type Chart'!$A$5:$A$19,0),MATCH($D13,'Type Chart'!$B$4:$P$4,0))) -> 1 | ... S13: =INDEX('Type Chart'!$B$5:$P$19,MATCH(S$4,'Type Chart'!$A$5:$A$19,0),MATCH($C13,'Type Chart'!$B$4:$P$4,0))*IF($D13="",1,INDEX('Type Chart'!$B$5:$P$19,MATCH(S$4,'Type Chart'!$A$5:$A$19,0),MATCH($D13,'Type Chart'!$B$4:$P$4,0))) -> 1
A14: 10 | B14: Caterpie | C14: =Pokedex!C14 -> Bug | D14: =Pokedex!D14 -> 0 | E14: =INDEX('Type Chart'!$B$5:$P$19,MATCH(E$4,'Type Chart'!$A$5:$A$19,0),MATCH($C14,'Type Chart'!$B$4:$P$4,0))*IF($D14="",1,INDEX('Type Chart'!$B$5:$P$19,MATCH(E$4,'Type Chart'!$A$5:$A$19,0),MATCH($D14,'Type Chart'!$B$4:$P$4,0))) -> 1 | F14: =INDEX('Type Chart'!$B$5:$P$19,MATCH(F$4,'Type Chart'!$A$5:$A$19,0),MATCH($C14,'Type Chart'!$B$4:$P$4,0))*IF($D14="",1,INDEX('Type Chart'!$B$5:$P$19,MATCH(F$4,'Type Chart'!$A$5:$A$19,0),MATCH($D14,'Type Chart'!$B$4:$P$4,0))) -> 2 | G14: =INDEX('Type Chart'!$B$5:$P$19,MATCH(G$4,'Type Chart'!$A$5:$A$19,0),MATCH($C14,'Type Chart'!$B$4:$P$4,0))*IF($D14="",1,INDEX('Type Chart'!$B$5:$P$19,MATCH(G$4,'Type Chart'!$A$5:$A$19,0),MATCH($D14,'Type Chart'!$B$4:$P$4,0))) -> 1 | H14: =INDEX('Type Chart'!$B$5:$P$19,MATCH(H$4,'Type Chart'!$A$5:$A$19,0),MATCH($C14,'Type Chart'!$B$4:$P$4,0))*IF($D14="",1,INDEX('Type Chart'!$B$5:$P$19,MATCH(H$4,'Type Chart'!$A$5:$A$19,0),MATCH($D14,'Type Chart'!$B$4:$P$4,0))) -> 1 | I14: =INDEX('Type Chart'!$B$5:$P$19,MATCH(I$4,'Type Chart'!$A$5:$A$19,0),MATCH($C14,'Type Chart'!$B$4:$P$4,0))*IF($D14="",1,INDEX('Type Chart'!$B$5:$P$19,MATCH(I$4,'Type Chart'!$A$5:$A$19,0),MATCH($D14,'Type Chart'!$B$4:$P$4,0))) -> 0.5 | J14: =INDEX('Type Chart'!$B$5:$P$19,MATCH(J$4,'Type Chart'!$A$5:$A$19,0),MATCH($C14,'Type Chart'!$B$4:$P$4,0))*IF($D14="",1,INDEX('Type Chart'!$B$5:$P$19,MATCH(J$4,'Type Chart'!$A$5:$A$19,0),MATCH($D14,'Type Chart'!$B$4:$P$4,0))) -> 1 | K14: =INDEX('Type Chart'!$B$5:$P$19,MATCH(K$4,'Type Chart'!$A$5:$A$19,0),MATCH($C14,'Type Chart'!$B$4:$P$4,0))*IF($D14="",1,INDEX('Type Chart'!$B$5:$P$19,MATCH(K$4,'Type Chart'!$A$5:$A$19,0),MATCH($D14,'Type Chart'!$B$4:$P$4,0))) -> 0.5 | L14: =INDEX('Type Chart'!$B$5:$P$19,MATCH(L$4,'Type Chart'!$A$5:$A$19,0),MATCH($C14,'Type Chart'!$B$4:$P$4,0))*IF($D14="",1,INDEX('Type Chart'!$B$5:$P$19,MATCH(L$4,'Type Chart'!$A$5:$A$19,0),MATCH($D14,'Type Chart'!$B$4:$P$4,0))) -> 2 | ... S14: =INDEX('Type Chart'!$B$5:$P$19,MATCH(S$4,'Type Chart'!$A$5:$A$19,0),MATCH($C14,'Type Chart'!$B$4:$P$4,0))*IF($D14="",1,INDEX('Type Chart'!$B$5:$P$19,MATCH(S$4,'Type Chart'!$A$5:$A$19,0),MATCH($D14,'Type Chart'!$B$4:$P$4,0))) -> 1
A15: 11 | B15: Metapod | C15: =Pokedex!C15 -> Bug | D15: =Pokedex!D15 -> 0 | E15: =INDEX('Type Chart'!$B$5:$P$19,MATCH(E$4,'Type Chart'!$A$5:$A$19,0),MATCH($C15,'Type Chart'!$B$4:$P$4,0))*IF($D15="",1,INDEX('Type Chart'!$B$5:$P$19,MATCH(E$4,'Type Chart'!$A$5:$A$19,0),MATCH($D15,'Type Chart'!$B$4:$P$4,0))) -> 1 | F15: =INDEX('Type Chart'!$B$5:$P$19,MATCH(F$4,'Type Chart'!$A$5:$A$19,0),MATCH($C15,'Type Chart'!$B$4:$P$4,0))*IF($D15="",1,INDEX('Type Chart'!$B$5:$P$19,MATCH(F$4,'Type Chart'!$A$5:$A$19,0),MATCH($D15,'Type Chart'!$B$4:$P$4,0))) -> 2 | G15: =INDEX('Type Chart'!$B$5:$P$19,MATCH(G$4,'Type Chart'!$A$5:$A$19,0),MATCH($C15,'Type Chart'!$B$4:$P$4,0))*IF($D15="",1,INDEX('Type Chart'!$B$5:$P$19,MATCH(G$4,'Type Chart'!$A$5:$A$19,0),MATCH($D15,'Type Chart'!$B$4:$P$4,0))) -> 1 | H15: =INDEX('Type Chart'!$B$5:$P$19,MATCH(H$4,'Type Chart'!$A$5:$A$19,0),MATCH($C15,'Type Chart'!$B$4:$P$4,0))*IF($D15="",1,INDEX('Type Chart'!$B$5:$P$19,MATCH(H$4,'Type Chart'!$A$5:$A$19,0),MATCH($D15,'Type Chart'!$B$4:$P$4,0))) -> 1 | I15: =INDEX('Type Chart'!$B$5:$P$19,MATCH(I$4,'Type Chart'!$A$5:$A$19,0),MATCH($C15,'Type Chart'!$B$4:$P$4,0))*IF($D15="",1,INDEX('Type Chart'!$B$5:$P$19,MATCH(I$4,'Type Chart'!$A$5:$A$19,0),MATCH($D15,'Type Chart'!$B$4:$P$4,0))) -> 0.5 | J15: =INDEX('Type Chart'!$B$5:$P$19,MATCH(J$4,'Type Chart'!$A$5:$A$19,0),MATCH($C15,'Type Chart'!$B$4:$P$4,0))*IF($D15="",1,INDEX('Type Chart'!$B$5:$P$19,MATCH(J$4,'Type Chart'!$A$5:$A$19,0),MATCH($D15,'Type Chart'!$B$4:$P$4,0))) -> 1 | K15: =INDEX('Type Chart'!$B$5:$P$19,MATCH(K$4,'Type Chart'!$A$5:$A$19,0),MATCH($C15,'Type Chart'!$B$4:$P$4,0))*IF($D15="",1,INDEX('Type Chart'!$B$5:$P$19,MATCH(K$4,'Type Chart'!$A$5:$A$19,0),MATCH($D15,'Type Chart'!$B$4:$P$4,0))) -> 0.5 | L15: =INDEX('Type Chart'!$B$5:$P$19,MATCH(L$4,'Type Chart'!$A$5:$A$19,0),MATCH($C15,'Type Chart'!$B$4:$P$4,0))*IF($D15="",1,INDEX('Type Chart'!$B$5:$P$19,MATCH(L$4,'Type Chart'!$A$5:$A$19,0),MATCH($D15,'Type Chart'!$B$4:$P$4,0))) -> 2 | ... S15: =INDEX('Type Chart'!$B$5:$P$19,MATCH(S$4,'Type Chart'!$A$5:$A$19,0),MATCH($C15,'Type Chart'!$B$4:$P$4,0))*IF($D15="",1,INDEX('Type Chart'!$B$5:$P$19,MATCH(S$4,'Type Chart'!$A$5:$A$19,0),MATCH($D15,'Type Chart'!$B$4:$P$4,0))) -> 1
A16: 12 | B16: Butterfree | C16: =Pokedex!C16 -> Bug | D16: =Pokedex!D16 -> Flying | E16: =INDEX('Type Chart'!$B$5:$P$19,MATCH(E$4,'Type Chart'!$A$5:$A$19,0),MATCH($C16,'Type Chart'!$B$4:$P$4,0))*IF($D16="",1,INDEX('Type Chart'!$B$5:$P$19,MATCH(E$4,'Type Chart'!$A$5:$A$19,0),MATCH($D16,'Type Chart'!$B$4:$P$4,0))) -> 1 | F16: =INDEX('Type Chart'!$B$5:$P$19,MATCH(F$4,'Type Chart'!$A$5:$A$19,0),MATCH($C16,'Type Chart'!$B$4:$P$4,0))*IF($D16="",1,INDEX('Type Chart'!$B$5:$P$19,MATCH(F$4,'Type Chart'!$A$5:$A$19,0),MATCH($D16,'Type Chart'!$B$4:$P$4,0))) -> 2 | G16: =INDEX('Type Chart'!$B$5:$P$19,MATCH(G$4,'Type Chart'!$A$5:$A$19,0),MATCH($C16,'Type Chart'!$B$4:$P$4,0))*IF($D16="",1,INDEX('Type Chart'!$B$5:$P$19,MATCH(G$4,'Type Chart'!$A$5:$A$19,0),MATCH($D16,'Type Chart'!$B$4:$P$4,0))) -> 1 | H16: =INDEX('Type Chart'!$B$5:$P$19,MATCH(H$4,'Type Chart'!$A$5:$A$19,0),MATCH($C16,'Type Chart'!$B$4:$P$4,0))*IF($D16="",1,INDEX('Type Chart'!$B$5:$P$19,MATCH(H$4,'Type Chart'!$A$5:$A$19,0),MATCH($D16,'Type Chart'!$B$4:$P$4,0))) -> 2 | I16: =INDEX('Type Chart'!$B$5:$P$19,MATCH(I$4,'Type Chart'!$A$5:$A$19,0),MATCH($C16,'Type Chart'!$B$4:$P$4,0))*IF($D16="",1,INDEX('Type Chart'!$B$5:$P$19,MATCH(I$4,'Type Chart'!$A$5:$A$19,0),MATCH($D16,'Type Chart'!$B$4:$P$4,0))) -> 0.25 | J16: =INDEX('Type Chart'!$B$5:$P$19,MATCH(J$4,'Type Chart'!$A$5:$A$19,0),MATCH($C16,'Type Chart'!$B$4:$P$4,0))*IF($D16="",1,INDEX('Type Chart'!$B$5:$P$19,MATCH(J$4,'Type Chart'!$A$5:$A$19,0),MATCH($D16,'Type Chart'!$B$4:$P$4,0))) -> 2 | K16: =INDEX('Type Chart'!$B$5:$P$19,MATCH(K$4,'Type Chart'!$A$5:$A$19,0),MATCH($C16,'Type Chart'!$B$4:$P$4,0))*IF($D16="",1,INDEX('Type Chart'!$B$5:$P$19,MATCH(K$4,'Type Chart'!$A$5:$A$19,0),MATCH($D16,'Type Chart'!$B$4:$P$4,0))) -> 0.25 | L16: =INDEX('Type Chart'!$B$5:$P$19,MATCH(L$4,'Type Chart'!$A$5:$A$19,0),MATCH($C16,'Type Chart'!$B$4:$P$4,0))*IF($D16="",1,INDEX('Type Chart'!$B$5:$P$19,MATCH(L$4,'Type Chart'!$A$5:$A$19,0),MATCH($D16,'Type Chart'!$B$4:$P$4,0))) -> 2 | ... S16: =INDEX('Type Chart'!$B$5:$P$19,MATCH(S$4,'Type Chart'!$A$5:$A$19,0),MATCH($C16,'Type Chart'!$B$4:$P$4,0))*IF($D16="",1,INDEX('Type Chart'!$B$5:$P$19,MATCH(S$4,'Type Chart'!$A$5:$A$19,0),MATCH($D16,'Type Chart'!$B$4:$P$4,0))) -> 1
... A155: 151 | B155: Mew | C155: =Pokedex!C155 -> Psychic | D155: =Pokedex!D155 -> 0 | E155: =INDEX('Type Chart'!$B$5:$P$19,MATCH(E$4,'Type Chart'!$A$5:$A$19,0),MATCH($C155,'Type Chart'!$B$4:$P$4,0))*IF($D155="",1,INDEX('Type Chart'!$B$5:$P$19,MATCH(E$4,'Type Chart'!$A$5:$A$19,0),MATCH($D155,'Type Chart'!$B$4:$P$4,0))) -> 1 | F155: =INDEX('Type Chart'!$B$5:$P$19,MATCH(F$4,'Type Chart'!$A$5:$A$19,0),MATCH($C155,'Type Chart'!$B$4:$P$4,0))*IF($D155="",1,INDEX('Type Chart'!$B$5:$P$19,MATCH(F$4,'Type Chart'!$A$5:$A$19,0),MATCH($D155,'Type Chart'!$B$4:$P$4,0))) -> 1 | G155: =INDEX('Type Chart'!$B$5:$P$19,MATCH(G$4,'Type Chart'!$A$5:$A$19,0),MATCH($C155,'Type Chart'!$B$4:$P$4,0))*IF($D155="",1,INDEX('Type Chart'!$B$5:$P$19,MATCH(G$4,'Type Chart'!$A$5:$A$19,0),MATCH($D155,'Type Chart'!$B$4:$P$4,0))) -> 1 | H155: =INDEX('Type Chart'!$B$5:$P$19,MATCH(H$4,'Type Chart'!$A$5:$A$19,0),MATCH($C155,'Type Chart'!$B$4:$P$4,0))*IF($D155="",1,INDEX('Type Chart'!$B$5:$P$19,MATCH(H$4,'Type Chart'!$A$5:$A$19,0),MATCH($D155,'Type Chart'!$B$4:$P$4,0))) -> 1 | I155: =INDEX('Type Chart'!$B$5:$P$19,MATCH(I$4,'Type Chart'!$A$5:$A$19,0),MATCH($C155,'Type Chart'!$B$4:$P$4,0))*IF($D155="",1,INDEX('Type Chart'!$B$5:$P$19,MATCH(I$4,'Type Chart'!$A$5:$A$19,0),MATCH($D155,'Type Chart'!$B$4:$P$4,0))) -> 1 | J155: =INDEX('Type Chart'!$B$5:$P$19,MATCH(J$4,'Type Chart'!$A$5:$A$19,0),MATCH($C155,'Type Chart'!$B$4:$P$4,0))*IF($D155="",1,INDEX('Type Chart'!$B$5:$P$19,MATCH(J$4,'Type Chart'!$A$5:$A$19,0),MATCH($D155,'Type Chart'!$B$4:$P$4,0))) -> 1 | K155: =INDEX('Type Chart'!$B$5:$P$19,MATCH(K$4,'Type Chart'!$A$5:$A$19,0),MATCH($C155,'Type Chart'!$B$4:$P$4,0))*IF($D155="",1,INDEX('Type Chart'!$B$5:$P$19,MATCH(K$4,'Type Chart'!$A$5:$A$19,0),MATCH($D155,'Type Chart'!$B$4:$P$4,0))) -> 0.5 | L155: =INDEX('Type Chart'!$B$5:$P$19,MATCH(L$4,'Type Chart'!$A$5:$A$19,0),MATCH($C155,'Type Chart'!$B$4:$P$4,0))*IF($D155="",1,INDEX('Type Chart'!$B$5:$P$19,MATCH(L$4,'Type Chart'!$A$5:$A$19,0),MATCH($D155,'Type Chart'!$B$4:$P$4,0))) -> 1 | ... S155: =INDEX('Type Chart'!$B$5:$P$19,MATCH(S$4,'Type Chart'!$A$5:$A$19,0),MATCH($C155,'Type Chart'!$B$4:$P$4,0))*IF($D155="",1,INDEX('Type Chart'!$B$5:$P$19,MATCH(S$4,'Type Chart'!$A$5:$A$19,0),MATCH($D155,'Type Chart'!$B$4:$P$4,0))) -> 1

Sheet Yellow Bosses
A1: The Yellow Gauntlet — 49 Boss Pokemon
A2: 8 Gym Leaders + Elite Four + Champion. Yellow rosters (NOT Red/Blue). Multipliers are live formulas.
A4: Trainer | B4: Stage | C4: Pokemon | D4: Lv | E4: Type 1 | F4: Type 2 | G4: Ace | H4: Normal | I4: Fire | J4: Water | K4: Electric | L4: Grass | M4: Ice | N4: Fighting | O4: Poison | P4: Ground | Q4: Flying | R4: Psychic | S4: Bug | T4: Rock | U4: Ghost | V4: Dragon
A5: Brock | B5: Gym 1 | C5: Geodude | D5: 10 | E5: Rock | F5: Ground | H5: =INDEX('Type Chart'!$B$5:$P$19,MATCH(H$4,'Type Chart'!$A$5:$A$19,0),MATCH($E5,'Type Chart'!$B$4:$P$4,0))*IF($F5="",1,INDEX('Type Chart'!$B$5:$P$19,MATCH(H$4,'Type Chart'!$A$5:$A$19,0),MATCH($F5,'Type Chart'!$B$4:$P$4,0))) -> 0.5 | I5: =INDEX('Type Chart'!$B$5:$P$19,MATCH(I$4,'Type Chart'!$A$5:$A$19,0),MATCH($E5,'Type Chart'!$B$4:$P$4,0))*IF($F5="",1,INDEX('Type Chart'!$B$5:$P$19,MATCH(I$4,'Type Chart'!$A$5:$A$19,0),MATCH($F5,'Type Chart'!$B$4:$P$4,0))) -> 0.5 | J5: =INDEX('Type Chart'!$B$5:$P$19,MATCH(J$4,'Type Chart'!$A$5:$A$19,0),MATCH($E5,'Type Chart'!$B$4:$P$4,0))*IF($F5="",1,INDEX('Type Chart'!$B$5:$P$19,MATCH(J$4,'Type Chart'!$A$5:$A$19,0),MATCH($F5,'Type Chart'!$B$4:$P$4,0))) -> 4 | K5: =INDEX('Type Chart'!$B$5:$P$19,MATCH(K$4,'Type Chart'!$A$5:$A$19,0),MATCH($E5,'Type Chart'!$B$4:$P$4,0))*IF($F5="",1,INDEX('Type Chart'!$B$5:$P$19,MATCH(K$4,'Type Chart'!$A$5:$A$19,0),MATCH($F5,'Type Chart'!$B$4:$P$4,0))) -> 0 | L5: =INDEX('Type Chart'!$B$5:$P$19,MATCH(L$4,'Type Chart'!$A$5:$A$19,0),MATCH($E5,'Type Chart'!$B$4:$P$4,0))*IF($F5="",1,INDEX('Type Chart'!$B$5:$P$19,MATCH(L$4,'Type Chart'!$A$5:$A$19,0),MATCH($F5,'Type Chart'!$B$4:$P$4,0))) -> 4 | M5: =INDEX('Type Chart'!$B$5:$P$19,MATCH(M$4,'Type Chart'!$A$5:$A$19,0),MATCH($E5,'Type Chart'!$B$4:$P$4,0))*IF($F5="",1,INDEX('Type Chart'!$B$5:$P$19,MATCH(M$4,'Type Chart'!$A$5:$A$19,0),MATCH($F5,'Type Chart'!$B$4:$P$4,0))) -> 2 | N5: =INDEX('Type Chart'!$B$5:$P$19,MATCH(N$4,'Type Chart'!$A$5:$A$19,0),MATCH($E5,'Type Chart'!$B$4:$P$4,0))*IF($F5="",1,INDEX('Type Chart'!$B$5:$P$19,MATCH(N$4,'Type Chart'!$A$5:$A$19,0),MATCH($F5,'Type Chart'!$B$4:$P$4,0))) -> 2 | O5: =INDEX('Type Chart'!$B$5:$P$19,MATCH(O$4,'Type Chart'!$A$5:$A$19,0),MATCH($E5,'Type Chart'!$B$4:$P$4,0))*IF($F5="",1,INDEX('Type Chart'!$B$5:$P$19,MATCH(O$4,'Type Chart'!$A$5:$A$19,0),MATCH($F5,'Type Chart'!$B$4:$P$4,0))) -> 0.25 | ... V5: =INDEX('Type Chart'!$B$5:$P$19,MATCH(V$4,'Type Chart'!$A$5:$A$19,0),MATCH($E5,'Type Chart'!$B$4:$P$4,0))*IF($F5="",1,INDEX('Type Chart'!$B$5:$P$19,MATCH(V$4,'Type Chart'!$A$5:$A$19,0),MATCH($F5,'Type Chart'!$B$4:$P$4,0))) -> 1
A6: Brock | B6: Gym 1 | C6: Onix | D6: 12 | E6: Rock | F6: Ground | G6: ACE | H6: =INDEX('Type Chart'!$B$5:$P$19,MATCH(H$4,'Type Chart'!$A$5:$A$19,0),MATCH($E6,'Type Chart'!$B$4:$P$4,0))*IF($F6="",1,INDEX('Type Chart'!$B$5:$P$19,MATCH(H$4,'Type Chart'!$A$5:$A$19,0),MATCH($F6,'Type Chart'!$B$4:$P$4,0))) -> 0.5 | I6: =INDEX('Type Chart'!$B$5:$P$19,MATCH(I$4,'Type Chart'!$A$5:$A$19,0),MATCH($E6,'Type Chart'!$B$4:$P$4,0))*IF($F6="",1,INDEX('Type Chart'!$B$5:$P$19,MATCH(I$4,'Type Chart'!$A$5:$A$19,0),MATCH($F6,'Type Chart'!$B$4:$P$4,0))) -> 0.5 | J6: =INDEX('Type Chart'!$B$5:$P$19,MATCH(J$4,'Type Chart'!$A$5:$A$19,0),MATCH($E6,'Type Chart'!$B$4:$P$4,0))*IF($F6="",1,INDEX('Type Chart'!$B$5:$P$19,MATCH(J$4,'Type Chart'!$A$5:$A$19,0),MATCH($F6,'Type Chart'!$B$4:$P$4,0))) -> 4 | K6: =INDEX('Type Chart'!$B$5:$P$19,MATCH(K$4,'Type Chart'!$A$5:$A$19,0),MATCH($E6,'Type Chart'!$B$4:$P$4,0))*IF($F6="",1,INDEX('Type Chart'!$B$5:$P$19,MATCH(K$4,'Type Chart'!$A$5:$A$19,0),MATCH($F6,'Type Chart'!$B$4:$P$4,0))) -> 0 | L6: =INDEX('Type Chart'!$B$5:$P$19,MATCH(L$4,'Type Chart'!$A$5:$A$19,0),MATCH($E6,'Type Chart'!$B$4:$P$4,0))*IF($F6="",1,INDEX('Type Chart'!$B$5:$P$19,MATCH(L$4,'Type Chart'!$A$5:$A$19,0),MATCH($F6,'Type Chart'!$B$4:$P$4,0))) -> 4 | M6: =INDEX('Type Chart'!$B$5:$P$19,MATCH(M$4,'Type Chart'!$A$5:$A$19,0),MATCH($E6,'Type Chart'!$B$4:$P$4,0))*IF($F6="",1,INDEX('Type Chart'!$B$5:$P$19,MATCH(M$4,'Type Chart'!$A$5:$A$19,0),MATCH($F6,'Type Chart'!$B$4:$P$4,0))) -> 2 | N6: =INDEX('Type Chart'!$B$5:$P$19,MATCH(N$4,'Type Chart'!$A$5:$A$19,0),MATCH($E6,'Type Chart'!$B$4:$P$4,0))*IF($F6="",1,INDEX('Type Chart'!$B$5:$P$19,MATCH(N$4,'Type Chart'!$A$5:$A$19,0),MATCH($F6,'Type Chart'!$B$4:$P$4,0))) -> 2 | O6: =INDEX('Type Chart'!$B$5:$P$19,MATCH(O$4,'Type Chart'!$A$5:$A$19,0),MATCH($E6,'Type Chart'!$B$4:$P$4,0))*IF($F6="",1,INDEX('Type Chart'!$B$5:$P$19,MATCH(O$4,'Type Chart'!$A$5:$A$19,0),MATCH($F6,'Type Chart'!$B$4:$P$4,0))) -> 0.25 | ... V6: =INDEX('Type Chart'!$B$5:$P$19,MATCH(V$4,'Type Chart'!$A$5:$A$19,0),MATCH($E6,'Type Chart'!$B$4:$P$4,0))*IF($F6="",1,INDEX('Type Chart'!$B$5:$P$19,MATCH(V$4,'Type Chart'!$A$5:$A$19,0),MATCH($F6,'Type Chart'!$B$4:$P$4,0))) -> 1
A7: Misty | B7: Gym 2 | C7: Staryu | D7: 18 | E7: Water | H7: =INDEX('Type Chart'!$B$5:$P$19,MATCH(H$4,'Type Chart'!$A$5:$A$19,0),MATCH($E7,'Type Chart'!$B$4:$P$4,0))*IF($F7="",1,INDEX('Type Chart'!$B$5:$P$19,MATCH(H$4,'Type Chart'!$A$5:$A$19,0),MATCH($F7,'Type Chart'!$B$4:$P$4,0))) -> 1 | I7: =INDEX('Type Chart'!$B$5:$P$19,MATCH(I$4,'Type Chart'!$A$5:$A$19,0),MATCH($E7,'Type Chart'!$B$4:$P$4,0))*IF($F7="",1,INDEX('Type Chart'!$B$5:$P$19,MATCH(I$4,'Type Chart'!$A$5:$A$19,0),MATCH($F7,'Type Chart'!$B$4:$P$4,0))) -> 0.5 | J7: =INDEX('Type Chart'!$B$5:$P$19,MATCH(J$4,'Type Chart'!$A$5:$A$19,0),MATCH($E7,'Type Chart'!$B$4:$P$4,0))*IF($F7="",1,INDEX('Type Chart'!$B$5:$P$19,MATCH(J$4,'Type Chart'!$A$5:$A$19,0),MATCH($F7,'Type Chart'!$B$4:$P$4,0))) -> 0.5 | K7: =INDEX('Type Chart'!$B$5:$P$19,MATCH(K$4,'Type Chart'!$A$5:$A$19,0),MATCH($E7,'Type Chart'!$B$4:$P$4,0))*IF($F7="",1,INDEX('Type Chart'!$B$5:$P$19,MATCH(K$4,'Type Chart'!$A$5:$A$19,0),MATCH($F7,'Type Chart'!$B$4:$P$4,0))) -> 2 | L7: =INDEX('Type Chart'!$B$5:$P$19,MATCH(L$4,'Type Chart'!$A$5:$A$19,0),MATCH($E7,'Type Chart'!$B$4:$P$4,0))*IF($F7="",1,INDEX('Type Chart'!$B$5:$P$19,MATCH(L$4,'Type Chart'!$A$5:$A$19,0),MATCH($F7,'Type Chart'!$B$4:$P$4,0))) -> 2 | M7: =INDEX('Type Chart'!$B$5:$P$19,MATCH(M$4,'Type Chart'!$A$5:$A$19,0),MATCH($E7,'Type Chart'!$B$4:$P$4,0))*IF($F7="",1,INDEX('Type Chart'!$B$5:$P$19,MATCH(M$4,'Type Chart'!$A$5:$A$19,0),MATCH($F7,'Type Chart'!$B$4:$P$4,0))) -> 0.5 | N7: =INDEX('Type Chart'!$B$5:$P$19,MATCH(N$4,'Type Chart'!$A$5:$A$19,0),MATCH($E7,'Type Chart'!$B$4:$P$4,0))*IF($F7="",1,INDEX('Type Chart'!$B$5:$P$19,MATCH(N$4,'Type Chart'!$A$5:$A$19,0),MATCH($F7,'Type Chart'!$B$4:$P$4,0))) -> 1 | O7: =INDEX('Type Chart'!$B$5:$P$19,MATCH(O$4,'Type Chart'!$A$5:$A$19,0),MATCH($E7,'Type Chart'!$B$4:$P$4,0))*IF($F7="",1,INDEX('Type Chart'!$B$5:$P$19,MATCH(O$4,'Type Chart'!$A$5:$A$19,0),MATCH($F7,'Type Chart'!$B$4:$P$4,0))) -> 1 | ... V7: =INDEX('Type Chart'!$B$5:$P$19,MATCH(V$4,'Type Chart'!$A$5:$A$19,0),MATCH($E7,'Type Chart'!$B$4:$P$4,0))*IF($F7="",1,INDEX('Type Chart'!$B$5:$P$19,MATCH(V$4,'Type Chart'!$A$5:$A$19,0),MATCH($F7,'Type Chart'!$B$4:$P$4,0))) -> 1
A8: Misty | B8: Gym 2 | C8: Starmie | D8: 21 | E8: Water | F8: Psychic | G8: ACE | H8: =INDEX('Type Chart'!$B$5:$P$19,MATCH(H$4,'Type Chart'!$A$5:$A$19,0),MATCH($E8,'Type Chart'!$B$4:$P$4,0))*IF($F8="",1,INDEX('Type Chart'!$B$5:$P$19,MATCH(H$4,'Type Chart'!$A$5:$A$19,0),MATCH($F8,'Type Chart'!$B$4:$P$4,0))) -> 1 | I8: =INDEX('Type Chart'!$B$5:$P$19,MATCH(I$4,'Type Chart'!$A$5:$A$19,0),MATCH($E8,'Type Chart'!$B$4:$P$4,0))*IF($F8="",1,INDEX('Type Chart'!$B$5:$P$19,MATCH(I$4,'Type Chart'!$A$5:$A$19,0),MATCH($F8,'Type Chart'!$B$4:$P$4,0))) -> 0.5 | J8: =INDEX('Type Chart'!$B$5:$P$19,MATCH(J$4,'Type Chart'!$A$5:$A$19,0),MATCH($E8,'Type Chart'!$B$4:$P$4,0))*IF($F8="",1,INDEX('Type Chart'!$B$5:$P$19,MATCH(J$4,'Type Chart'!$A$5:$A$19,0),MATCH($F8,'Type Chart'!$B$4:$P$4,0))) -> 0.5 | K8: =INDEX('Type Chart'!$B$5:$P$19,MATCH(K$4,'Type Chart'!$A$5:$A$19,0),MATCH($E8,'Type Chart'!$B$4:$P$4,0))*IF($F8="",1,INDEX('Type Chart'!$B$5:$P$19,MATCH(K$4,'Type Chart'!$A$5:$A$19,0),MATCH($F8,'Type Chart'!$B$4:$P$4,0))) -> 2 | L8: =INDEX('Type Chart'!$B$5:$P$19,MATCH(L$4,'Type Chart'!$A$5:$A$19,0),MATCH($E8,'Type Chart'!$B$4:$P$4,0))*IF($F8="",1,INDEX('Type Chart'!$B$5:$P$19,MATCH(L$4,'Type Chart'!$A$5:$A$19,0),MATCH($F8,'Type Chart'!$B$4:$P$4,0))) -> 2 | M8: =INDEX('Type Chart'!$B$5:$P$19,MATCH(M$4,'Type Chart'!$A$5:$A$19,0),MATCH($E8,'Type Chart'!$B$4:$P$4,0))*IF($F8="",1,INDEX('Type Chart'!$B$5:$P$19,MATCH(M$4,'Type Chart'!$A$5:$A$19,0),MATCH($F8,'Type Chart'!$B$4:$P$4,0))) -> 0.5 | N8: =INDEX('Type Chart'!$B$5:$P$19,MATCH(N$4,'Type Chart'!$A$5:$A$19,0),MATCH($E8,'Type Chart'!$B$4:$P$4,0))*IF($F8="",1,INDEX('Type Chart'!$B$5:$P$19,MATCH(N$4,'Type Chart'!$A$5:$A$19,0),MATCH($F8,'Type Chart'!$B$4:$P$4,0))) -> 0.5 | O8: =INDEX('Type Chart'!$B$5:$P$19,MATCH(O$4,'Type Chart'!$A$5:$A$19,0),MATCH($E8,'Type Chart'!$B$4:$P$4,0))*IF($F8="",1,INDEX('Type Chart'!$B$5:$P$19,MATCH(O$4,'Type Chart'!$A$5:$A$19,0),MATCH($F8,'Type Chart'!$B$4:$P$4,0))) -> 1 | ... V8: =INDEX('Type Chart'!$B$5:$P$19,MATCH(V$4,'Type Chart'!$A$5:$A$19,0),MATCH($E8,'Type Chart'!$B$4:$P$4,0))*IF($F8="",1,INDEX('Type Chart'!$B$5:$P$19,MATCH(V$4,'Type Chart'!$A$5:$A$19,0),MATCH($F8,'Type Chart'!$B$4:$P$4,0))) -> 1
A9: Lt. Surge | B9: Gym 3 | C9: Raichu | D9: 28 | E9: Electric | G9: ACE | H9: =INDEX('Type Chart'!$B$5:$P$19,MATCH(H$4,'Type Chart'!$A$5:$A$19,0),MATCH($E9,'Type Chart'!$B$4:$P$4,0))*IF($F9="",1,INDEX('Type Chart'!$B$5:$P$19,MATCH(H$4,'Type Chart'!$A$5:$A$19,0),MATCH($F9,'Type Chart'!$B$4:$P$4,0))) -> 1 | I9: =INDEX('Type Chart'!$B$5:$P$19,MATCH(I$4,'Type Chart'!$A$5:$A$19,0),MATCH($E9,'Type Chart'!$B$4:$P$4,0))*IF($F9="",1,INDEX('Type Chart'!$B$5:$P$19,MATCH(I$4,'Type Chart'!$A$5:$A$19,0),MATCH($F9,'Type Chart'!$B$4:$P$4,0))) -> 1 | J9: =INDEX('Type Chart'!$B$5:$P$19,MATCH(J$4,'Type Chart'!$A$5:$A$19,0),MATCH($E9,'Type Chart'!$B$4:$P$4,0))*IF($F9="",1,INDEX('Type Chart'!$B$5:$P$19,MATCH(J$4,'Type Chart'!$A$5:$A$19,0),MATCH($F9,'Type Chart'!$B$4:$P$4,0))) -> 1 | K9: =INDEX('Type Chart'!$B$5:$P$19,MATCH(K$4,'Type Chart'!$A$5:$A$19,0),MATCH($E9,'Type Chart'!$B$4:$P$4,0))*IF($F9="",1,INDEX('Type Chart'!$B$5:$P$19,MATCH(K$4,'Type Chart'!$A$5:$A$19,0),MATCH($F9,'Type Chart'!$B$4:$P$4,0))) -> 0.5 | L9: =INDEX('Type Chart'!$B$5:$P$19,MATCH(L$4,'Type Chart'!$A$5:$A$19,0),MATCH($E9,'Type Chart'!$B$4:$P$4,0))*IF($F9="",1,INDEX('Type Chart'!$B$5:$P$19,MATCH(L$4,'Type Chart'!$A$5:$A$19,0),MATCH($F9,'Type Chart'!$B$4:$P$4,0))) -> 1 | M9: =INDEX('Type Chart'!$B$5:$P$19,MATCH(M$4,'Type Chart'!$A$5:$A$19,0),MATCH($E9,'Type Chart'!$B$4:$P$4,0))*IF($F9="",1,INDEX('Type Chart'!$B$5:$P$19,MATCH(M$4,'Type Chart'!$A$5:$A$19,0),MATCH($F9,'Type Chart'!$B$4:$P$4,0))) -> 1 | N9: =INDEX('Type Chart'!$B$5:$P$19,MATCH(N$4,'Type Chart'!$A$5:$A$19,0),MATCH($E9,'Type Chart'!$B$4:$P$4,0))*IF($F9="",1,INDEX('Type Chart'!$B$5:$P$19,MATCH(N$4,'Type Chart'!$A$5:$A$19,0),MATCH($F9,'Type Chart'!$B$4:$P$4,0))) -> 1 | O9: =INDEX('Type Chart'!$B$5:$P$19,MATCH(O$4,'Type Chart'!$A$5:$A$19,0),MATCH($E9,'Type Chart'!$B$4:$P$4,0))*IF($F9="",1,INDEX('Type Chart'!$B$5:$P$19,MATCH(O$4,'Type Chart'!$A$5:$A$19,0),MATCH($F9,'Type Chart'!$B$4:$P$4,0))) -> 1 | ... V9: =INDEX('Type Chart'!$B$5:$P$19,MATCH(V$4,'Type Chart'!$A$5:$A$19,0),MATCH($E9,'Type Chart'!$B$4:$P$4,0))*IF($F9="",1,INDEX('Type Chart'!$B$5:$P$19,MATCH(V$4,'Type Chart'!$A$5:$A$19,0),MATCH($F9,'Type Chart'!$B$4:$P$4,0))) -> 1
A10: Erika | B10: Gym 4 | C10: Tangela | D10: 30 | E10: Grass | H10: =INDEX('Type Chart'!$B$5:$P$19,MATCH(H$4,'Type Chart'!$A$5:$A$19,0),MATCH($E10,'Type Chart'!$B$4:$P$4,0))*IF($F10="",1,INDEX('Type Chart'!$B$5:$P$19,MATCH(H$4,'Type Chart'!$A$5:$A$19,0),MATCH($F10,'Type Chart'!$B$4:$P$4,0))) -> 1 | I10: =INDEX('Type Chart'!$B$5:$P$19,MATCH(I$4,'Type Chart'!$A$5:$A$19,0),MATCH($E10,'Type Chart'!$B$4:$P$4,0))*IF($F10="",1,INDEX('Type Chart'!$B$5:$P$19,MATCH(I$4,'Type Chart'!$A$5:$A$19,0),MATCH($F10,'Type Chart'!$B$4:$P$4,0))) -> 2 | J10: =INDEX('Type Chart'!$B$5:$P$19,MATCH(J$4,'Type Chart'!$A$5:$A$19,0),MATCH($E10,'Type Chart'!$B$4:$P$4,0))*IF($F10="",1,INDEX('Type Chart'!$B$5:$P$19,MATCH(J$4,'Type Chart'!$A$5:$A$19,0),MATCH($F10,'Type Chart'!$B$4:$P$4,0))) -> 0.5 | K10: =INDEX('Type Chart'!$B$5:$P$19,MATCH(K$4,'Type Chart'!$A$5:$A$19,0),MATCH($E10,'Type Chart'!$B$4:$P$4,0))*IF($F10="",1,INDEX('Type Chart'!$B$5:$P$19,MATCH(K$4,'Type Chart'!$A$5:$A$19,0),MATCH($F10,'Type Chart'!$B$4:$P$4,0))) -> 0.5 | L10: =INDEX('Type Chart'!$B$5:$P$19,MATCH(L$4,'Type Chart'!$A$5:$A$19,0),MATCH($E10,'Type Chart'!$B$4:$P$4,0))*IF($F10="",1,INDEX('Type Chart'!$B$5:$P$19,MATCH(L$4,'Type Chart'!$A$5:$A$19,0),MATCH($F10,'Type Chart'!$B$4:$P$4,0))) -> 0.5 | M10: =INDEX('Type Chart'!$B$5:$P$19,MATCH(M$4,'Type Chart'!$A$5:$A$19,0),MATCH($E10,'Type Chart'!$B$4:$P$4,0))*IF($F10="",1,INDEX('Type Chart'!$B$5:$P$19,MATCH(M$4,'Type Chart'!$A$5:$A$19,0),MATCH($F10,'Type Chart'!$B$4:$P$4,0))) -> 2 | N10: =INDEX('Type Chart'!$B$5:$P$19,MATCH(N$4,'Type Chart'!$A$5:$A$19,0),MATCH($E10,'Type Chart'!$B$4:$P$4,0))*IF($F10="",1,INDEX('Type Chart'!$B$5:$P$19,MATCH(N$4,'Type Chart'!$A$5:$A$19,0),MATCH($F10,'Type Chart'!$B$4:$P$4,0))) -> 1 | O10: =INDEX('Type Chart'!$B$5:$P$19,MATCH(O$4,'Type Chart'!$A$5:$A$19,0),MATCH($E10,'Type Chart'!$B$4:$P$4,0))*IF($F10="",1,INDEX('Type Chart'!$B$5:$P$19,MATCH(O$4,'Type Chart'!$A$5:$A$19,0),MATCH($F10,'Type Chart'!$B$4:$P$4,0))) -> 2 | ... V10: =INDEX('Type Chart'!$B$5:$P$19,MATCH(V$4,'Type Chart'!$A$5:$A$19,0),MATCH($E10,'Type Chart'!$B$4:$P$4,0))*IF($F10="",1,INDEX('Type Chart'!$B$5:$P$19,MATCH(V$4,'Type Chart'!$A$5:$A$19,0),MATCH($F10,'Type Chart'!$B$4:$P$4,0))) -> 1
A11: Erika | B11: Gym 4 | C11: Weepinbell | D11: 32 | E11: Grass | F11: Poison | H11: =INDEX('Type Chart'!$B$5:$P$19,MATCH(H$4,'Type Chart'!$A$5:$A$19,0),MATCH($E11,'Type Chart'!$B$4:$P$4,0))*IF($F11="",1,INDEX('Type Chart'!$B$5:$P$19,MATCH(H$4,'Type Chart'!$A$5:$A$19,0),MATCH($F11,'Type Chart'!$B$4:$P$4,0))) -> 1 | I11: =INDEX('Type Chart'!$B$5:$P$19,MATCH(I$4,'Type Chart'!$A$5:$A$19,0),MATCH($E11,'Type Chart'!$B$4:$P$4,0))*IF($F11="",1,INDEX('Type Chart'!$B$5:$P$19,MATCH(I$4,'Type Chart'!$A$5:$A$19,0),MATCH($F11,'Type Chart'!$B$4:$P$4,0))) -> 2 | J11: =INDEX('Type Chart'!$B$5:$P$19,MATCH(J$4,'Type Chart'!$A$5:$A$19,0),MATCH($E11,'Type Chart'!$B$4:$P$4,0))*IF($F11="",1,INDEX('Type Chart'!$B$5:$P$19,MATCH(J$4,'Type Chart'!$A$5:$A$19,0),MATCH($F11,'Type Chart'!$B$4:$P$4,0))) -> 0.5 | K11: =INDEX('Type Chart'!$B$5:$P$19,MATCH(K$4,'Type Chart'!$A$5:$A$19,0),MATCH($E11,'Type Chart'!$B$4:$P$4,0))*IF($F11="",1,INDEX('Type Chart'!$B$5:$P$19,MATCH(K$4,'Type Chart'!$A$5:$A$19,0),MATCH($F11,'Type Chart'!$B$4:$P$4,0))) -> 0.5 | L11: =INDEX('Type Chart'!$B$5:$P$19,MATCH(L$4,'Type Chart'!$A$5:$A$19,0),MATCH($E11,'Type Chart'!$B$4:$P$4,0))*IF($F11="",1,INDEX('Type Chart'!$B$5:$P$19,MATCH(L$4,'Type Chart'!$A$5:$A$19,0),MATCH($F11,'Type Chart'!$B$4:$P$4,0))) -> 0.25 | M11: =INDEX('Type Chart'!$B$5:$P$19,MATCH(M$4,'Type Chart'!$A$5:$A$19,0),MATCH($E11,'Type Chart'!$B$4:$P$4,0))*IF($F11="",1,INDEX('Type Chart'!$B$5:$P$19,MATCH(M$4,'Type Chart'!$A$5:$A$19,0),MATCH($F11,'Type Chart'!$B$4:$P$4,0))) -> 2 | N11: =INDEX('Type Chart'!$B$5:$P$19,MATCH(N$4,'Type Chart'!$A$5:$A$19,0),MATCH($E11,'Type Chart'!$B$4:$P$4,0))*IF($F11="",1,INDEX('Type Chart'!$B$5:$P$19,MATCH(N$4,'Type Chart'!$A$5:$A$19,0),MATCH($F11,'Type Chart'!$B$4:$P$4,0))) -> 0.5 | O11: =INDEX('Type Chart'!$B$5:$P$19,MATCH(O$4,'Type Chart'!$A$5:$A$19,0),MATCH($E11,'Type Chart'!$B$4:$P$4,0))*IF($F11="",1,INDEX('Type Chart'!$B$5:$P$19,MATCH(O$4,'Type Chart'!$A$5:$A$19,0),MATCH($F11,'Type Chart'!$B$4:$P$4,0))) -> 1 | ... V11: =INDEX('Type Chart'!$B$5:$P$19,MATCH(V$4,'Type Chart'!$A$5:$A$19,0),MATCH($E11,'Type Chart'!$B$4:$P$4,0))*IF($F11="",1,INDEX('Type Chart'!$B$5:$P$19,MATCH(V$4,'Type Chart'!$A$5:$A$19,0),MATCH($F11,'Type Chart'!$B$4:$P$4,0))) -> 1
A12: Erika | B12: Gym 4 | C12: Gloom | D12: 32 | E12: Grass | F12: Poison | G12: ACE | H12: =INDEX('Type Chart'!$B$5:$P$19,MATCH(H$4,'Type Chart'!$A$5:$A$19,0),MATCH($E12,'Type Chart'!$B$4:$P$4,0))*IF($F12="",1,INDEX('Type Chart'!$B$5:$P$19,MATCH(H$4,'Type Chart'!$A$5:$A$19,0),MATCH($F12,'Type Chart'!$B$4:$P$4,0))) -> 1 | I12: =INDEX('Type Chart'!$B$5:$P$19,MATCH(I$4,'Type Chart'!$A$5:$A$19,0),MATCH($E12,'Type Chart'!$B$4:$P$4,0))*IF($F12="",1,INDEX('Type Chart'!$B$5:$P$19,MATCH(I$4,'Type Chart'!$A$5:$A$19,0),MATCH($F12,'Type Chart'!$B$4:$P$4,0))) -> 2 | J12: =INDEX('Type Chart'!$B$5:$P$19,MATCH(J$4,'Type Chart'!$A$5:$A$19,0),MATCH($E12,'Type Chart'!$B$4:$P$4,0))*IF($F12="",1,INDEX('Type Chart'!$B$5:$P$19,MATCH(J$4,'Type Chart'!$A$5:$A$19,0),MATCH($F12,'Type Chart'!$B$4:$P$4,0))) -> 0.5 | K12: =INDEX('Type Chart'!$B$5:$P$19,MATCH(K$4,'Type Chart'!$A$5:$A$19,0),MATCH($E12,'Type Chart'!$B$4:$P$4,0))*IF($F12="",1,INDEX('Type Chart'!$B$5:$P$19,MATCH(K$4,'Type Chart'!$A$5:$A$19,0),MATCH($F12,'Type Chart'!$B$4:$P$4,0))) -> 0.5 | L12: =INDEX('Type Chart'!$B$5:$P$19,MATCH(L$4,'Type Chart'!$A$5:$A$19,0),MATCH($E12,'Type Chart'!$B$4:$P$4,0))*IF($F12="",1,INDEX('Type Chart'!$B$5:$P$19,MATCH(L$4,'Type Chart'!$A$5:$A$19,0),MATCH($F12,'Type Chart'!$B$4:$P$4,0))) -> 0.25 | M12: =INDEX('Type Chart'!$B$5:$P$19,MATCH(M$4,'Type Chart'!$A$5:$A$19,0),MATCH($E12,'Type Chart'!$B$4:$P$4,0))*IF($F12="",1,INDEX('Type Chart'!$B$5:$P$19,MATCH(M$4,'Type Chart'!$A$5:$A$19,0),MATCH($F12,'Type Chart'!$B$4:$P$4,0))) -> 2 | N12: =INDEX('Type Chart'!$B$5:$P$19,MATCH(N$4,'Type Chart'!$A$5:$A$19,0),MATCH($E12,'Type Chart'!$B$4:$P$4,0))*IF($F12="",1,INDEX('Type Chart'!$B$5:$P$19,MATCH(N$4,'Type Chart'!$A$5:$A$19,0),MATCH($F12,'Type Chart'!$B$4:$P$4,0))) -> 0.5 | O12: =INDEX('Type Chart'!$B$5:$P$19,MATCH(O$4,'Type Chart'!$A$5:$A$19,0),MATCH($E12,'Type Chart'!$B$4:$P$4,0))*IF($F12="",1,INDEX('Type Chart'!$B$5:$P$19,MATCH(O$4,'Type Chart'!$A$5:$A$19,0),MATCH($F12,'Type Chart'!$B$4:$P$4,0))) -> 1 | ... V12: =INDEX('Type Chart'!$B$5:$P$19,MATCH(V$4,'Type Chart'!$A$5:$A$19,0),MATCH($E12,'Type Chart'!$B$4:$P$4,0))*IF($F12="",1,INDEX('Type Chart'!$B$5:$P$19,MATCH(V$4,'Type Chart'!$A$5:$A$19,0),MATCH($F12,'Type Chart'!$B$4:$P$4,0))) -> 1
A13: Koga | B13: Gym 5 | C13: Venonat | D13: 44 | E13: Bug | F13: Poison | H13: =INDEX('Type Chart'!$B$5:$P$19,MATCH(H$4,'Type Chart'!$A$5:$A$19,0),MATCH($E13,'Type Chart'!$B$4:$P$4,0))*IF($F13="",1,INDEX('Type Chart'!$B$5:$P$19,MATCH(H$4,'Type Chart'!$A$5:$A$19,0),MATCH($F13,'Type Chart'!$B$4:$P$4,0))) -> 1 | I13: =INDEX('Type Chart'!$B$5:$P$19,MATCH(I$4,'Type Chart'!$A$5:$A$19,0),MATCH($E13,'Type Chart'!$B$4:$P$4,0))*IF($F13="",1,INDEX('Type Chart'!$B$5:$P$19,MATCH(I$4,'Type Chart'!$A$5:$A$19,0),MATCH($F13,'Type Chart'!$B$4:$P$4,0))) -> 2 | J13: =INDEX('Type Chart'!$B$5:$P$19,MATCH(J$4,'Type Chart'!$A$5:$A$19,0),MATCH($E13,'Type Chart'!$B$4:$P$4,0))*IF($F13="",1,INDEX('Type Chart'!$B$5:$P$19,MATCH(J$4,'Type Chart'!$A$5:$A$19,0),MATCH($F13,'Type Chart'!$B$4:$P$4,0))) -> 1 | K13: =INDEX('Type Chart'!$B$5:$P$19,MATCH(K$4,'Type Chart'!$A$5:$A$19,0),MATCH($E13,'Type Chart'!$B$4:$P$4,0))*IF($F13="",1,INDEX('Type Chart'!$B$5:$P$19,MATCH(K$4,'Type Chart'!$A$5:$A$19,0),MATCH($F13,'Type Chart'!$B$4:$P$4,0))) -> 1 | L13: =INDEX('Type Chart'!$B$5:$P$19,MATCH(L$4,'Type Chart'!$A$5:$A$19,0),MATCH($E13,'Type Chart'!$B$4:$P$4,0))*IF($F13="",1,INDEX('Type Chart'!$B$5:$P$19,MATCH(L$4,'Type Chart'!$A$5:$A$19,0),MATCH($F13,'Type Chart'!$B$4:$P$4,0))) -> 0.25 | M13: =INDEX('Type Chart'!$B$5:$P$19,MATCH(M$4,'Type Chart'!$A$5:$A$19,0),MATCH($E13,'Type Chart'!$B$4:$P$4,0))*IF($F13="",1,INDEX('Type Chart'!$B$5:$P$19,MATCH(M$4,'Type Chart'!$A$5:$A$19,0),MATCH($F13,'Type Chart'!$B$4:$P$4,0))) -> 1 | N13: =INDEX('Type Chart'!$B$5:$P$19,MATCH(N$4,'Type Chart'!$A$5:$A$19,0),MATCH($E13,'Type Chart'!$B$4:$P$4,0))*IF($F13="",1,INDEX('Type Chart'!$B$5:$P$19,MATCH(N$4,'Type Chart'!$A$5:$A$19,0),MATCH($F13,'Type Chart'!$B$4:$P$4,0))) -> 0.25 | O13: =INDEX('Type Chart'!$B$5:$P$19,MATCH(O$4,'Type Chart'!$A$5:$A$19,0),MATCH($E13,'Type Chart'!$B$4:$P$4,0))*IF($F13="",1,INDEX('Type Chart'!$B$5:$P$19,MATCH(O$4,'Type Chart'!$A$5:$A$19,0),MATCH($F13,'Type Chart'!$B$4:$P$4,0))) -> 1 | ... V13: =INDEX('Type Chart'!$B$5:$P$19,MATCH(V$4,'Type Chart'!$A$5:$A$19,0),MATCH($E13,'Type Chart'!$B$4:$P$4,0))*IF($F13="",1,INDEX('Type Chart'!$B$5:$P$19,MATCH(V$4,'Type Chart'!$A$5:$A$19,0),MATCH($F13,'Type Chart'!$B$4:$P$4,0))) -> 1
A14: Koga | B14: Gym 5 | C14: Venonat | D14: 46 | E14: Bug | F14: Poison | H14: =INDEX('Type Chart'!$B$5:$P$19,MATCH(H$4,'Type Chart'!$A$5:$A$19,0),MATCH($E14,'Type Chart'!$B$4:$P$4,0))*IF($F14="",1,INDEX('Type Chart'!$B$5:$P$19,MATCH(H$4,'Type Chart'!$A$5:$A$19,0),MATCH($F14,'Type Chart'!$B$4:$P$4,0))) -> 1 | I14: =INDEX('Type Chart'!$B$5:$P$19,MATCH(I$4,'Type Chart'!$A$5:$A$19,0),MATCH($E14,'Type Chart'!$B$4:$P$4,0))*IF($F14="",1,INDEX('Type Chart'!$B$5:$P$19,MATCH(I$4,'Type Chart'!$A$5:$A$19,0),MATCH($F14,'Type Chart'!$B$4:$P$4,0))) -> 2 | J14: =INDEX('Type Chart'!$B$5:$P$19,MATCH(J$4,'Type Chart'!$A$5:$A$19,0),MATCH($E14,'Type Chart'!$B$4:$P$4,0))*IF($F14="",1,INDEX('Type Chart'!$B$5:$P$19,MATCH(J$4,'Type Chart'!$A$5:$A$19,0),MATCH($F14,'Type Chart'!$B$4:$P$4,0))) -> 1 | K14: =INDEX('Type Chart'!$B$5:$P$19,MATCH(K$4,'Type Chart'!$A$5:$A$19,0),MATCH($E14,'Type Chart'!$B$4:$P$4,0))*IF($F14="",1,INDEX('Type Chart'!$B$5:$P$19,MATCH(K$4,'Type Chart'!$A$5:$A$19,0),MATCH($F14,'Type Chart'!$B$4:$P$4,0))) -> 1 | L14: =INDEX('Type Chart'!$B$5:$P$19,MATCH(L$4,'Type Chart'!$A$5:$A$19,0),MATCH($E14,'Type Chart'!$B$4:$P$4,0))*IF($F14="",1,INDEX('Type Chart'!$B$5:$P$19,MATCH(L$4,'Type Chart'!$A$5:$A$19,0),MATCH($F14,'Type Chart'!$B$4:$P$4,0))) -> 0.25 | M14: =INDEX('Type Chart'!$B$5:$P$19,MATCH(M$4,'Type Chart'!$A$5:$A$19,0),MATCH($E14,'Type Chart'!$B$4:$P$4,0))*IF($F14="",1,INDEX('Type Chart'!$B$5:$P$19,MATCH(M$4,'Type Chart'!$A$5:$A$19,0),MATCH($F14,'Type Chart'!$B$4:$P$4,0))) -> 1 | N14: =INDEX('Type Chart'!$B$5:$P$19,MATCH(N$4,'Type Chart'!$A$5:$A$19,0),MATCH($E14,'Type Chart'!$B$4:$P$4,0))*IF($F14="",1,INDEX('Type Chart'!$B$5:$P$19,MATCH(N$4,'Type Chart'!$A$5:$A$19,0),MATCH($F14,'Type Chart'!$B$4:$P$4,0))) -> 0.25 | O14: =INDEX('Type Chart'!$B$5:$P$19,MATCH(O$4,'Type Chart'!$A$5:$A$19,0),MATCH($E14,'Type Chart'!$B$4:$P$4,0))*IF($F14="",1,INDEX('Type Chart'!$B$5:$P$19,MATCH(O$4,'Type Chart'!$A$5:$A$19,0),MATCH($F14,'Type Chart'!$B$4:$P$4,0))) -> 1 | ... V14: =INDEX('Type Chart'!$B$5:$P$19,MATCH(V$4,'Type Chart'!$A$5:$A$19,0),MATCH($E14,'Type Chart'!$B$4:$P$4,0))*IF($F14="",1,INDEX('Type Chart'!$B$5:$P$19,MATCH(V$4,'Type Chart'!$A$5:$A$19,0),MATCH($F14,'Type Chart'!$B$4:$P$4,0))) -> 1
