Workbook

Sheet README
A1: POKEMON YELLOW LEGACY — Team Model
A2: Rebuilt from scratch against the Legacy source. Everything in the two earlier workbooks was VANILLA Yellow and does not apply to this game.
A4: SOURCE
A5: Data | B5: github.com/cRz-Shadows/Pokemon_Yellow_Legacy — the hack's own disassembly. Type chart, base stats, learnsets, TM/HM compatibility, move power, TM shop inventories and every boss roster are parsed from it directly.
A6: Version note | B6: Balance shifted between Legacy releases. If your ROM is an old pre-patched build, some numbers here may be off. Check your version against the repo.
A8: WHY THE OLD WORKBOOKS ARE VOID
A9: Type chart | B9: Legacy CHANGED it. Ghost is now SPECIAL and hits Psychic for 2x (the vanilla bug is fixed). Bug is no longer super-effective vs Poison.
A10: Trade evolutions | B10: GONE. Kadabra->Alakazam L42, Haunter->Gengar L42, Graveler->Golem L38, Machoke->Machamp L38. No link cable needed.
A11: TM scarcity | B11: Mostly GONE. The Indigo Plateau lobby sells Blizzard, Thunderbolt, Earthquake, Body Slam, Psychic, Ice Beam, Rock Slide, Fire Blast and more. Scarcity is a MID-GAME constraint only.
A12: Move relearner | B12: Legacy adds one. Missed level-up moves are recoverable.
A13: Stats & moves | B13: Rebalanced. Pikachu +65 BST. Onix hugely buffed. Night Shade is now a real 60 BP Special Ghost attack. Solarbeam is 180 BP. Cut is a 55 BP BUG move.
A14: Boss rosters | B14: Completely different and harder. 8 gyms + Elite Four + Champion = 55 Pokemon, all re-parsed.
A16: METHOD
A17: Damage sim | B17: Gen 1 formula, Legacy's numbers: ((((2*L/5+2) * Power * A/D)/50)+2) * STAB * TypeEffectiveness. Category is set by TYPE (no phys/spec split in Legacy either) -- but note GHOST moved into the Special group.
A18: Level-matched | B18: Your Pokemon fights each trainer at that trainer's ace level. No free wins from overlevelling.
A19: 2HKO bar | B19: 'Covers' a boss = can 2HKO it. 'Fragility' = how many of the 55 bosses can 2HKO YOU back.
A20: Assumptions | B20: DV 8, no stat-XP. Damage roll averaged at 92.5%, multiplied by accuracy. Charge moves x0.55, Hyper Beam x0.62, recoil x0.9. Selfdestruct/Explosion/OHKO moves excluded.
A21: Champion | B21: Blue has 3 Eevee-branch variants. The Vaporeon branch is modelled (Machamp/Pidgeot/Ninetales/Victreebel/Alakazam/Vaporeon). The other two swap a few slots; conclusions do not change.
A22: Not modelled | B22: Status moves, turn order, crits, Hard Mode level caps. Speed enters only via Fragility.
A24: SHEETS
A25: Legacy vs Vanilla | B25: Exactly what the hack changed.
A26: Type Chart | B26: Legacy's own matrix.
A27: Boss Gauntlet | B27: All 55, with every type's multiplier.
A28: Solo Carries | B28: Every Pokemon, its best legal 4 moves, coverage and fragility.
A29: TM Economy | B29: Buyable vs one-off, and WHEN each becomes unlimited. Read before spending a TM.
A30: Learnset Matrix | B30: 151 x 15 -- who can attack with what.
A31: Dual-Type Defense | B31: Recomputed on the NEW chart.
A32: Your Roster | B32: Your 11 Pokemon, scored.
A33: Recommended Team | B33: The answer.

Sheet Legacy vs Vanilla
A1: What Yellow Legacy Actually Changed
A2: Every row verified by diffing the two disassemblies.
A4: Area | B4: Vanilla Yellow | C4: Yellow Legacy | D4: Why it matters
A5: Ghost -> Psychic | B5: 0x (shipped bug) | C5: 2x -- FIXED | D5: Psychic finally has a working counter. Gengar becomes a genuine threat.
A6: Ghost category | B6: Physical (ran off Attack) | C6: SPECIAL | D6: Ghost mons have huge Special and terrible Attack. This alone makes Ghost usable.
A7: Night Shade | B7: Fixed damage = user's level | C7: 60 BP Special Ghost attack | D7: Ghost now has a real attacking move. In vanilla it had none.
A8: Bug -> Poison | B8: 2x | C8: 1x -- removed | D8: Bug loses its hidden edge. Beedrill/Venomoth get worse.
A9: Trade evolutions | B9: Required a link cable | C9: Level-up: Alakazam/Gengar L42, Golem/Machamp L38 | D9: You can get all four solo. No emulator trading needed.
A10: TM shop | B10: Celadon only, junk TMs | C10: Indigo Plateau sells Blizzard, Thunderbolt, Earthquake, Body Slam, Psychic, Ice Beam, Rock Slide, Fire Blast... | D10: TM scarcity basically disappears by endgame. Everyone can run the good moves.
A11: Move relearner | B11: Does not exist | C11: Added | D11: Missed level-up moves are recoverable. Evolution timing is far more forgiving.
A12: Pikachu | B12: 35/55/30/90/50 | C12: 60/55/50/90/70 (+65 BST), gains Thunderpunch L20, Headbutt L24 | D12: Pikachu is genuinely usable now, not a passenger.
A13: Onix | B13: 35/45/160/70/30 | C13: 75/80/160/85/65 | D13: From a joke to a real wall.
A14: Solarbeam | B14: 120 BP | C14: 180 BP | D14: Grass stops being a dead type.
A15: Cut | B15: 50 BP Normal | C15: 55 BP BUG | D15: The HM is no longer a totally dead slot.
... A17: Boss teams | B17: Vanilla rosters | C17: Rebuilt, higher levels, anti-sweep movesets | D17: The old 49-boss gauntlet is meaningless here. 55 bosses now.

Sheet Type Chart
A1: Yellow Legacy Type Chart
A2: Rows = attacker. RED = changed from vanilla Gen 1.
A4: ATK \ DEF | B4: Normal | C4: Fire | D4: Water | E4: Electric | F4: Grass | G4: Ice | H4: Fighting | I4: Poison | J4: Ground | K4: Flying | L4: Psychic | M4: Bug | N4: Rock | O4: Ghost | P4: Dragon
A5: Normal | B5: 1 | C5: 1 | D5: 1 | E5: 1 | F5: 1 | G5: 1 | H5: 1 | I5: 1 | J5: 1 | K5: 1 | L5: 1 | M5: 1 | N5: 0.5 | O5: 0 | P5: 1
A6: Fire | B6: 1 | C6: 0.5 | D6: 0.5 | E6: 1 | F6: 2 | G6: 2 | H6: 1 | I6: 1 | J6: 1 | K6: 1 | L6: 1 | M6: 2 | N6: 0.5 | O6: 1 | P6: 0.5
A7: Water | B7: 1 | C7: 2 | D7: 0.5 | E7: 1 | F7: 0.5 | G7: 1 | H7: 1 | I7: 1 | J7: 2 | K7: 1 | L7: 1 | M7: 1 | N7: 2 | O7: 1 | P7: 0.5
A8: Electric | B8: 1 | C8: 1 | D8: 2 | E8: 0.5 | F8: 0.5 | G8: 1 | H8: 1 | I8: 1 | J8: 0 | K8: 2 | L8: 1 | M8: 1 | N8: 1 | O8: 1 | P8: 0.5
A9: Grass | B9: 1 | C9: 0.5 | D9: 2 | E9: 1 | F9: 0.5 | G9: 1 | H9: 1 | I9: 0.5 | J9: 2 | K9: 0.5 | L9: 1 | M9: 0.5 | N9: 2 | O9: 1 | P9: 0.5
A10: Ice | B10: 1 | C10: 1 | D10: 0.5 | E10: 1 | F10: 2 | G10: 0.5 | H10: 1 | I10: 1 | J10: 2 | K10: 2 | L10: 1 | M10: 1 | N10: 1 | O10: 1 | P10: 2
A11: Fighting | B11: 2 | C11: 1 | D11: 1 | E11: 1 | F11: 1 | G11: 2 | H11: 1 | I11: 0.5 | J11: 1 | K11: 0.5 | L11: 0.5 | M11: 0.5 | N11: 2 | O11: 0 | P11: 1
A12: Poison | B12: 1 | C12: 1 | D12: 1 | E12: 1 | F12: 2 | G12: 1 | H12: 1 | I12: 0.5 | J12: 0.5 | K12: 1 | L12: 1 | M12: 2 | N12: 0.5 | O12: 0.5 | P12: 1
A13: Ground | B13: 1 | C13: 2 | D13: 1 | E13: 2 | F13: 0.5 | G13: 1 | H13: 1 | I13: 2 | J13: 1 | K13: 0 | L13: 1 | M13: 0.5 | N13: 2 | O13: 1 | P13: 1
A14: Flying | B14: 1 | C14: 1 | D14: 1 | E14: 0.5 | F14: 2 | G14: 1 | H14: 2 | I14: 1 | J14: 1 | K14: 1 | L14: 1 | M14: 2 | N14: 0.5 | O14: 1 | P14: 1
A15: Psychic | B15: 1 | C15: 1 | D15: 1 | E15: 1 | F15: 1 | G15: 1 | H15: 2 | I15: 2 | J15: 1 | K15: 1 | L15: 0.5 | M15: 1 | N15: 1 | O15: 1 | P15: 1
A16: Bug | B16: 1 | C16: 0.5 | D16: 1 | E16: 1 | F16: 2 | G16: 1 | H16: 0.5 | I16: 1 | J16: 1 | K16: 0.5 | L16: 2 | M16: 1 | N16: 1 | O16: 0.5 | P16: 1
... A19: Dragon | B19: 1 | C19: 1 | D19: 1 | E19: 1 | F19: 1 | G19: 1 | H19: 1 | I19: 1 | J19: 1 | K19: 1 | L19: 1 | M19: 1 | N19: 1 | O19: 1 | P19: 2
A21: Only two cells differ from vanilla Gen 1: Ghost->Psychic (0x -> 2x) and Bug->Poison (2x -> 1x). Both are marked red.

Sheet Boss Gauntlet
A1: The Legacy Gauntlet — 55 Boss Pokemon
A2: Parsed from Legacy's own trainer party data. Multipliers are live formulas.
A4: Trainer | B4: Stage | C4: Pokemon | D4: Lv | E4: Type 1 | F4: Type 2 | G4: Normal | H4: Fire | I4: Water | J4: Electric | K4: Grass | L4: Ice | M4: Fighting | N4: Poison | O4: Ground | P4: Flying | Q4: Psychic | R4: Bug | S4: Rock | T4: Ghost | U4: Dragon
A5: Brock | B5: Gym 1 | C5: Geodude | D5: 10 | E5: Rock | F5: Ground | G5: =INDEX('Type Chart'!$B$5:$P$19,MATCH(G$4,'Type Chart'!$A$5:$A$19,0),MATCH($E5,'Type Chart'!$B$4:$P$4,0))*IF($F5="",1,INDEX('Type Chart'!$B$5:$P$19,MATCH(G$4,'Type Chart'!$A$5:$A$19,0),MATCH($F5,'Type Chart'!$B$4:$P$4,0))) -> 0.5 | H5: =INDEX('Type Chart'!$B$5:$P$19,MATCH(H$4,'Type Chart'!$A$5:$A$19,0),MATCH($E5,'Type Chart'!$B$4:$P$4,0))*IF($F5="",1,INDEX('Type Chart'!$B$5:$P$19,MATCH(H$4,'Type Chart'!$A$5:$A$19,0),MATCH($F5,'Type Chart'!$B$4:$P$4,0))) -> 0.5 | I5: =INDEX('Type Chart'!$B$5:$P$19,MATCH(I$4,'Type Chart'!$A$5:$A$19,0),MATCH($E5,'Type Chart'!$B$4:$P$4,0))*IF($F5="",1,INDEX('Type Chart'!$B$5:$P$19,MATCH(I$4,'Type Chart'!$A$5:$A$19,0),MATCH($F5,'Type Chart'!$B$4:$P$4,0))) -> 4 | J5: =INDEX('Type Chart'!$B$5:$P$19,MATCH(J$4,'Type Chart'!$A$5:$A$19,0),MATCH($E5,'Type Chart'!$B$4:$P$4,0))*IF($F5="",1,INDEX('Type Chart'!$B$5:$P$19,MATCH(J$4,'Type Chart'!$A$5:$A$19,0),MATCH($F5,'Type Chart'!$B$4:$P$4,0))) -> 0 | K5: =INDEX('Type Chart'!$B$5:$P$19,MATCH(K$4,'Type Chart'!$A$5:$A$19,0),MATCH($E5,'Type Chart'!$B$4:$P$4,0))*IF($F5="",1,INDEX('Type Chart'!$B$5:$P$19,MATCH(K$4,'Type Chart'!$A$5:$A$19,0),MATCH($F5,'Type Chart'!$B$4:$P$4,0))) -> 4 | L5: =INDEX('Type Chart'!$B$5:$P$19,MATCH(L$4,'Type Chart'!$A$5:$A$19,0),MATCH($E5,'Type Chart'!$B$4:$P$4,0))*IF($F5="",1,INDEX('Type Chart'!$B$5:$P$19,MATCH(L$4,'Type Chart'!$A$5:$A$19,0),MATCH($F5,'Type Chart'!$B$4:$P$4,0))) -> 2 | M5: =INDEX('Type Chart'!$B$5:$P$19,MATCH(M$4,'Type Chart'!$A$5:$A$19,0),MATCH($E5,'Type Chart'!$B$4:$P$4,0))*IF($F5="",1,INDEX('Type Chart'!$B$5:$P$19,MATCH(M$4,'Type Chart'!$A$5:$A$19,0),MATCH($F5,'Type Chart'!$B$4:$P$4,0))) -> 2 | N5: =INDEX('Type Chart'!$B$5:$P$19,MATCH(N$4,'Type Chart'!$A$5:$A$19,0),MATCH($E5,'Type Chart'!$B$4:$P$4,0))*IF($F5="",1,INDEX('Type Chart'!$B$5:$P$19,MATCH(N$4,'Type Chart'!$A$5:$A$19,0),MATCH($F5,'Type Chart'!$B$4:$P$4,0))) -> 0.25 | ... U5: =INDEX('Type Chart'!$B$5:$P$19,MATCH(U$4,'Type Chart'!$A$5:$A$19,0),MATCH($E5,'Type Chart'!$B$4:$P$4,0))*IF($F5="",1,INDEX('Type Chart'!$B$5:$P$19,MATCH(U$4,'Type Chart'!$A$5:$A$19,0),MATCH($F5,'Type Chart'!$B$4:$P$4,0))) -> 1
A6: Brock | B6: Gym 1 | C6: Onix | D6: 12 | E6: Rock | F6: Ground | G6: =INDEX('Type Chart'!$B$5:$P$19,MATCH(G$4,'Type Chart'!$A$5:$A$19,0),MATCH($E6,'Type Chart'!$B$4:$P$4,0))*IF($F6="",1,INDEX('Type Chart'!$B$5:$P$19,MATCH(G$4,'Type Chart'!$A$5:$A$19,0),MATCH($F6,'Type Chart'!$B$4:$P$4,0))) -> 0.5 | H6: =INDEX('Type Chart'!$B$5:$P$19,MATCH(H$4,'Type Chart'!$A$5:$A$19,0),MATCH($E6,'Type Chart'!$B$4:$P$4,0))*IF($F6="",1,INDEX('Type Chart'!$B$5:$P$19,MATCH(H$4,'Type Chart'!$A$5:$A$19,0),MATCH($F6,'Type Chart'!$B$4:$P$4,0))) -> 0.5 | I6: =INDEX('Type Chart'!$B$5:$P$19,MATCH(I$4,'Type Chart'!$A$5:$A$19,0),MATCH($E6,'Type Chart'!$B$4:$P$4,0))*IF($F6="",1,INDEX('Type Chart'!$B$5:$P$19,MATCH(I$4,'Type Chart'!$A$5:$A$19,0),MATCH($F6,'Type Chart'!$B$4:$P$4,0))) -> 4 | J6: =INDEX('Type Chart'!$B$5:$P$19,MATCH(J$4,'Type Chart'!$A$5:$A$19,0),MATCH($E6,'Type Chart'!$B$4:$P$4,0))*IF($F6="",1,INDEX('Type Chart'!$B$5:$P$19,MATCH(J$4,'Type Chart'!$A$5:$A$19,0),MATCH($F6,'Type Chart'!$B$4:$P$4,0))) -> 0 | K6: =INDEX('Type Chart'!$B$5:$P$19,MATCH(K$4,'Type Chart'!$A$5:$A$19,0),MATCH($E6,'Type Chart'!$B$4:$P$4,0))*IF($F6="",1,INDEX('Type Chart'!$B$5:$P$19,MATCH(K$4,'Type Chart'!$A$5:$A$19,0),MATCH($F6,'Type Chart'!$B$4:$P$4,0))) -> 4 | L6: =INDEX('Type Chart'!$B$5:$P$19,MATCH(L$4,'Type Chart'!$A$5:$A$19,0),MATCH($E6,'Type Chart'!$B$4:$P$4,0))*IF($F6="",1,INDEX('Type Chart'!$B$5:$P$19,MATCH(L$4,'Type Chart'!$A$5:$A$19,0),MATCH($F6,'Type Chart'!$B$4:$P$4,0))) -> 2 | M6: =INDEX('Type Chart'!$B$5:$P$19,MATCH(M$4,'Type Chart'!$A$5:$A$19,0),MATCH($E6,'Type Chart'!$B$4:$P$4,0))*IF($F6="",1,INDEX('Type Chart'!$B$5:$P$19,MATCH(M$4,'Type Chart'!$A$5:$A$19,0),MATCH($F6,'Type Chart'!$B$4:$P$4,0))) -> 2 | N6: =INDEX('Type Chart'!$B$5:$P$19,MATCH(N$4,'Type Chart'!$A$5:$A$19,0),MATCH($E6,'Type Chart'!$B$4:$P$4,0))*IF($F6="",1,INDEX('Type Chart'!$B$5:$P$19,MATCH(N$4,'Type Chart'!$A$5:$A$19,0),MATCH($F6,'Type Chart'!$B$4:$P$4,0))) -> 0.25 | ... U6: =INDEX('Type Chart'!$B$5:$P$19,MATCH(U$4,'Type Chart'!$A$5:$A$19,0),MATCH($E6,'Type Chart'!$B$4:$P$4,0))*IF($F6="",1,INDEX('Type Chart'!$B$5:$P$19,MATCH(U$4,'Type Chart'!$A$5:$A$19,0),MATCH($F6,'Type Chart'!$B$4:$P$4,0))) -> 1
A7: Misty | B7: Gym 2 | C7: Psyduck | D7: 19 | E7: Water | G7: =INDEX('Type Chart'!$B$5:$P$19,MATCH(G$4,'Type Chart'!$A$5:$A$19,0),MATCH($E7,'Type Chart'!$B$4:$P$4,0))*IF($F7="",1,INDEX('Type Chart'!$B$5:$P$19,MATCH(G$4,'Type Chart'!$A$5:$A$19,0),MATCH($F7,'Type Chart'!$B$4:$P$4,0))) -> 1 | H7: =INDEX('Type Chart'!$B$5:$P$19,MATCH(H$4,'Type Chart'!$A$5:$A$19,0),MATCH($E7,'Type Chart'!$B$4:$P$4,0))*IF($F7="",1,INDEX('Type Chart'!$B$5:$P$19,MATCH(H$4,'Type Chart'!$A$5:$A$19,0),MATCH($F7,'Type Chart'!$B$4:$P$4,0))) -> 0.5 | I7: =INDEX('Type Chart'!$B$5:$P$19,MATCH(I$4,'Type Chart'!$A$5:$A$19,0),MATCH($E7,'Type Chart'!$B$4:$P$4,0))*IF($F7="",1,INDEX('Type Chart'!$B$5:$P$19,MATCH(I$4,'Type Chart'!$A$5:$A$19,0),MATCH($F7,'Type Chart'!$B$4:$P$4,0))) -> 0.5 | J7: =INDEX('Type Chart'!$B$5:$P$19,MATCH(J$4,'Type Chart'!$A$5:$A$19,0),MATCH($E7,'Type Chart'!$B$4:$P$4,0))*IF($F7="",1,INDEX('Type Chart'!$B$5:$P$19,MATCH(J$4,'Type Chart'!$A$5:$A$19,0),MATCH($F7,'Type Chart'!$B$4:$P$4,0))) -> 2 | K7: =INDEX('Type Chart'!$B$5:$P$19,MATCH(K$4,'Type Chart'!$A$5:$A$19,0),MATCH($E7,'Type Chart'!$B$4:$P$4,0))*IF($F7="",1,INDEX('Type Chart'!$B$5:$P$19,MATCH(K$4,'Type Chart'!$A$5:$A$19,0),MATCH($F7,'Type Chart'!$B$4:$P$4,0))) -> 2 | L7: =INDEX('Type Chart'!$B$5:$P$19,MATCH(L$4,'Type Chart'!$A$5:$A$19,0),MATCH($E7,'Type Chart'!$B$4:$P$4,0))*IF($F7="",1,INDEX('Type Chart'!$B$5:$P$19,MATCH(L$4,'Type Chart'!$A$5:$A$19,0),MATCH($F7,'Type Chart'!$B$4:$P$4,0))) -> 0.5 | M7: =INDEX('Type Chart'!$B$5:$P$19,MATCH(M$4,'Type Chart'!$A$5:$A$19,0),MATCH($E7,'Type Chart'!$B$4:$P$4,0))*IF($F7="",1,INDEX('Type Chart'!$B$5:$P$19,MATCH(M$4,'Type Chart'!$A$5:$A$19,0),MATCH($F7,'Type Chart'!$B$4:$P$4,0))) -> 1 | N7: =INDEX('Type Chart'!$B$5:$P$19,MATCH(N$4,'Type Chart'!$A$5:$A$19,0),MATCH($E7,'Type Chart'!$B$4:$P$4,0))*IF($F7="",1,INDEX('Type Chart'!$B$5:$P$19,MATCH(N$4,'Type Chart'!$A$5:$A$19,0),MATCH($F7,'Type Chart'!$B$4:$P$4,0))) -> 1 | ... U7: =INDEX('Type Chart'!$B$5:$P$19,MATCH(U$4,'Type Chart'!$A$5:$A$19,0),MATCH($E7,'Type Chart'!$B$4:$P$4,0))*IF($F7="",1,INDEX('Type Chart'!$B$5:$P$19,MATCH(U$4,'Type Chart'!$A$5:$A$19,0),MATCH($F7,'Type Chart'!$B$4:$P$4,0))) -> 1
A8: Misty | B8: Gym 2 | C8: Goldeen | D8: 18 | E8: Water | G8: =INDEX('Type Chart'!$B$5:$P$19,MATCH(G$4,'Type Chart'!$A$5:$A$19,0),MATCH($E8,'Type Chart'!$B$4:$P$4,0))*IF($F8="",1,INDEX('Type Chart'!$B$5:$P$19,MATCH(G$4,'Type Chart'!$A$5:$A$19,0),MATCH($F8,'Type Chart'!$B$4:$P$4,0))) -> 1 | H8: =INDEX('Type Chart'!$B$5:$P$19,MATCH(H$4,'Type Chart'!$A$5:$A$19,0),MATCH($E8,'Type Chart'!$B$4:$P$4,0))*IF($F8="",1,INDEX('Type Chart'!$B$5:$P$19,MATCH(H$4,'Type Chart'!$A$5:$A$19,0),MATCH($F8,'Type Chart'!$B$4:$P$4,0))) -> 0.5 | I8: =INDEX('Type Chart'!$B$5:$P$19,MATCH(I$4,'Type Chart'!$A$5:$A$19,0),MATCH($E8,'Type Chart'!$B$4:$P$4,0))*IF($F8="",1,INDEX('Type Chart'!$B$5:$P$19,MATCH(I$4,'Type Chart'!$A$5:$A$19,0),MATCH($F8,'Type Chart'!$B$4:$P$4,0))) -> 0.5 | J8: =INDEX('Type Chart'!$B$5:$P$19,MATCH(J$4,'Type Chart'!$A$5:$A$19,0),MATCH($E8,'Type Chart'!$B$4:$P$4,0))*IF($F8="",1,INDEX('Type Chart'!$B$5:$P$19,MATCH(J$4,'Type Chart'!$A$5:$A$19,0),MATCH($F8,'Type Chart'!$B$4:$P$4,0))) -> 2 | K8: =INDEX('Type Chart'!$B$5:$P$19,MATCH(K$4,'Type Chart'!$A$5:$A$19,0),MATCH($E8,'Type Chart'!$B$4:$P$4,0))*IF($F8="",1,INDEX('Type Chart'!$B$5:$P$19,MATCH(K$4,'Type Chart'!$A$5:$A$19,0),MATCH($F8,'Type Chart'!$B$4:$P$4,0))) -> 2 | L8: =INDEX('Type Chart'!$B$5:$P$19,MATCH(L$4,'Type Chart'!$A$5:$A$19,0),MATCH($E8,'Type Chart'!$B$4:$P$4,0))*IF($F8="",1,INDEX('Type Chart'!$B$5:$P$19,MATCH(L$4,'Type Chart'!$A$5:$A$19,0),MATCH($F8,'Type Chart'!$B$4:$P$4,0))) -> 0.5 | M8: =INDEX('Type Chart'!$B$5:$P$19,MATCH(M$4,'Type Chart'!$A$5:$A$19,0),MATCH($E8,'Type Chart'!$B$4:$P$4,0))*IF($F8="",1,INDEX('Type Chart'!$B$5:$P$19,MATCH(M$4,'Type Chart'!$A$5:$A$19,0),MATCH($F8,'Type Chart'!$B$4:$P$4,0))) -> 1 | N8: =INDEX('Type Chart'!$B$5:$P$19,MATCH(N$4,'Type Chart'!$A$5:$A$19,0),MATCH($E8,'Type Chart'!$B$4:$P$4,0))*IF($F8="",1,INDEX('Type Chart'!$B$5:$P$19,MATCH(N$4,'Type Chart'!$A$5:$A$19,0),MATCH($F8,'Type Chart'!$B$4:$P$4,0))) -> 1 | ... U8: =INDEX('Type Chart'!$B$5:$P$19,MATCH(U$4,'Type Chart'!$A$5:$A$19,0),MATCH($E8,'Type Chart'!$B$4:$P$4,0))*IF($F8="",1,INDEX('Type Chart'!$B$5:$P$19,MATCH(U$4,'Type Chart'!$A$5:$A$19,0),MATCH($F8,'Type Chart'!$B$4:$P$4,0))) -> 1
A9: Misty | B9: Gym 2 | C9: Starmie | D9: 21 | E9: Water | F9: Psychic | G9: =INDEX('Type Chart'!$B$5:$P$19,MATCH(G$4,'Type Chart'!$A$5:$A$19,0),MATCH($E9,'Type Chart'!$B$4:$P$4,0))*IF($F9="",1,INDEX('Type Chart'!$B$5:$P$19,MATCH(G$4,'Type Chart'!$A$5:$A$19,0),MATCH($F9,'Type Chart'!$B$4:$P$4,0))) -> 1 | H9: =INDEX('Type Chart'!$B$5:$P$19,MATCH(H$4,'Type Chart'!$A$5:$A$19,0),MATCH($E9,'Type Chart'!$B$4:$P$4,0))*IF($F9="",1,INDEX('Type Chart'!$B$5:$P$19,MATCH(H$4,'Type Chart'!$A$5:$A$19,0),MATCH($F9,'Type Chart'!$B$4:$P$4,0))) -> 0.5 | I9: =INDEX('Type Chart'!$B$5:$P$19,MATCH(I$4,'Type Chart'!$A$5:$A$19,0),MATCH($E9,'Type Chart'!$B$4:$P$4,0))*IF($F9="",1,INDEX('Type Chart'!$B$5:$P$19,MATCH(I$4,'Type Chart'!$A$5:$A$19,0),MATCH($F9,'Type Chart'!$B$4:$P$4,0))) -> 0.5 | J9: =INDEX('Type Chart'!$B$5:$P$19,MATCH(J$4,'Type Chart'!$A$5:$A$19,0),MATCH($E9,'Type Chart'!$B$4:$P$4,0))*IF($F9="",1,INDEX('Type Chart'!$B$5:$P$19,MATCH(J$4,'Type Chart'!$A$5:$A$19,0),MATCH($F9,'Type Chart'!$B$4:$P$4,0))) -> 2 | K9: =INDEX('Type Chart'!$B$5:$P$19,MATCH(K$4,'Type Chart'!$A$5:$A$19,0),MATCH($E9,'Type Chart'!$B$4:$P$4,0))*IF($F9="",1,INDEX('Type Chart'!$B$5:$P$19,MATCH(K$4,'Type Chart'!$A$5:$A$19,0),MATCH($F9,'Type Chart'!$B$4:$P$4,0))) -> 2 | L9: =INDEX('Type Chart'!$B$5:$P$19,MATCH(L$4,'Type Chart'!$A$5:$A$19,0),MATCH($E9,'Type Chart'!$B$4:$P$4,0))*IF($F9="",1,INDEX('Type Chart'!$B$5:$P$19,MATCH(L$4,'Type Chart'!$A$5:$A$19,0),MATCH($F9,'Type Chart'!$B$4:$P$4,0))) -> 0.5 | M9: =INDEX('Type Chart'!$B$5:$P$19,MATCH(M$4,'Type Chart'!$A$5:$A$19,0),MATCH($E9,'Type Chart'!$B$4:$P$4,0))*IF($F9="",1,INDEX('Type Chart'!$B$5:$P$19,MATCH(M$4,'Type Chart'!$A$5:$A$19,0),MATCH($F9,'Type Chart'!$B$4:$P$4,0))) -> 0.5 | N9: =INDEX('Type Chart'!$B$5:$P$19,MATCH(N$4,'Type Chart'!$A$5:$A$19,0),MATCH($E9,'Type Chart'!$B$4:$P$4,0))*IF($F9="",1,INDEX('Type Chart'!$B$5:$P$19,MATCH(N$4,'Type Chart'!$A$5:$A$19,0),MATCH($F9,'Type Chart'!$B$4:$P$4,0))) -> 1 | ... U9: =INDEX('Type Chart'!$B$5:$P$19,MATCH(U$4,'Type Chart'!$A$5:$A$19,0),MATCH($E9,'Type Chart'!$B$4:$P$4,0))*IF($F9="",1,INDEX('Type Chart'!$B$5:$P$19,MATCH(U$4,'Type Chart'!$A$5:$A$19,0),MATCH($F9,'Type Chart'!$B$4:$P$4,0))) -> 1
A10: Lt. Surge | B10: Gym 3 | C10: Raichu | D10: 29 | E10: Electric | G10: =INDEX('Type Chart'!$B$5:$P$19,MATCH(G$4,'Type Chart'!$A$5:$A$19,0),MATCH($E10,'Type Chart'!$B$4:$P$4,0))*IF($F10="",1,INDEX('Type Chart'!$B$5:$P$19,MATCH(G$4,'Type Chart'!$A$5:$A$19,0),MATCH($F10,'Type Chart'!$B$4:$P$4,0))) -> 1 | H10: =INDEX('Type Chart'!$B$5:$P$19,MATCH(H$4,'Type Chart'!$A$5:$A$19,0),MATCH($E10,'Type Chart'!$B$4:$P$4,0))*IF($F10="",1,INDEX('Type Chart'!$B$5:$P$19,MATCH(H$4,'Type Chart'!$A$5:$A$19,0),MATCH($F10,'Type Chart'!$B$4:$P$4,0))) -> 1 | I10: =INDEX('Type Chart'!$B$5:$P$19,MATCH(I$4,'Type Chart'!$A$5:$A$19,0),MATCH($E10,'Type Chart'!$B$4:$P$4,0))*IF($F10="",1,INDEX('Type Chart'!$B$5:$P$19,MATCH(I$4,'Type Chart'!$A$5:$A$19,0),MATCH($F10,'Type Chart'!$B$4:$P$4,0))) -> 1 | J10: =INDEX('Type Chart'!$B$5:$P$19,MATCH(J$4,'Type Chart'!$A$5:$A$19,0),MATCH($E10,'Type Chart'!$B$4:$P$4,0))*IF($F10="",1,INDEX('Type Chart'!$B$5:$P$19,MATCH(J$4,'Type Chart'!$A$5:$A$19,0),MATCH($F10,'Type Chart'!$B$4:$P$4,0))) -> 0.5 | K10: =INDEX('Type Chart'!$B$5:$P$19,MATCH(K$4,'Type Chart'!$A$5:$A$19,0),MATCH($E10,'Type Chart'!$B$4:$P$4,0))*IF($F10="",1,INDEX('Type Chart'!$B$5:$P$19,MATCH(K$4,'Type Chart'!$A$5:$A$19,0),MATCH($F10,'Type Chart'!$B$4:$P$4,0))) -> 1 | L10: =INDEX('Type Chart'!$B$5:$P$19,MATCH(L$4,'Type Chart'!$A$5:$A$19,0),MATCH($E10,'Type Chart'!$B$4:$P$4,0))*IF($F10="",1,INDEX('Type Chart'!$B$5:$P$19,MATCH(L$4,'Type Chart'!$A$5:$A$19,0),MATCH($F10,'Type Chart'!$B$4:$P$4,0))) -> 1 | M10: =INDEX('Type Chart'!$B$5:$P$19,MATCH(M$4,'Type Chart'!$A$5:$A$19,0),MATCH($E10,'Type Chart'!$B$4:$P$4,0))*IF($F10="",1,INDEX('Type Chart'!$B$5:$P$19,MATCH(M$4,'Type Chart'!$A$5:$A$19,0),MATCH($F10,'Type Chart'!$B$4:$P$4,0))) -> 1 | N10: =INDEX('Type Chart'!$B$5:$P$19,MATCH(N$4,'Type Chart'!$A$5:$A$19,0),MATCH($E10,'Type Chart'!$B$4:$P$4,0))*IF($F10="",1,INDEX('Type Chart'!$B$5:$P$19,MATCH(N$4,'Type Chart'!$A$5:$A$19,0),MATCH($F10,'Type Chart'!$B$4:$P$4,0))) -> 1 | ... U10: =INDEX('Type Chart'!$B$5:$P$19,MATCH(U$4,'Type Chart'!$A$5:$A$19,0),MATCH($E10,'Type Chart'!$B$4:$P$4,0))*IF($F10="",1,INDEX('Type Chart'!$B$5:$P$19,MATCH(U$4,'Type Chart'!$A$5:$A$19,0),MATCH($F10,'Type Chart'!$B$4:$P$4,0))) -> 1
A11: Erika | B11: Gym 4 | C11: Tangela | D11: 33 | E11: Grass | G11: =INDEX('Type Chart'!$B$5:$P$19,MATCH(G$4,'Type Chart'!$A$5:$A$19,0),MATCH($E11,'Type Chart'!$B$4:$P$4,0))*IF($F11="",1,INDEX('Type Chart'!$B$5:$P$19,MATCH(G$4,'Type Chart'!$A$5:$A$19,0),MATCH($F11,'Type Chart'!$B$4:$P$4,0))) -> 1 | H11: =INDEX('Type Chart'!$B$5:$P$19,MATCH(H$4,'Type Chart'!$A$5:$A$19,0),MATCH($E11,'Type Chart'!$B$4:$P$4,0))*IF($F11="",1,INDEX('Type Chart'!$B$5:$P$19,MATCH(H$4,'Type Chart'!$A$5:$A$19,0),MATCH($F11,'Type Chart'!$B$4:$P$4,0))) -> 2 | I11: =INDEX('Type Chart'!$B$5:$P$19,MATCH(I$4,'Type Chart'!$A$5:$A$19,0),MATCH($E11,'Type Chart'!$B$4:$P$4,0))*IF($F11="",1,INDEX('Type Chart'!$B$5:$P$19,MATCH(I$4,'Type Chart'!$A$5:$A$19,0),MATCH($F11,'Type Chart'!$B$4:$P$4,0))) -> 0.5 | J11: =INDEX('Type Chart'!$B$5:$P$19,MATCH(J$4,'Type Chart'!$A$5:$A$19,0),MATCH($E11,'Type Chart'!$B$4:$P$4,0))*IF($F11="",1,INDEX('Type Chart'!$B$5:$P$19,MATCH(J$4,'Type Chart'!$A$5:$A$19,0),MATCH($F11,'Type Chart'!$B$4:$P$4,0))) -> 0.5 | K11: =INDEX('Type Chart'!$B$5:$P$19,MATCH(K$4,'Type Chart'!$A$5:$A$19,0),MATCH($E11,'Type Chart'!$B$4:$P$4,0))*IF($F11="",1,INDEX('Type Chart'!$B$5:$P$19,MATCH(K$4,'Type Chart'!$A$5:$A$19,0),MATCH($F11,'Type Chart'!$B$4:$P$4,0))) -> 0.5 | L11: =INDEX('Type Chart'!$B$5:$P$19,MATCH(L$4,'Type Chart'!$A$5:$A$19,0),MATCH($E11,'Type Chart'!$B$4:$P$4,0))*IF($F11="",1,INDEX('Type Chart'!$B$5:$P$19,MATCH(L$4,'Type Chart'!$A$5:$A$19,0),MATCH($F11,'Type Chart'!$B$4:$P$4,0))) -> 2 | M11: =INDEX('Type Chart'!$B$5:$P$19,MATCH(M$4,'Type Chart'!$A$5:$A$19,0),MATCH($E11,'Type Chart'!$B$4:$P$4,0))*IF($F11="",1,INDEX('Type Chart'!$B$5:$P$19,MATCH(M$4,'Type Chart'!$A$5:$A$19,0),MATCH($F11,'Type Chart'!$B$4:$P$4,0))) -> 1 | N11: =INDEX('Type Chart'!$B$5:$P$19,MATCH(N$4,'Type Chart'!$A$5:$A$19,0),MATCH($E11,'Type Chart'!$B$4:$P$4,0))*IF($F11="",1,INDEX('Type Chart'!$B$5:$P$19,MATCH(N$4,'Type Chart'!$A$5:$A$19,0),MATCH($F11,'Type Chart'!$B$4:$P$4,0))) -> 2 | ... U11: =INDEX('Type Chart'!$B$5:$P$19,MATCH(U$4,'Type Chart'!$A$5:$A$19,0),MATCH($E11,'Type Chart'!$B$4:$P$4,0))*IF($F11="",1,INDEX('Type Chart'!$B$5:$P$19,MATCH(U$4,'Type Chart'!$A$5:$A$19,0),MATCH($F11,'Type Chart'!$B$4:$P$4,0))) -> 1
A12: Erika | B12: Gym 4 | C12: Victreebel | D12: 34 | E12: Grass | F12: Poison | G12: =INDEX('Type Chart'!$B$5:$P$19,MATCH(G$4,'Type Chart'!$A$5:$A$19,0),MATCH($E12,'Type Chart'!$B$4:$P$4,0))*IF($F12="",1,INDEX('Type Chart'!$B$5:$P$19,MATCH(G$4,'Type Chart'!$A$5:$A$19,0),MATCH($F12,'Type Chart'!$B$4:$P$4,0))) -> 1 | H12: =INDEX('Type Chart'!$B$5:$P$19,MATCH(H$4,'Type Chart'!$A$5:$A$19,0),MATCH($E12,'Type Chart'!$B$4:$P$4,0))*IF($F12="",1,INDEX('Type Chart'!$B$5:$P$19,MATCH(H$4,'Type Chart'!$A$5:$A$19,0),MATCH($F12,'Type Chart'!$B$4:$P$4,0))) -> 2 | I12: =INDEX('Type Chart'!$B$5:$P$19,MATCH(I$4,'Type Chart'!$A$5:$A$19,0),MATCH($E12,'Type Chart'!$B$4:$P$4,0))*IF($F12="",1,INDEX('Type Chart'!$B$5:$P$19,MATCH(I$4,'Type Chart'!$A$5:$A$19,0),MATCH($F12,'Type Chart'!$B$4:$P$4,0))) -> 0.5 | J12: =INDEX('Type Chart'!$B$5:$P$19,MATCH(J$4,'Type Chart'!$A$5:$A$19,0),MATCH($E12,'Type Chart'!$B$4:$P$4,0))*IF($F12="",1,INDEX('Type Chart'!$B$5:$P$19,MATCH(J$4,'Type Chart'!$A$5:$A$19,0),MATCH($F12,'Type Chart'!$B$4:$P$4,0))) -> 0.5 | K12: =INDEX('Type Chart'!$B$5:$P$19,MATCH(K$4,'Type Chart'!$A$5:$A$19,0),MATCH($E12,'Type Chart'!$B$4:$P$4,0))*IF($F12="",1,INDEX('Type Chart'!$B$5:$P$19,MATCH(K$4,'Type Chart'!$A$5:$A$19,0),MATCH($F12,'Type Chart'!$B$4:$P$4,0))) -> 0.25 | L12: =INDEX('Type Chart'!$B$5:$P$19,MATCH(L$4,'Type Chart'!$A$5:$A$19,0),MATCH($E12,'Type Chart'!$B$4:$P$4,0))*IF($F12="",1,INDEX('Type Chart'!$B$5:$P$19,MATCH(L$4,'Type Chart'!$A$5:$A$19,0),MATCH($F12,'Type Chart'!$B$4:$P$4,0))) -> 2 | M12: =INDEX('Type Chart'!$B$5:$P$19,MATCH(M$4,'Type Chart'!$A$5:$A$19,0),MATCH($E12,'Type Chart'!$B$4:$P$4,0))*IF($F12="",1,INDEX('Type Chart'!$B$5:$P$19,MATCH(M$4,'Type Chart'!$A$5:$A$19,0),MATCH($F12,'Type Chart'!$B$4:$P$4,0))) -> 0.5 | N12: =INDEX('Type Chart'!$B$5:$P$19,MATCH(N$4,'Type Chart'!$A$5:$A$19,0),MATCH($E12,'Type Chart'!$B$4:$P$4,0))*IF($F12="",1,INDEX('Type Chart'!$B$5:$P$19,MATCH(N$4,'Type Chart'!$A$5:$A$19,0),MATCH($F12,'Type Chart'!$B$4:$P$4,0))) -> 1 | ... U12: =INDEX('Type Chart'!$B$5:$P$19,MATCH(U$4,'Type Chart'!$A$5:$A$19,0),MATCH($E12,'Type Chart'!$B$4:$P$4,0))*IF($F12="",1,INDEX('Type Chart'!$B$5:$P$19,MATCH(U$4,'Type Chart'!$A$5:$A$19,0),MATCH($F12,'Type Chart'!$B$4:$P$4,0))) -> 1
A13: Erika | B13: Gym 4 | C13: Ivysaur | D13: 31 | E13: Grass | F13: Poison | G13: =INDEX('Type Chart'!$B$5:$P$19,MATCH(G$4,'Type Chart'!$A$5:$A$19,0),MATCH($E13,'Type Chart'!$B$4:$P$4,0))*IF($F13="",1,INDEX('Type Chart'!$B$5:$P$19,MATCH(G$4,'Type Chart'!$A$5:$A$19,0),MATCH($F13,'Type Chart'!$B$4:$P$4,0))) -> 1 | H13: =INDEX('Type Chart'!$B$5:$P$19,MATCH(H$4,'Type Chart'!$A$5:$A$19,0),MATCH($E13,'Type Chart'!$B$4:$P$4,0))*IF($F13="",1,INDEX('Type Chart'!$B$5:$P$19,MATCH(H$4,'Type Chart'!$A$5:$A$19,0),MATCH($F13,'Type Chart'!$B$4:$P$4,0))) -> 2 | I13: =INDEX('Type Chart'!$B$5:$P$19,MATCH(I$4,'Type Chart'!$A$5:$A$19,0),MATCH($E13,'Type Chart'!$B$4:$P$4,0))*IF($F13="",1,INDEX('Type Chart'!$B$5:$P$19,MATCH(I$4,'Type Chart'!$A$5:$A$19,0),MATCH($F13,'Type Chart'!$B$4:$P$4,0))) -> 0.5 | J13: =INDEX('Type Chart'!$B$5:$P$19,MATCH(J$4,'Type Chart'!$A$5:$A$19,0),MATCH($E13,'Type Chart'!$B$4:$P$4,0))*IF($F13="",1,INDEX('Type Chart'!$B$5:$P$19,MATCH(J$4,'Type Chart'!$A$5:$A$19,0),MATCH($F13,'Type Chart'!$B$4:$P$4,0))) -> 0.5 | K13: =INDEX('Type Chart'!$B$5:$P$19,MATCH(K$4,'Type Chart'!$A$5:$A$19,0),MATCH($E13,'Type Chart'!$B$4:$P$4,0))*IF($F13="",1,INDEX('Type Chart'!$B$5:$P$19,MATCH(K$4,'Type Chart'!$A$5:$A$19,0),MATCH($F13,'Type Chart'!$B$4:$P$4,0))) -> 0.25 | L13: =INDEX('Type Chart'!$B$5:$P$19,MATCH(L$4,'Type Chart'!$A$5:$A$19,0),MATCH($E13,'Type Chart'!$B$4:$P$4,0))*IF($F13="",1,INDEX('Type Chart'!$B$5:$P$19,MATCH(L$4,'Type Chart'!$A$5:$A$19,0),MATCH($F13,'Type Chart'!$B$4:$P$4,0))) -> 2 | M13: =INDEX('Type Chart'!$B$5:$P$19,MATCH(M$4,'Type Chart'!$A$5:$A$19,0),MATCH($E13,'Type Chart'!$B$4:$P$4,0))*IF($F13="",1,INDEX('Type Chart'!$B$5:$P$19,MATCH(M$4,'Type Chart'!$A$5:$A$19,0),MATCH($F13,'Type Chart'!$B$4:$P$4,0))) -> 0.5 | N13: =INDEX('Type Chart'!$B$5:$P$19,MATCH(N$4,'Type Chart'!$A$5:$A$19,0),MATCH($E13,'Type Chart'!$B$4:$P$4,0))*IF($F13="",1,INDEX('Type Chart'!$B$5:$P$19,MATCH(N$4,'Type Chart'!$A$5:$A$19,0),MATCH($F13,'Type Chart'!$B$4:$P$4,0))) -> 1 | ... U13: =INDEX('Type Chart'!$B$5:$P$19,MATCH(U$4,'Type Chart'!$A$5:$A$19,0),MATCH($E13,'Type Chart'!$B$4:$P$4,0))*IF($F13="",1,INDEX('Type Chart'!$B$5:$P$19,MATCH(U$4,'Type Chart'!$A$5:$A$19,0),MATCH($F13,'Type Chart'!$B$4:$P$4,0))) -> 1
A14: Erika | B14: Gym 4 | C14: Vileplume | D14: 35 | E14: Grass | F14: Poison | G14: =INDEX('Type Chart'!$B$5:$P$19,MATCH(G$4,'Type Chart'!$A$5:$A$19,0),MATCH($E14,'Type Chart'!$B$4:$P$4,0))*IF($F14="",1,INDEX('Type Chart'!$B$5:$P$19,MATCH(G$4,'Type Chart'!$A$5:$A$19,0),MATCH($F14,'Type Chart'!$B$4:$P$4,0))) -> 1 | H14: =INDEX('Type Chart'!$B$5:$P$19,MATCH(H$4,'Type Chart'!$A$5:$A$19,0),MATCH($E14,'Type Chart'!$B$4:$P$4,0))*IF($F14="",1,INDEX('Type Chart'!$B$5:$P$19,MATCH(H$4,'Type Chart'!$A$5:$A$19,0),MATCH($F14,'Type Chart'!$B$4:$P$4,0))) -> 2 | I14: =INDEX('Type Chart'!$B$5:$P$19,MATCH(I$4,'Type Chart'!$A$5:$A$19,0),MATCH($E14,'Type Chart'!$B$4:$P$4,0))*IF($F14="",1,INDEX('Type Chart'!$B$5:$P$19,MATCH(I$4,'Type Chart'!$A$5:$A$19,0),MATCH($F14,'Type Chart'!$B$4:$P$4,0))) -> 0.5 | J14: =INDEX('Type Chart'!$B$5:$P$19,MATCH(J$4,'Type Chart'!$A$5:$A$19,0),MATCH($E14,'Type Chart'!$B$4:$P$4,0))*IF($F14="",1,INDEX('Type Chart'!$B$5:$P$19,MATCH(J$4,'Type Chart'!$A$5:$A$19,0),MATCH($F14,'Type Chart'!$B$4:$P$4,0))) -> 0.5 | K14: =INDEX('Type Chart'!$B$5:$P$19,MATCH(K$4,'Type Chart'!$A$5:$A$19,0),MATCH($E14,'Type Chart'!$B$4:$P$4,0))*IF($F14="",1,INDEX('Type Chart'!$B$5:$P$19,MATCH(K$4,'Type Chart'!$A$5:$A$19,0),MATCH($F14,'Type Chart'!$B$4:$P$4,0))) -> 0.25 | L14: =INDEX('Type Chart'!$B$5:$P$19,MATCH(L$4,'Type Chart'!$A$5:$A$19,0),MATCH($E14,'Type Chart'!$B$4:$P$4,0))*IF($F14="",1,INDEX('Type Chart'!$B$5:$P$19,MATCH(L$4,'Type Chart'!$A$5:$A$19,0),MATCH($F14,'Type Chart'!$B$4:$P$4,0))) -> 2 | M14: =INDEX('Type Chart'!$B$5:$P$19,MATCH(M$4,'Type Chart'!$A$5:$A$19,0),MATCH($E14,'Type Chart'!$B$4:$P$4,0))*IF($F14="",1,INDEX('Type Chart'!$B$5:$P$19,MATCH(M$4,'Type Chart'!$A$5:$A$19,0),MATCH($F14,'Type Chart'!$B$4:$P$4,0))) -> 0.5 | N14: =INDEX('Type Chart'!$B$5:$P$19,MATCH(N$4,'Type Chart'!$A$5:$A$19,0),MATCH($E14,'Type Chart'!$B$4:$P$4,0))*IF($F14="",1,INDEX('Type Chart'!$B$5:$P$19,MATCH(N$4,'Type Chart'!$A$5:$A$19,0),MATCH($F14,'Type Chart'!$B$4:$P$4,0))) -> 1 | ... U14: =INDEX('Type Chart'!$B$5:$P$19,MATCH(U$4,'Type Chart'!$A$5:$A$19,0),MATCH($E14,'Type Chart'!$B$4:$P$4,0))*IF($F14="",1,INDEX('Type Chart'!$B$5:$P$19,MATCH(U$4,'Type Chart'!$A$5:$A$19,0),MATCH($F14,'Type Chart'!$B$4:$P$4,0))) -> 1
A15: Koga | B15: Gym 5 | C15: Golbat | D15: 42 | E15: Poison | F15: Flying | G15: =INDEX('Type Chart'!$B$5:$P$19,MATCH(G$4,'Type Chart'!$A$5:$A$19,0),MATCH($E15,'Type Chart'!$B$4:$P$4,0))*IF($F15="",1,INDEX('Type Chart'!$B$5:$P$19,MATCH(G$4,'Type Chart'!$A$5:$A$19,0),MATCH($F15,'Type Chart'!$B$4:$P$4,0))) -> 1 | H15: =INDEX('Type Chart'!$B$5:$P$19,MATCH(H$4,'Type Chart'!$A$5:$A$19,0),MATCH($E15,'Type Chart'!$B$4:$P$4,0))*IF($F15="",1,INDEX('Type Chart'!$B$5:$P$19,MATCH(H$4,'Type Chart'!$A$5:$A$19,0),MATCH($F15,'Type Chart'!$B$4:$P$4,0))) -> 1 | I15: =INDEX('Type Chart'!$B$5:$P$19,MATCH(I$4,'Type Chart'!$A$5:$A$19,0),MATCH($E15,'Type Chart'!$B$4:$P$4,0))*IF($F15="",1,INDEX('Type Chart'!$B$5:$P$19,MATCH(I$4,'Type Chart'!$A$5:$A$19,0),MATCH($F15,'Type Chart'!$B$4:$P$4,0))) -> 1 | J15: =INDEX('Type Chart'!$B$5:$P$19,MATCH(J$4,'Type Chart'!$A$5:$A$19,0),MATCH($E15,'Type Chart'!$B$4:$P$4,0))*IF($F15="",1,INDEX('Type Chart'!$B$5:$P$19,MATCH(J$4,'Type Chart'!$A$5:$A$19,0),MATCH($F15,'Type Chart'!$B$4:$P$4,0))) -> 2 | K15: =INDEX('Type Chart'!$B$5:$P$19,MATCH(K$4,'Type Chart'!$A$5:$A$19,0),MATCH($E15,'Type Chart'!$B$4:$P$4,0))*IF($F15="",1,INDEX('Type Chart'!$B$5:$P$19,MATCH(K$4,'Type Chart'!$A$5:$A$19,0),MATCH($F15,'Type Chart'!$B$4:$P$4,0))) -> 0.25 | L15: =INDEX('Type Chart'!$B$5:$P$19,MATCH(L$4,'Type Chart'!$A$5:$A$19,0),MATCH($E15,'Type Chart'!$B$4:$P$4,0))*IF($F15="",1,INDEX('Type Chart'!$B$5:$P$19,MATCH(L$4,'Type Chart'!$A$5:$A$19,0),MATCH($F15,'Type Chart'!$B$4:$P$4,0))) -> 2 | M15: =INDEX('Type Chart'!$B$5:$P$19,MATCH(M$4,'Type Chart'!$A$5:$A$19,0),MATCH($E15,'Type Chart'!$B$4:$P$4,0))*IF($F15="",1,INDEX('Type Chart'!$B$5:$P$19,MATCH(M$4,'Type Chart'!$A$5:$A$19,0),MATCH($F15,'Type Chart'!$B$4:$P$4,0))) -> 0.25 | N15: =INDEX('Type Chart'!$B$5:$P$19,MATCH(N$4,'Type Chart'!$A$5:$A$19,0),MATCH($E15,'Type Chart'!$B$4:$P$4,0))*IF($F15="",1,INDEX('Type Chart'!$B$5:$P$19,MATCH(N$4,'Type Chart'!$A$5:$A$19,0),MATCH($F15,'Type Chart'!$B$4:$P$4,0))) -> 0.5 | ... U15: =INDEX('Type Chart'!$B$5:$P$19,MATCH(U$4,'Type Chart'!$A$5:$A$19,0),MATCH($E15,'Type Chart'!$B$4:$P$4,0))*IF($F15="",1,INDEX('Type Chart'!$B$5:$P$19,MATCH(U$4,'Type Chart'!$A$5:$A$19,0),MATCH($F15,'Type Chart'!$B$4:$P$4,0))) -> 1
A16: Koga | B16: Gym 5 | C16: Muk | D16: 42 | E16: Poison | G16: =INDEX('Type Chart'!$B$5:$P$19,MATCH(G$4,'Type Chart'!$A$5:$A$19,0),MATCH($E16,'Type Chart'!$B$4:$P$4,0))*IF($F16="",1,INDEX('Type Chart'!$B$5:$P$19,MATCH(G$4,'Type Chart'!$A$5:$A$19,0),MATCH($F16,'Type Chart'!$B$4:$P$4,0))) -> 1 | H16: =INDEX('Type Chart'!$B$5:$P$19,MATCH(H$4,'Type Chart'!$A$5:$A$19,0),MATCH($E16,'Type Chart'!$B$4:$P$4,0))*IF($F16="",1,INDEX('Type Chart'!$B$5:$P$19,MATCH(H$4,'Type Chart'!$A$5:$A$19,0),MATCH($F16,'Type Chart'!$B$4:$P$4,0))) -> 1 | I16: =INDEX('Type Chart'!$B$5:$P$19,MATCH(I$4,'Type Chart'!$A$5:$A$19,0),MATCH($E16,'Type Chart'!$B$4:$P$4,0))*IF($F16="",1,INDEX('Type Chart'!$B$5:$P$19,MATCH(I$4,'Type Chart'!$A$5:$A$19,0),MATCH($F16,'Type Chart'!$B$4:$P$4,0))) -> 1 | J16: =INDEX('Type Chart'!$B$5:$P$19,MATCH(J$4,'Type Chart'!$A$5:$A$19,0),MATCH($E16,'Type Chart'!$B$4:$P$4,0))*IF($F16="",1,INDEX('Type Chart'!$B$5:$P$19,MATCH(J$4,'Type Chart'!$A$5:$A$19,0),MATCH($F16,'Type Chart'!$B$4:$P$4,0))) -> 1 | K16: =INDEX('Type Chart'!$B$5:$P$19,MATCH(K$4,'Type Chart'!$A$5:$A$19,0),MATCH($E16,'Type Chart'!$B$4:$P$4,0))*IF($F16="",1,INDEX('Type Chart'!$B$5:$P$19,MATCH(K$4,'Type Chart'!$A$5:$A$19,0),MATCH($F16,'Type Chart'!$B$4:$P$4,0))) -> 0.5 | L16: =INDEX('Type Chart'!$B$5:$P$19,MATCH(L$4,'Type Chart'!$A$5:$A$19,0),MATCH($E16,'Type Chart'!$B$4:$P$4,0))*IF($F16="",1,INDEX('Type Chart'!$B$5:$P$19,MATCH(L$4,'Type Chart'!$A$5:$A$19,0),MATCH($F16,'Type Chart'!$B$4:$P$4,0))) -> 1 | M16: =INDEX('Type Chart'!$B$5:$P$19,MATCH(M$4,'Type Chart'!$A$5:$A$19,0),MATCH($E16,'Type Chart'!$B$4:$P$4,0))*IF($F16="",1,INDEX('Type Chart'!$B$5:$P$19,MATCH(M$4,'Type Chart'!$A$5:$A$19,0),MATCH($F16,'Type Chart'!$B$4:$P$4,0))) -> 0.5 | N16: =INDEX('Type Chart'!$B$5:$P$19,MATCH(N$4,'Type Chart'!$A$5:$A$19,0),MATCH($E16,'Type Chart'!$B$4:$P$4,0))*IF($F16="",1,INDEX('Type Chart'!$B$5:$P$19,MATCH(N$4,'Type Chart'!$A$5:$A$19,0),MATCH($F16,'Type Chart'!$B$4:$P$4,0))) -> 0.5 | ... U16: =INDEX('Type Chart'!$B$5:$P$19,MATCH(U$4,'Type Chart'!$A$5:$A$19,0),MATCH($E16,'Type Chart'!$B$4:$P$4,0))*IF($F16="",1,INDEX('Type Chart'!$B$5:$P$19,MATCH(U$4,'Type Chart'!$A$5:$A$19,0),MATCH($F16,'Type Chart'!$B$4:$P$4,0))) -> 1
A17: Koga | B17: Gym 5 | C17: Tentacruel | D17: 41 | E17: Water | F17: Poison | G17: =INDEX('Type Chart'!$B$5:$P$19,MATCH(G$4,'Type Chart'!$A$5:$A$19,0),MATCH($E17,'Type Chart'!$B$4:$P$4,0))*IF($F17="",1,INDEX('Type Chart'!$B$5:$P$19,MATCH(G$4,'Type Chart'!$A$5:$A$19,0),MATCH($F17,'Type Chart'!$B$4:$P$4,0))) -> 1 | H17: =INDEX('Type Chart'!$B$5:$P$19,MATCH(H$4,'Type Chart'!$A$5:$A$19,0),MATCH($E17,'Type Chart'!$B$4:$P$4,0))*IF($F17="",1,INDEX('Type Chart'!$B$5:$P$19,MATCH(H$4,'Type Chart'!$A$5:$A$19,0),MATCH($F17,'Type Chart'!$B$4:$P$4,0))) -> 0.5 | I17: =INDEX('Type Chart'!$B$5:$P$19,MATCH(I$4,'Type Chart'!$A$5:$A$19,0),MATCH($E17,'Type Chart'!$B$4:$P$4,0))*IF($F17="",1,INDEX('Type Chart'!$B$5:$P$19,MATCH(I$4,'Type Chart'!$A$5:$A$19,0),MATCH($F17,'Type Chart'!$B$4:$P$4,0))) -> 0.5 | J17: =INDEX('Type Chart'!$B$5:$P$19,MATCH(J$4,'Type Chart'!$A$5:$A$19,0),MATCH($E17,'Type Chart'!$B$4:$P$4,0))*IF($F17="",1,INDEX('Type Chart'!$B$5:$P$19,MATCH(J$4,'Type Chart'!$A$5:$A$19,0),MATCH($F17,'Type Chart'!$B$4:$P$4,0))) -> 2 | K17: =INDEX('Type Chart'!$B$5:$P$19,MATCH(K$4,'Type Chart'!$A$5:$A$19,0),MATCH($E17,'Type Chart'!$B$4:$P$4,0))*IF($F17="",1,INDEX('Type Chart'!$B$5:$P$19,MATCH(K$4,'Type Chart'!$A$5:$A$19,0),MATCH($F17,'Type Chart'!$B$4:$P$4,0))) -> 1 | L17: =INDEX('Type Chart'!$B$5:$P$19,MATCH(L$4,'Type Chart'!$A$5:$A$19,0),MATCH($E17,'Type Chart'!$B$4:$P$4,0))*IF($F17="",1,INDEX('Type Chart'!$B$5:$P$19,MATCH(L$4,'Type Chart'!$A$5:$A$19,0),MATCH($F17,'Type Chart'!$B$4:$P$4,0))) -> 0.5 | M17: =INDEX('Type Chart'!$B$5:$P$19,MATCH(M$4,'Type Chart'!$A$5:$A$19,0),MATCH($E17,'Type Chart'!$B$4:$P$4,0))*IF($F17="",1,INDEX('Type Chart'!$B$5:$P$19,MATCH(M$4,'Type Chart'!$A$5:$A$19,0),MATCH($F17,'Type Chart'!$B$4:$P$4,0))) -> 0.5 | N17: =INDEX('Type Chart'!$B$5:$P$19,MATCH(N$4,'Type Chart'!$A$5:$A$19,0),MATCH($E17,'Type Chart'!$B$4:$P$4,0))*IF($F17="",1,INDEX('Type Chart'!$B$5:$P$19,MATCH(N$4,'Type Chart'!$A$5:$A$19,0),MATCH($F17,'Type Chart'!$B$4:$P$4,0))) -> 0.5 | ... U17: =INDEX('Type Chart'!$B$5:$P$19,MATCH(U$4,'Type Chart'!$A$5:$A$19,0),MATCH($E17,'Type Chart'!$B$4:$P$4,0))*IF($F17="",1,INDEX('Type Chart'!$B$5:$P$19,MATCH(U$4,'Type Chart'!$A$5:$A$19,0),MATCH($F17,'Type Chart'!$B$4:$P$4,0))) -> 1
A18: Koga | B18: Gym 5 | C18: Venomoth | D18: 43 | E18: Bug | F18: Poison | G18: =INDEX('Type Chart'!$B$5:$P$19,MATCH(G$4,'Type Chart'!$A$5:$A$19,0),MATCH($E18,'Type Chart'!$B$4:$P$4,0))*IF($F18="",1,INDEX('Type Chart'!$B$5:$P$19,MATCH(G$4,'Type Chart'!$A$5:$A$19,0),MATCH($F18,'Type Chart'!$B$4:$P$4,0))) -> 1 | H18: =INDEX('Type Chart'!$B$5:$P$19,MATCH(H$4,'Type Chart'!$A$5:$A$19,0),MATCH($E18,'Type Chart'!$B$4:$P$4,0))*IF($F18="",1,INDEX('Type Chart'!$B$5:$P$19,MATCH(H$4,'Type Chart'!$A$5:$A$19,0),MATCH($F18,'Type Chart'!$B$4:$P$4,0))) -> 2 | I18: =INDEX('Type Chart'!$B$5:$P$19,MATCH(I$4,'Type Chart'!$A$5:$A$19,0),MATCH($E18,'Type Chart'!$B$4:$P$4,0))*IF($F18="",1,INDEX('Type Chart'!$B$5:$P$19,MATCH(I$4,'Type Chart'!$A$5:$A$19,0),MATCH($F18,'Type Chart'!$B$4:$P$4,0))) -> 1 | J18: =INDEX('Type Chart'!$B$5:$P$19,MATCH(J$4,'Type Chart'!$A$5:$A$19,0),MATCH($E18,'Type Chart'!$B$4:$P$4,0))*IF($F18="",1,INDEX('Type Chart'!$B$5:$P$19,MATCH(J$4,'Type Chart'!$A$5:$A$19,0),MATCH($F18,'Type Chart'!$B$4:$P$4,0))) -> 1 | K18: =INDEX('Type Chart'!$B$5:$P$19,MATCH(K$4,'Type Chart'!$A$5:$A$19,0),MATCH($E18,'Type Chart'!$B$4:$P$4,0))*IF($F18="",1,INDEX('Type Chart'!$B$5:$P$19,MATCH(K$4,'Type Chart'!$A$5:$A$19,0),MATCH($F18,'Type Chart'!$B$4:$P$4,0))) -> 0.25 | L18: =INDEX('Type Chart'!$B$5:$P$19,MATCH(L$4,'Type Chart'!$A$5:$A$19,0),MATCH($E18,'Type Chart'!$B$4:$P$4,0))*IF($F18="",1,INDEX('Type Chart'!$B$5:$P$19,MATCH(L$4,'Type Chart'!$A$5:$A$19,0),MATCH($F18,'Type Chart'!$B$4:$P$4,0))) -> 1 | M18: =INDEX('Type Chart'!$B$5:$P$19,MATCH(M$4,'Type Chart'!$A$5:$A$19,0),MATCH($E18,'Type Chart'!$B$4:$P$4,0))*IF($F18="",1,INDEX('Type Chart'!$B$5:$P$19,MATCH(M$4,'Type Chart'!$A$5:$A$19,0),MATCH($F18,'Type Chart'!$B$4:$P$4,0))) -> 0.25 | N18: =INDEX('Type Chart'!$B$5:$P$19,MATCH(N$4,'Type Chart'!$A$5:$A$19,0),MATCH($E18,'Type Chart'!$B$4:$P$4,0))*IF($F18="",1,INDEX('Type Chart'!$B$5:$P$19,MATCH(N$4,'Type Chart'!$A$5:$A$19,0),MATCH($F18,'Type Chart'!$B$4:$P$4,0))) -> 1 | ... U18: =INDEX('Type Chart'!$B$5:$P$19,MATCH(U$4,'Type Chart'!$A$5:$A$19,0),MATCH($E18,'Type Chart'!$B$4:$P$4,0))*IF($F18="",1,INDEX('Type Chart'!$B$5:$P$19,MATCH(U$4,'Type Chart'!$A$5:$A$19,0),MATCH($F18,'Type Chart'!$B$4:$P$4,0))) -> 1
A19: Sabrina | B19: Gym 6 | C19: Abra | D19: 50 | E19: Psychic | G19: =INDEX('Type Chart'!$B$5:$P$19,MATCH(G$4,'Type Chart'!$A$5:$A$19,0),MATCH($E19,'Type Chart'!$B$4:$P$4,0))*IF($F19="",1,INDEX('Type Chart'!$B$5:$P$19,MATCH(G$4,'Type Chart'!$A$5:$A$19,0),MATCH($F19,'Type Chart'!$B$4:$P$4,0))) -> 1 | H19: =INDEX('Type Chart'!$B$5:$P$19,MATCH(H$4,'Type Chart'!$A$5:$A$19,0),MATCH($E19,'Type Chart'!$B$4:$P$4,0))*IF($F19="",1,INDEX('Type Chart'!$B$5:$P$19,MATCH(H$4,'Type Chart'!$A$5:$A$19,0),MATCH($F19,'Type Chart'!$B$4:$P$4,0))) -> 1 | I19: =INDEX('Type Chart'!$B$5:$P$19,MATCH(I$4,'Type Chart'!$A$5:$A$19,0),MATCH($E19,'Type Chart'!$B$4:$P$4,0))*IF($F19="",1,INDEX('Type Chart'!$B$5:$P$19,MATCH(I$4,'Type Chart'!$A$5:$A$19,0),MATCH($F19,'Type Chart'!$B$4:$P$4,0))) -> 1 | J19: =INDEX('Type Chart'!$B$5:$P$19,MATCH(J$4,'Type Chart'!$A$5:$A$19,0),MATCH($E19,'Type Chart'!$B$4:$P$4,0))*IF($F19="",1,INDEX('Type Chart'!$B$5:$P$19,MATCH(J$4,'Type Chart'!$A$5:$A$19,0),MATCH($F19,'Type Chart'!$B$4:$P$4,0))) -> 1 | K19: =INDEX('Type Chart'!$B$5:$P$19,MATCH(K$4,'Type Chart'!$A$5:$A$19,0),MATCH($E19,'Type Chart'!$B$4:$P$4,0))*IF($F19="",1,INDEX('Type Chart'!$B$5:$P$19,MATCH(K$4,'Type Chart'!$A$5:$A$19,0),MATCH($F19,'Type Chart'!$B$4:$P$4,0))) -> 1 | L19: =INDEX('Type Chart'!$B$5:$P$19,MATCH(L$4,'Type Chart'!$A$5:$A$19,0),MATCH($E19,'Type Chart'!$B$4:$P$4,0))*IF($F19="",1,INDEX('Type Chart'!$B$5:$P$19,MATCH(L$4,'Type Chart'!$A$5:$A$19,0),MATCH($F19,'Type Chart'!$B$4:$P$4,0))) -> 1 | M19: =INDEX('Type Chart'!$B$5:$P$19,MATCH(M$4,'Type Chart'!$A$5:$A$19,0),MATCH($E19,'Type Chart'!$B$4:$P$4,0))*IF($F19="",1,INDEX('Type Chart'!$B$5:$P$19,MATCH(M$4,'Type Chart'!$A$5:$A$19,0),MATCH($F19,'Type Chart'!$B$4:$P$4,0))) -> 0.5 | N19: =INDEX('Type Chart'!$B$5:$P$19,MATCH(N$4,'Type Chart'!$A$5:$A$19,0),MATCH($E19,'Type Chart'!$B$4:$P$4,0))*IF($F19="",1,INDEX('Type Chart'!$B$5:$P$19,MATCH(N$4,'Type Chart'!$A$5:$A$19,0),MATCH($F19,'Type Chart'!$B$4:$P$4,0))) -> 1 | ... U19: =INDEX('Type Chart'!$B$5:$P$19,MATCH(U$4,'Type Chart'!$A$5:$A$19,0),MATCH($E19,'Type Chart'!$B$4:$P$4,0))*IF($F19="",1,INDEX('Type Chart'!$B$5:$P$19,MATCH(U$4,'Type Chart'!$A$5:$A$19,0),MATCH($F19,'Type Chart'!$B$4:$P$4,0))) -> 1
A20: Sabrina | B20: Gym 6 | C20: Hypno | D20: 48 | E20: Psychic | G20: =INDEX('Type Chart'!$B$5:$P$19,MATCH(G$4,'Type Chart'!$A$5:$A$19,0),MATCH($E20,'Type Chart'!$B$4:$P$4,0))*IF($F20="",1,INDEX('Type Chart'!$B$5:$P$19,MATCH(G$4,'Type Chart'!$A$5:$A$19,0),MATCH($F20,'Type Chart'!$B$4:$P$4,0))) -> 1 | H20: =INDEX('Type Chart'!$B$5:$P$19,MATCH(H$4,'Type Chart'!$A$5:$A$19,0),MATCH($E20,'Type Chart'!$B$4:$P$4,0))*IF($F20="",1,INDEX('Type Chart'!$B$5:$P$19,MATCH(H$4,'Type Chart'!$A$5:$A$19,0),MATCH($F20,'Type Chart'!$B$4:$P$4,0))) -> 1 | I20: =INDEX('Type Chart'!$B$5:$P$19,MATCH(I$4,'Type Chart'!$A$5:$A$19,0),MATCH($E20,'Type Chart'!$B$4:$P$4,0))*IF($F20="",1,INDEX('Type Chart'!$B$5:$P$19,MATCH(I$4,'Type Chart'!$A$5:$A$19,0),MATCH($F20,'Type Chart'!$B$4:$P$4,0))) -> 1 | J20: =INDEX('Type Chart'!$B$5:$P$19,MATCH(J$4,'Type Chart'!$A$5:$A$19,0),MATCH($E20,'Type Chart'!$B$4:$P$4,0))*IF($F20="",1,INDEX('Type Chart'!$B$5:$P$19,MATCH(J$4,'Type Chart'!$A$5:$A$19,0),MATCH($F20,'Type Chart'!$B$4:$P$4,0))) -> 1 | K20: =INDEX('Type Chart'!$B$5:$P$19,MATCH(K$4,'Type Chart'!$A$5:$A$19,0),MATCH($E20,'Type Chart'!$B$4:$P$4,0))*IF($F20="",1,INDEX('Type Chart'!$B$5:$P$19,MATCH(K$4,'Type Chart'!$A$5:$A$19,0),MATCH($F20,'Type Chart'!$B$4:$P$4,0))) -> 1 | L20: =INDEX('Type Chart'!$B$5:$P$19,MATCH(L$4,'Type Chart'!$A$5:$A$19,0),MATCH($E20,'Type Chart'!$B$4:$P$4,0))*IF($F20="",1,INDEX('Type Chart'!$B$5:$P$19,MATCH(L$4,'Type Chart'!$A$5:$A$19,0),MATCH($F20,'Type Chart'!$B$4:$P$4,0))) -> 1 | M20: =INDEX('Type Chart'!$B$5:$P$19,MATCH(M$4,'Type Chart'!$A$5:$A$19,0),MATCH($E20,'Type Chart'!$B$4:$P$4,0))*IF($F20="",1,INDEX('Type Chart'!$B$5:$P$19,MATCH(M$4,'Type Chart'!$A$5:$A$19,0),MATCH($F20,'Type Chart'!$B$4:$P$4,0))) -> 0.5 | N20: =INDEX('Type Chart'!$B$5:$P$19,MATCH(N$4,'Type Chart'!$A$5:$A$19,0),MATCH($E20,'Type Chart'!$B$4:$P$4,0))*IF($F20="",1,INDEX('Type Chart'!$B$5:$P$19,MATCH(N$4,'Type Chart'!$A$5:$A$19,0),MATCH($F20,'Type Chart'!$B$4:$P$4,0))) -> 1 | ... U20: =INDEX('Type Chart'!$B$5:$P$19,MATCH(U$4,'Type Chart'!$A$5:$A$19,0),MATCH($E20,'Type Chart'!$B$4:$P$4,0))*IF($F20="",1,INDEX('Type Chart'!$B$5:$P$19,MATCH(U$4,'Type Chart'!$A$5:$A$19,0),MATCH($F20,'Type Chart'!$B$4:$P$4,0))) -> 1
A21: Sabrina | B21: Gym 6 | C21: Mrime | D21: 49 | E21: Psychic | G21: =INDEX('Type Chart'!$B$5:$P$19,MATCH(G$4,'Type Chart'!$A$5:$A$19,0),MATCH($E21,'Type Chart'!$B$4:$P$4,0))*IF($F21="",1,INDEX('Type Chart'!$B$5:$P$19,MATCH(G$4,'Type Chart'!$A$5:$A$19,0),MATCH($F21,'Type Chart'!$B$4:$P$4,0))) -> 1 | H21: =INDEX('Type Chart'!$B$5:$P$19,MATCH(H$4,'Type Chart'!$A$5:$A$19,0),MATCH($E21,'Type Chart'!$B$4:$P$4,0))*IF($F21="",1,INDEX('Type Chart'!$B$5:$P$19,MATCH(H$4,'Type Chart'!$A$5:$A$19,0),MATCH($F21,'Type Chart'!$B$4:$P$4,0))) -> 1 | I21: =INDEX('Type Chart'!$B$5:$P$19,MATCH(I$4,'Type Chart'!$A$5:$A$19,0),MATCH($E21,'Type Chart'!$B$4:$P$4,0))*IF($F21="",1,INDEX('Type Chart'!$B$5:$P$19,MATCH(I$4,'Type Chart'!$A$5:$A$19,0),MATCH($F21,'Type Chart'!$B$4:$P$4,0))) -> 1 | J21: =INDEX('Type Chart'!$B$5:$P$19,MATCH(J$4,'Type Chart'!$A$5:$A$19,0),MATCH($E21,'Type Chart'!$B$4:$P$4,0))*IF($F21="",1,INDEX('Type Chart'!$B$5:$P$19,MATCH(J$4,'Type Chart'!$A$5:$A$19,0),MATCH($F21,'Type Chart'!$B$4:$P$4,0))) -> 1 | K21: =INDEX('Type Chart'!$B$5:$P$19,MATCH(K$4,'Type Chart'!$A$5:$A$19,0),MATCH($E21,'Type Chart'!$B$4:$P$4,0))*IF($F21="",1,INDEX('Type Chart'!$B$5:$P$19,MATCH(K$4,'Type Chart'!$A$5:$A$19,0),MATCH($F21,'Type Chart'!$B$4:$P$4,0))) -> 1 | L21: =INDEX('Type Chart'!$B$5:$P$19,MATCH(L$4,'Type Chart'!$A$5:$A$19,0),MATCH($E21,'Type Chart'!$B$4:$P$4,0))*IF($F21="",1,INDEX('Type Chart'!$B$5:$P$19,MATCH(L$4,'Type Chart'!$A$5:$A$19,0),MATCH($F21,'Type Chart'!$B$4:$P$4,0))) -> 1 | M21: =INDEX('Type Chart'!$B$5:$P$19,MATCH(M$4,'Type Chart'!$A$5:$A$19,0),MATCH($E21,'Type Chart'!$B$4:$P$4,0))*IF($F21="",1,INDEX('Type Chart'!$B$5:$P$19,MATCH(M$4,'Type Chart'!$A$5:$A$19,0),MATCH($F21,'Type Chart'!$B$4:$P$4,0))) -> 0.5 | N21: =INDEX('Type Chart'!$B$5:$P$19,MATCH(N$4,'Type Chart'!$A$5:$A$19,0),MATCH($E21,'Type Chart'!$B$4:$P$4,0))*IF($F21="",1,INDEX('Type Chart'!$B$5:$P$19,MATCH(N$4,'Type Chart'!$A$5:$A$19,0),MATCH($F21,'Type Chart'!$B$4:$P$4,0))) -> 1 | ... U21: =INDEX('Type Chart'!$B$5:$P$19,MATCH(U$4,'Type Chart'!$A$5:$A$19,0),MATCH($E21,'Type Chart'!$B$4:$P$4,0))*IF($F21="",1,INDEX('Type Chart'!$B$5:$P$19,MATCH(U$4,'Type Chart'!$A$5:$A$19,0),MATCH($F21,'Type Chart'!$B$4:$P$4,0))) -> 1
A22: Sabrina | B22: Gym 6 | C22: Kadabra | D22: 50 | E22: Psychic | G22: =INDEX('Type Chart'!$B$5:$P$19,MATCH(G$4,'Type Chart'!$A$5:$A$19,0),MATCH($E22,'Type Chart'!$B$4:$P$4,0))*IF($F22="",1,INDEX('Type Chart'!$B$5:$P$19,MATCH(G$4,'Type Chart'!$A$5:$A$19,0),MATCH($F22,'Type Chart'!$B$4:$P$4,0))) -> 1 | H22: =INDEX('Type Chart'!$B$5:$P$19,MATCH(H$4,'Type Chart'!$A$5:$A$19,0),MATCH($E22,'Type Chart'!$B$4:$P$4,0))*IF($F22="",1,INDEX('Type Chart'!$B$5:$P$19,MATCH(H$4,'Type Chart'!$A$5:$A$19,0),MATCH($F22,'Type Chart'!$B$4:$P$4,0))) -> 1 | I22: =INDEX('Type Chart'!$B$5:$P$19,MATCH(I$4,'Type Chart'!$A$5:$A$19,0),MATCH($E22,'Type Chart'!$B$4:$P$4,0))*IF($F22="",1,INDEX('Type Chart'!$B$5:$P$19,MATCH(I$4,'Type Chart'!$A$5:$A$19,0),MATCH($F22,'Type Chart'!$B$4:$P$4,0))) -> 1 | J22: =INDEX('Type Chart'!$B$5:$P$19,MATCH(J$4,'Type Chart'!$A$5:$A$19,0),MATCH($E22,'Type Chart'!$B$4:$P$4,0))*IF($F22="",1,INDEX('Type Chart'!$B$5:$P$19,MATCH(J$4,'Type Chart'!$A$5:$A$19,0),MATCH($F22,'Type Chart'!$B$4:$P$4,0))) -> 1 | K22: =INDEX('Type Chart'!$B$5:$P$19,MATCH(K$4,'Type Chart'!$A$5:$A$19,0),MATCH($E22,'Type Chart'!$B$4:$P$4,0))*IF($F22="",1,INDEX('Type Chart'!$B$5:$P$19,MATCH(K$4,'Type Chart'!$A$5:$A$19,0),MATCH($F22,'Type Chart'!$B$4:$P$4,0))) -> 1 | L22: =INDEX('Type Chart'!$B$5:$P$19,MATCH(L$4,'Type Chart'!$A$5:$A$19,0),MATCH($E22,'Type Chart'!$B$4:$P$4,0))*IF($F22="",1,INDEX('Type Chart'!$B$5:$P$19,MATCH(L$4,'Type Chart'!$A$5:$A$19,0),MATCH($F22,'Type Chart'!$B$4:$P$4,0))) -> 1 | M22: =INDEX('Type Chart'!$B$5:$P$19,MATCH(M$4,'Type Chart'!$A$5:$A$19,0),MATCH($E22,'Type Chart'!$B$4:$P$4,0))*IF($F22="",1,INDEX('Type Chart'!$B$5:$P$19,MATCH(M$4,'Type Chart'!$A$5:$A$19,0),MATCH($F22,'Type Chart'!$B$4:$P$4,0))) -> 0.5 | N22: =INDEX('Type Chart'!$B$5:$P$19,MATCH(N$4,'Type Chart'!$A$5:$A$19,0),MATCH($E22,'Type Chart'!$B$4:$P$4,0))*IF($F22="",1,INDEX('Type Chart'!$B$5:$P$19,MATCH(N$4,'Type Chart'!$A$5:$A$19,0),MATCH($F22,'Type Chart'!$B$4:$P$4,0))) -> 1 | ... U22: =INDEX('Type Chart'!$B$5:$P$19,MATCH(U$4,'Type Chart'!$A$5:$A$19,0),MATCH($E22,'Type Chart'!$B$4:$P$4,0))*IF($F22="",1,INDEX('Type Chart'!$B$5:$P$19,MATCH(U$4,'Type Chart'!$A$5:$A$19,0),MATCH($F22,'Type Chart'!$B$4:$P$4,0))) -> 1
A23: Sabrina | B23: Gym 6 | C23: Alakazam | D23: 50 | E23: Psychic | G23: =INDEX('Type Chart'!$B$5:$P$19,MATCH(G$4,'Type Chart'!$A$5:$A$19,0),MATCH($E23,'Type Chart'!$B$4:$P$4,0))*IF($F23="",1,INDEX('Type Chart'!$B$5:$P$19,MATCH(G$4,'Type Chart'!$A$5:$A$19,0),MATCH($F23,'Type Chart'!$B$4:$P$4,0))) -> 1 | H23: =INDEX('Type Chart'!$B$5:$P$19,MATCH(H$4,'Type Chart'!$A$5:$A$19,0),MATCH($E23,'Type Chart'!$B$4:$P$4,0))*IF($F23="",1,INDEX('Type Chart'!$B$5:$P$19,MATCH(H$4,'Type Chart'!$A$5:$A$19,0),MATCH($F23,'Type Chart'!$B$4:$P$4,0))) -> 1 | I23: =INDEX('Type Chart'!$B$5:$P$19,MATCH(I$4,'Type Chart'!$A$5:$A$19,0),MATCH($E23,'Type Chart'!$B$4:$P$4,0))*IF($F23="",1,INDEX('Type Chart'!$B$5:$P$19,MATCH(I$4,'Type Chart'!$A$5:$A$19,0),MATCH($F23,'Type Chart'!$B$4:$P$4,0))) -> 1 | J23: =INDEX('Type Chart'!$B$5:$P$19,MATCH(J$4,'Type Chart'!$A$5:$A$19,0),MATCH($E23,'Type Chart'!$B$4:$P$4,0))*IF($F23="",1,INDEX('Type Chart'!$B$5:$P$19,MATCH(J$4,'Type Chart'!$A$5:$A$19,0),MATCH($F23,'Type Chart'!$B$4:$P$4,0))) -> 1 | K23: =INDEX('Type Chart'!$B$5:$P$19,MATCH(K$4,'Type Chart'!$A$5:$A$19,0),MATCH($E23,'Type Chart'!$B$4:$P$4,0))*IF($F23="",1,INDEX('Type Chart'!$B$5:$P$19,MATCH(K$4,'Type Chart'!$A$5:$A$19,0),MATCH($F23,'Type Chart'!$B$4:$P$4,0))) -> 1 | L23: =INDEX('Type Chart'!$B$5:$P$19,MATCH(L$4,'Type Chart'!$A$5:$A$19,0),MATCH($E23,'Type Chart'!$B$4:$P$4,0))*IF($F23="",1,INDEX('Type Chart'!$B$5:$P$19,MATCH(L$4,'Type Chart'!$A$5:$A$19,0),MATCH($F23,'Type Chart'!$B$4:$P$4,0))) -> 1 | M23: =INDEX('Type Chart'!$B$5:$P$19,MATCH(M$4,'Type Chart'!$A$5:$A$19,0),MATCH($E23,'Type Chart'!$B$4:$P$4,0))*IF($F23="",1,INDEX('Type Chart'!$B$5:$P$19,MATCH(M$4,'Type Chart'!$A$5:$A$19,0),MATCH($F23,'Type Chart'!$B$4:$P$4,0))) -> 0.5 | N23: =INDEX('Type Chart'!$B$5:$P$19,MATCH(N$4,'Type Chart'!$A$5:$A$19,0),MATCH($E23,'Type Chart'!$B$4:$P$4,0))*IF($F23="",1,INDEX('Type Chart'!$B$5:$P$19,MATCH(N$4,'Type Chart'!$A$5:$A$19,0),MATCH($F23,'Type Chart'!$B$4:$P$4,0))) -> 1 | ... U23: =INDEX('Type Chart'!$B$5:$P$19,MATCH(U$4,'Type Chart'!$A$5:$A$19,0),MATCH($E23,'Type Chart'!$B$4:$P$4,0))*IF($F23="",1,INDEX('Type Chart'!$B$5:$P$19,MATCH(U$4,'Type Chart'!$A$5:$A$19,0),MATCH($F23,'Type Chart'!$B$4:$P$4,0))) -> 1
A24: Blaine | B24: Gym 7 | C24: Rapidash | D24: 52 | E24: Fire | G24: =INDEX('Type Chart'!$B$5:$P$19,MATCH(G$4,'Type Chart'!$A$5:$A$19,0),MATCH($E24,'Type Chart'!$B$4:$P$4,0))*IF($F24="",1,INDEX('Type Chart'!$B$5:$P$19,MATCH(G$4,'Type Chart'!$A$5:$A$19,0),MATCH($F24,'Type Chart'!$B$4:$P$4,0))) -> 1 | H24: =INDEX('Type Chart'!$B$5:$P$19,MATCH(H$4,'Type Chart'!$A$5:$A$19,0),MATCH($E24,'Type Chart'!$B$4:$P$4,0))*IF($F24="",1,INDEX('Type Chart'!$B$5:$P$19,MATCH(H$4,'Type Chart'!$A$5:$A$19,0),MATCH($F24,'Type Chart'!$B$4:$P$4,0))) -> 0.5 | I24: =INDEX('Type Chart'!$B$5:$P$19,MATCH(I$4,'Type Chart'!$A$5:$A$19,0),MATCH($E24,'Type Chart'!$B$4:$P$4,0))*IF($F24="",1,INDEX('Type Chart'!$B$5:$P$19,MATCH(I$4,'Type Chart'!$A$5:$A$19,0),MATCH($F24,'Type Chart'!$B$4:$P$4,0))) -> 2 | J24: =INDEX('Type Chart'!$B$5:$P$19,MATCH(J$4,'Type Chart'!$A$5:$A$19,0),MATCH($E24,'Type Chart'!$B$4:$P$4,0))*IF($F24="",1,INDEX('Type Chart'!$B$5:$P$19,MATCH(J$4,'Type Chart'!$A$5:$A$19,0),MATCH($F24,'Type Chart'!$B$4:$P$4,0))) -> 1 | K24: =INDEX('Type Chart'!$B$5:$P$19,MATCH(K$4,'Type Chart'!$A$5:$A$19,0),MATCH($E24,'Type Chart'!$B$4:$P$4,0))*IF($F24="",1,INDEX('Type Chart'!$B$5:$P$19,MATCH(K$4,'Type Chart'!$A$5:$A$19,0),MATCH($F24,'Type Chart'!$B$4:$P$4,0))) -> 0.5 | L24: =INDEX('Type Chart'!$B$5:$P$19,MATCH(L$4,'Type Chart'!$A$5:$A$19,0),MATCH($E24,'Type Chart'!$B$4:$P$4,0))*IF($F24="",1,INDEX('Type Chart'!$B$5:$P$19,MATCH(L$4,'Type Chart'!$A$5:$A$19,0),MATCH($F24,'Type Chart'!$B$4:$P$4,0))) -> 1 | M24: =INDEX('Type Chart'!$B$5:$P$19,MATCH(M$4,'Type Chart'!$A$5:$A$19,0),MATCH($E24,'Type Chart'!$B$4:$P$4,0))*IF($F24="",1,INDEX('Type Chart'!$B$5:$P$19,MATCH(M$4,'Type Chart'!$A$5:$A$19,0),MATCH($F24,'Type Chart'!$B$4:$P$4,0))) -> 1 | N24: =INDEX('Type Chart'!$B$5:$P$19,MATCH(N$4,'Type Chart'!$A$5:$A$19,0),MATCH($E24,'Type Chart'!$B$4:$P$4,0))*IF($F24="",1,INDEX('Type Chart'!$B$5:$P$19,MATCH(N$4,'Type Chart'!$A$5:$A$19,0),MATCH($F24,'Type Chart'!$B$4:$P$4,0))) -> 1 | ... U24: =INDEX('Type Chart'!$B$5:$P$19,MATCH(U$4,'Type Chart'!$A$5:$A$19,0),MATCH($E24,'Type Chart'!$B$4:$P$4,0))*IF($F24="",1,INDEX('Type Chart'!$B$5:$P$19,MATCH(U$4,'Type Chart'!$A$5:$A$19,0),MATCH($F24,'Type Chart'!$B$4:$P$4,0))) -> 1
A25: Blaine | B25: Gym 7 | C25: Charizard | D25: 51 | E25: Fire | F25: Flying | G25: =INDEX('Type Chart'!$B$5:$P$19,MATCH(G$4,'Type Chart'!$A$5:$A$19,0),MATCH($E25,'Type Chart'!$B$4:$P$4,0))*IF($F25="",1,INDEX('Type Chart'!$B$5:$P$19,MATCH(G$4,'Type Chart'!$A$5:$A$19,0),MATCH($F25,'Type Chart'!$B$4:$P$4,0))) -> 1 | H25: =INDEX('Type Chart'!$B$5:$P$19,MATCH(H$4,'Type Chart'!$A$5:$A$19,0),MATCH($E25,'Type Chart'!$B$4:$P$4,0))*IF($F25="",1,INDEX('Type Chart'!$B$5:$P$19,MATCH(H$4,'Type Chart'!$A$5:$A$19,0),MATCH($F25,'Type Chart'!$B$4:$P$4,0))) -> 0.5 | I25: =INDEX('Type Chart'!$B$5:$P$19,MATCH(I$4,'Type Chart'!$A$5:$A$19,0),MATCH($E25,'Type Chart'!$B$4:$P$4,0))*IF($F25="",1,INDEX('Type Chart'!$B$5:$P$19,MATCH(I$4,'Type Chart'!$A$5:$A$19,0),MATCH($F25,'Type Chart'!$B$4:$P$4,0))) -> 2 | J25: =INDEX('Type Chart'!$B$5:$P$19,MATCH(J$4,'Type Chart'!$A$5:$A$19,0),MATCH($E25,'Type Chart'!$B$4:$P$4,0))*IF($F25="",1,INDEX('Type Chart'!$B$5:$P$19,MATCH(J$4,'Type Chart'!$A$5:$A$19,0),MATCH($F25,'Type Chart'!$B$4:$P$4,0))) -> 2 | K25: =INDEX('Type Chart'!$B$5:$P$19,MATCH(K$4,'Type Chart'!$A$5:$A$19,0),MATCH($E25,'Type Chart'!$B$4:$P$4,0))*IF($F25="",1,INDEX('Type Chart'!$B$5:$P$19,MATCH(K$4,'Type Chart'!$A$5:$A$19,0),MATCH($F25,'Type Chart'!$B$4:$P$4,0))) -> 0.25 | L25: =INDEX('Type Chart'!$B$5:$P$19,MATCH(L$4,'Type Chart'!$A$5:$A$19,0),MATCH($E25,'Type Chart'!$B$4:$P$4,0))*IF($F25="",1,INDEX('Type Chart'!$B$5:$P$19,MATCH(L$4,'Type Chart'!$A$5:$A$19,0),MATCH($F25,'Type Chart'!$B$4:$P$4,0))) -> 2 | M25: =INDEX('Type Chart'!$B$5:$P$19,MATCH(M$4,'Type Chart'!$A$5:$A$19,0),MATCH($E25,'Type Chart'!$B$4:$P$4,0))*IF($F25="",1,INDEX('Type Chart'!$B$5:$P$19,MATCH(M$4,'Type Chart'!$A$5:$A$19,0),MATCH($F25,'Type Chart'!$B$4:$P$4,0))) -> 0.5 | N25: =INDEX('Type Chart'!$B$5:$P$19,MATCH(N$4,'Type Chart'!$A$5:$A$19,0),MATCH($E25,'Type Chart'!$B$4:$P$4,0))*IF($F25="",1,INDEX('Type Chart'!$B$5:$P$19,MATCH(N$4,'Type Chart'!$A$5:$A$19,0),MATCH($F25,'Type Chart'!$B$4:$P$4,0))) -> 1 | ... U25: =INDEX('Type Chart'!$B$5:$P$19,MATCH(U$4,'Type Chart'!$A$5:$A$19,0),MATCH($E25,'Type Chart'!$B$4:$P$4,0))*IF($F25="",1,INDEX('Type Chart'!$B$5:$P$19,MATCH(U$4,'Type Chart'!$A$5:$A$19,0),MATCH($F25,'Type Chart'!$B$4:$P$4,0))) -> 1
A26: Blaine | B26: Gym 7 | C26: Ninetales | D26: 51 | E26: Fire | G26: =INDEX('Type Chart'!$B$5:$P$19,MATCH(G$4,'Type Chart'!$A$5:$A$19,0),MATCH($E26,'Type Chart'!$B$4:$P$4,0))*IF($F26="",1,INDEX('Type Chart'!$B$5:$P$19,MATCH(G$4,'Type Chart'!$A$5:$A$19,0),MATCH($F26,'Type Chart'!$B$4:$P$4,0))) -> 1 | H26: =INDEX('Type Chart'!$B$5:$P$19,MATCH(H$4,'Type Chart'!$A$5:$A$19,0),MATCH($E26,'Type Chart'!$B$4:$P$4,0))*IF($F26="",1,INDEX('Type Chart'!$B$5:$P$19,MATCH(H$4,'Type Chart'!$A$5:$A$19,0),MATCH($F26,'Type Chart'!$B$4:$P$4,0))) -> 0.5 | I26: =INDEX('Type Chart'!$B$5:$P$19,MATCH(I$4,'Type Chart'!$A$5:$A$19,0),MATCH($E26,'Type Chart'!$B$4:$P$4,0))*IF($F26="",1,INDEX('Type Chart'!$B$5:$P$19,MATCH(I$4,'Type Chart'!$A$5:$A$19,0),MATCH($F26,'Type Chart'!$B$4:$P$4,0))) -> 2 | J26: =INDEX('Type Chart'!$B$5:$P$19,MATCH(J$4,'Type Chart'!$A$5:$A$19,0),MATCH($E26,'Type Chart'!$B$4:$P$4,0))*IF($F26="",1,INDEX('Type Chart'!$B$5:$P$19,MATCH(J$4,'Type Chart'!$A$5:$A$19,0),MATCH($F26,'Type Chart'!$B$4:$P$4,0))) -> 1 | K26: =INDEX('Type Chart'!$B$5:$P$19,MATCH(K$4,'Type Chart'!$A$5:$A$19,0),MATCH($E26,'Type Chart'!$B$4:$P$4,0))*IF($F26="",1,INDEX('Type Chart'!$B$5:$P$19,MATCH(K$4,'Type Chart'!$A$5:$A$19,0),MATCH($F26,'Type Chart'!$B$4:$P$4,0))) -> 0.5 | L26: =INDEX('Type Chart'!$B$5:$P$19,MATCH(L$4,'Type Chart'!$A$5:$A$19,0),MATCH($E26,'Type Chart'!$B$4:$P$4,0))*IF($F26="",1,INDEX('Type Chart'!$B$5:$P$19,MATCH(L$4,'Type Chart'!$A$5:$A$19,0),MATCH($F26,'Type Chart'!$B$4:$P$4,0))) -> 1 | M26: =INDEX('Type Chart'!$B$5:$P$19,MATCH(M$4,'Type Chart'!$A$5:$A$19,0),MATCH($E26,'Type Chart'!$B$4:$P$4,0))*IF($F26="",1,INDEX('Type Chart'!$B$5:$P$19,MATCH(M$4,'Type Chart'!$A$5:$A$19,0),MATCH($F26,'Type Chart'!$B$4:$P$4,0))) -> 1 | N26: =INDEX('Type Chart'!$B$5:$P$19,MATCH(N$4,'Type Chart'!$A$5:$A$19,0),MATCH($E26,'Type Chart'!$B$4:$P$4,0))*IF($F26="",1,INDEX('Type Chart'!$B$5:$P$19,MATCH(N$4,'Type Chart'!$A$5:$A$19,0),MATCH($F26,'Type Chart'!$B$4:$P$4,0))) -> 1 | ... U26: =INDEX('Type Chart'!$B$5:$P$19,MATCH(U$4,'Type Chart'!$A$5:$A$19,0),MATCH($E26,'Type Chart'!$B$4:$P$4,0))*IF($F26="",1,INDEX('Type Chart'!$B$5:$P$19,MATCH(U$4,'Type Chart'!$A$5:$A$19,0),MATCH($F26,'Type Chart'!$B$4:$P$4,0))) -> 1
A27: Blaine | B27: Gym 7 | C27: Arcanine | D27: 52 | E27: Fire | G27: =INDEX('Type Chart'!$B$5:$P$19,MATCH(G$4,'Type Chart'!$A$5:$A$19,0),MATCH($E27,'Type Chart'!$B$4:$P$4,0))*IF($F27="",1,INDEX('Type Chart'!$B$5:$P$19,MATCH(G$4,'Type Chart'!$A$5:$A$19,0),MATCH($F27,'Type Chart'!$B$4:$P$4,0))) -> 1 | H27: =INDEX('Type Chart'!$B$5:$P$19,MATCH(H$4,'Type Chart'!$A$5:$A$19,0),MATCH($E27,'Type Chart'!$B$4:$P$4,0))*IF($F27="",1,INDEX('Type Chart'!$B$5:$P$19,MATCH(H$4,'Type Chart'!$A$5:$A$19,0),MATCH($F27,'Type Chart'!$B$4:$P$4,0))) -> 0.5 | I27: =INDEX('Type Chart'!$B$5:$P$19,MATCH(I$4,'Type Chart'!$A$5:$A$19,0),MATCH($E27,'Type Chart'!$B$4:$P$4,0))*IF($F27="",1,INDEX('Type Chart'!$B$5:$P$19,MATCH(I$4,'Type Chart'!$A$5:$A$19,0),MATCH($F27,'Type Chart'!$B$4:$P$4,0))) -> 2 | J27: =INDEX('Type Chart'!$B$5:$P$19,MATCH(J$4,'Type Chart'!$A$5:$A$19,0),MATCH($E27,'Type Chart'!$B$4:$P$4,0))*IF($F27="",1,INDEX('Type Chart'!$B$5:$P$19,MATCH(J$4,'Type Chart'!$A$5:$A$19,0),MATCH($F27,'Type Chart'!$B$4:$P$4,0))) -> 1 | K27: =INDEX('Type Chart'!$B$5:$P$19,MATCH(K$4,'Type Chart'!$A$5:$A$19,0),MATCH($E27,'Type Chart'!$B$4:$P$4,0))*IF($F27="",1,INDEX('Type Chart'!$B$5:$P$19,MATCH(K$4,'Type Chart'!$A$5:$A$19,0),MATCH($F27,'Type Chart'!$B$4:$P$4,0))) -> 0.5 | L27: =INDEX('Type Chart'!$B$5:$P$19,MATCH(L$4,'Type Chart'!$A$5:$A$19,0),MATCH($E27,'Type Chart'!$B$4:$P$4,0))*IF($F27="",1,INDEX('Type Chart'!$B$5:$P$19,MATCH(L$4,'Type Chart'!$A$5:$A$19,0),MATCH($F27,'Type Chart'!$B$4:$P$4,0))) -> 1 | M27: =INDEX('Type Chart'!$B$5:$P$19,MATCH(M$4,'Type Chart'!$A$5:$A$19,0),MATCH($E27,'Type Chart'!$B$4:$P$4,0))*IF($F27="",1,INDEX('Type Chart'!$B$5:$P$19,MATCH(M$4,'Type Chart'!$A$5:$A$19,0),MATCH($F27,'Type Chart'!$B$4:$P$4,0))) -> 1 | N27: =INDEX('Type Chart'!$B$5:$P$19,MATCH(N$4,'Type Chart'!$A$5:$A$19,0),MATCH($E27,'Type Chart'!$B$4:$P$4,0))*IF($F27="",1,INDEX('Type Chart'!$B$5:$P$19,MATCH(N$4,'Type Chart'!$A$5:$A$19,0),MATCH($F27,'Type Chart'!$B$4:$P$4,0))) -> 1 | ... U27: =INDEX('Type Chart'!$B$5:$P$19,MATCH(U$4,'Type Chart'!$A$5:$A$19,0),MATCH($E27,'Type Chart'!$B$4:$P$4,0))*IF($F27="",1,INDEX('Type Chart'!$B$5:$P$19,MATCH(U$4,'Type Chart'!$A$5:$A$19,0),MATCH($F27,'Type Chart'!$B$4:$P$4,0))) -> 1
